Workbook
Name \z: '[1]COAT&WRAP-QIOT-#3'!#REF!
Name ________________________________________________________cao1: #REF!
Name ________________________________________________________cao1: #REF!
Name ________________________________________________________cao2: #REF!
Name ________________________________________________________cao2: #REF!
Name ________________________________________________________cao3: #REF!
Name ________________________________________________________cao3: #REF!
Name ________________________________________________________cao4: #REF!
Name ________________________________________________________cao4: #REF!
Name ________________________________________________________cao5: #REF!
Name ________________________________________________________cao5: #REF!
Name ________________________________________________________cao6: #REF!
Name ________________________________________________________cao6: #REF!
Name ________________________________________________________dai1: #REF!
Name ________________________________________________________dai1: #REF!
Name ________________________________________________________dai2: #REF!
Name ________________________________________________________dai2: #REF!
Name ________________________________________________________dai3: #REF!
Name ________________________________________________________dai3: #REF!
Name ________________________________________________________dai4: #REF!
Name ________________________________________________________dai4: #REF!
Name ________________________________________________________dai5: #REF!
Name ________________________________________________________dai5: #REF!
Name ________________________________________________________dai6: #REF!
Name ________________________________________________________dai6: #REF!
Name ________________________________________________________dan1: #REF!
Name ________________________________________________________dan1: #REF!
Name ________________________________________________________dan2: #REF!
Name ________________________________________________________dan2: #REF!
Name ________________________________________________________phi10: #REF!
Name ________________________________________________________phi10: #REF!
Name ________________________________________________________phi12: #REF!
Name ________________________________________________________phi12: #REF!
Name ________________________________________________________phi14: #REF!
Name ________________________________________________________phi14: #REF!
Name ________________________________________________________phi16: #REF!
Name ________________________________________________________phi16: #REF!
Name ________________________________________________________phi18: #REF!
Name ________________________________________________________phi18: #REF!
Name ________________________________________________________phi20: #REF!
Name ________________________________________________________phi20: #REF!
Name ________________________________________________________phi22: #REF!
Name ________________________________________________________phi22: #REF!
Name ________________________________________________________phi25: #REF!
Name ________________________________________________________phi25: #REF!
Name ________________________________________________________phi28: #REF!
Name ________________________________________________________phi28: #REF!
Name ________________________________________________________phi6: #REF!
Name ________________________________________________________phi6: #REF!
Name ________________________________________________________phi8: #REF!
Name ________________________________________________________phi8: #REF!
Name ________________________________________________________slg1: #REF!
Name ________________________________________________________slg1: #REF!
Name ________________________________________________________slg2: #REF!
Name ________________________________________________________slg2: #REF!
Name ________________________________________________________slg3: #REF!
Name ________________________________________________________slg3: #REF!
Name ________________________________________________________slg4: #REF!
Name ________________________________________________________slg4: #REF!
Name ________________________________________________________slg5: #REF!

Sheet PKL
A1: ADVANCE KNITTING VIETNAM CO., LTD
A2: LOT F5-4, THUAN DAO INDUSTRIAL PARK'S EXPANSION PHASE, LONG CANG COMMUNE, TAY NINH PROVINCE, VIETNAM
A3: TEL:(+84)-723-643-733; (+84)-723-643-734 FAX: (+84)-723-643-735
A4: PACKING LIST
A6: Shipper / Exporter: | J6: No. / Date of Packing List :
A7: ADVANCE KNITTING VIETNAM CO.,LTD | J7: AK/GDI-20260009 | L7: 46121
A8: LOT F5-4, THUAN DAO INDUSTRIAL PARK'S EXPANSION PHASE, LONG CANG COMMUNE, TAY NINH PROVINCE, VIETNAM | J8: No. / Date of Invoice :
A9: TEL:(+84)-723-643-733; (+84)-723-643-734 FAX: (+84)-723-643-735 | J9: =J7 -> AK/GDI-20260009 | L9: =L7 -> 46121
A10: Buyer:
A11: GDI HK LIMITED | J11: No. / Date of Contract :
A12: FLAT H, 2/F MANSION INDUSTRIAL BUILDING, | J12: AK/GDI/CT-202602 | L12: 46035
A13: 8 A KUNG NGAM VILLAGE LANE, SHAU KEI WAN, HONG KONG
A16: Consignee:
A17: PT NIRWANA ALABARE GARMENT
A18: JL. RAYA RANCAEKEK - MAJALAYA , NO.289, DESA SOLOKAN JERUK,
A19: KECAMATAN SOLOKAN JERUK, KABUPATEN BANDUNG JAWA BARAT
A20: 40382, INDONESIA
A21: TAX ID :0745 4069 2644 4000
A22: EMAIL : LUSI@PTNAG.COM YUS.YULIUS@PTNAG.COM
A24: Loading: | E24: Discharge: | J24: Term of Delivery: | L24: CFR JAKARTA INDONESIA
A25: HO CHI MINH | E25: JAKARTA | J25: Origin of Goods: | L25: Vietnam
J26: PO No:
A27: FLIGHT NO: | C27: Delivery date | E27: ETA:
A28: TR 0553 | C28: 46125 | E28: 46127 | J28: Term of Payment: | K28: By T/T
C29: POLYESTER KNITTED RIB
A30: CARTON NO | B30: PO | C30: DESCRIPTION OF GOODS | D30: ITEM NO | E30: COLOR | F30: SIZE | H30: REF# | I30: Q'TY | J30: UNIT | K30: Net Weight (Kgs) | L30: Gross Weight (Kgs) | M30: Measurements (CBM)
A31: 1 | B31: SIOB260205005 | C31: 60% BETTER COTTON (BCI) 40% POLYESTER 32S/1x4 PLY FLAT KNIT COLLAR | D31: 1051120 | E31: BLACK JACK 400黑色 | F31: XS | G31: 13-1/4"x3.375” | H31: KD00397 265K0051-1ST LOT/ S/416363 | I31: 414 | J31: PCS | K31: =L31-1.45 -> 28.2 | L31: 29.65 | M31: 0.11 | N31: ĐƠN 11 | O31: =B31&E31&F31 -> SIOB260205005BLACK JACK 400黑色XS | Q31: =B31&E31&F31 -> SIOB260205005BLACK JACK 400黑色XS
B32: SIOB260205005 | C32: 60% BETTER COTTON (BCI) 40% POLYESTER 32S/1x4 PLY FLAT KNIT COLLAR | D32: 1051120 | E32: BLACK JACK 400黑色 | F32: XL | G32: 16"x3.625” | H32: KD00397 265K0051-1ST LOT/ S/416363 | I32: 751 | J32: PCS | N32: ĐƠN 11 | O32: =B32&E32&F32 -> SIOB260205005BLACK JACK 400黑色XL | Q32: =B32&E32&F32 -> SIOB260205005BLACK JACK 400黑色XL
A33: 2 | B33: SIOB260205005 | C33: 60% BETTER COTTON (BCI) 40% POLYESTER 32S/1x4 PLY FLAT KNIT COLLAR | D33: 1051120 | E33: BLACK JACK 400黑色 | F33: S | G33: 13-3/4"x3.375” | H33: KD00397 265K0051-1ST LOT/ S/416363 | I33: 785 | J33: PCS | K33: =L33-1.45 -> 25.3 | L33: 26.75 | M33: 0.11 | N33: ĐƠN 11 | O33: =B33&E33&F33 -> SIOB260205005BLACK JACK 400黑色S | Q33: =B33&E33&F33 -> SIOB260205005BLACK JACK 400黑色S
B34: SIOB260205005 | C34: 60% BETTER COTTON (BCI) 40% POLYESTER 32S/1x4 PLY FLAT KNIT COLLAR | D34: 1051120 | E34: BLACK JACK 400黑色 | F34: XXL | G34: 17"x3.625” | H34: KD00397 265K0051-1ST LOT/ S/416363 | I34: 311 | J34: PCS | N34: ĐƠN 11 | O34: =B34&E34&F34 -> SIOB260205005BLACK JACK 400黑色XXL | Q34: =B34&E34&F34 -> SIOB260205005BLACK JACK 400黑色XXL
A35: 3 | B35: SIOB260205005 | C35: 60% BETTER COTTON (BCI) 40% POLYESTER 32S/1x4 PLY FLAT KNIT COLLAR | D35: 1051120 | E35: BLACK JACK 400黑色 | F35: M | G35: 14-1/4"x3.625” | H35: KD00397 265K0051-1ST LOT/ S/416363 | I35: 799 | J35: PCS | K35: =L35-1.45 -> 23.75 | L35: 25.2 | M35: 0.11 | N35: ĐƠN 11 | O35: =B35&E35&F35 -> SIOB260205005BLACK JACK 400黑色M | Q35: =B35&E35&F35 -> SIOB260205005BLACK JACK 400黑色M
B36: SIOB260205005 | C36: 60% BETTER COTTON (BCI) 40% POLYESTER 32S/1x4 PLY FLAT KNIT COLLAR | D36: 1051120 | E36: BLACK JACK 400黑色 | F36: L HUSKY | G36: 15-1/2"x3.625” | H36: KD00397 265K0051-1ST LOT/ S/416363 | I36: 30 | J36: PCS | N36: ĐƠN 11 | O36: =B36&E36&F36 -> SIOB260205005BLACK JACK 400黑色L HUSKY | Q36: =B36&E36&F36 -> SIOB260205005BLACK JACK 400黑色L HUSKY
B37: SIOB260205005 | C37: 60% BETTER COTTON (BCI) 40% POLYESTER 32S/1x4 PLY FLAT KNIT COLLAR | D37: 1051120 | E37: BLACK JACK 400黑色 | F37: XL HUSKY | G37: 16-1/2"x3.625” | H37: KD00397 265K0051-1ST LOT/ S/416363 | I37: 50 | J37: PCS | N37: ĐƠN 11 | O37: =B37&E37&F37 -> SIOB260205005BLACK JACK 400黑色XL HUSKY | Q37: =B37&E37&F37 -> SIOB260205005BLACK JACK 400黑色XL HUSKY
B38: SIOB260205005 | C38: 60% BETTER COTTON (BCI) 40% POLYESTER 32S/1x4 PLY FLAT KNIT COLLAR | D38: 1051120 | E38: BLACK JACK 400黑色 | F38: XXL HUSKY | G38: 17-1/2"x3.625” | H38: KD00397 265K0051-1ST LOT/ S/416363 | I38: 85 | J38: PCS | N38: ĐƠN 11 | O38: =B38&E38&F38 -> SIOB260205005BLACK JACK 400黑色XXL HUSKY | Q38: =B38&E38&F38 -> SIOB260205005BLACK JACK 400黑色XXL HUSKY
A39: 4 | B39: SIOB260205005 | C39: 60% BETTER COTTON (BCI) 40% POLYESTER 32S/1x4 PLY FLAT KNIT COLLAR | D39: 1051120 | E39: BLACK JACK 400黑色 | F39: L | G39: 15"x3.625” | H39: KD00397 265K0051-1ST LOT/ S/416363 | I39: 949 | J39: PCS | K39: =L39-1.45 -> 23.6 | L39: 25.05 | M39: 0.11 | N39: ĐƠN 11 | O39: =B39&E39&F39 -> SIOB260205005BLACK JACK 400黑色L | Q39: =B39&E39&F39 -> SIOB260205005BLACK JACK 400黑色L
A40: 5 | B40: SIOB260205012 | C40: 60% BETTER COTTON (BCI) 40% POLYESTER 32S/1x4 PLY FLAT KNIT COLLAR | D40: 1051120 | E40: BLUE TANGO 884克莱恩蓝 | F40: XS | G40: 13"x3.375” | H40: KD00400 265K0052 -1ST LOT/ S/767468 | I40: 611 | J40: PCS | K40: =L40-1.45 -> 27.2 | L40: 28.65 | M40: 0.11 | N40: ĐƠN 10 | O40: =B40&E40&F40 -> SIOB260205012BLUE TANGO 884克莱恩蓝XS | Q40: =B40&E40&F40 -> SIOB260205012BLUE TANGO 884克莱恩蓝XS
B41: SIOB260205012 | C41: 60% BETTER COTTON (BCI) 40% POLYESTER 32S/1x4 PLY FLAT KNIT COLLAR | D41: 1051120 | E41: BLUE TANGO 884克莱恩蓝 | F41: XL | G41: 15-1/2"x3.625” | H41: KD00400 265K0052 -1ST LOT/ S/767468 | I41: 502 | J41: PCS | N41: ĐƠN 10 | O41: =B41&E41&F41 -> SIOB260205012BLUE TANGO 884克莱恩蓝XL | Q41: =B41&E41&F41 -> SIOB260205012BLUE TANGO 884克莱恩蓝XL
B42: SIOB260205012 | C42: 60% BETTER COTTON (BCI) 40% POLYESTER 32S/1x4 PLY FLAT KNIT COLLAR | D42: 1051120 | E42: BLUE TANGO 884克莱恩蓝 | F42: L HUSKY | G42: 15"x3.625” | H42: KD00400 265K0052 -1ST LOT/ S/767468 | I42: 80 | J42: PCS | N42: ĐƠN 10 | O42: =B42&E42&F42 -> SIOB260205012BLUE TANGO 884克莱恩蓝L HUSKY | Q42: =B42&E42&F42 -> SIOB260205012BLUE TANGO 884克莱恩蓝L HUSKY
A43: 6 | B43: SIOB260205012 | C43: 60% BETTER COTTON (BCI) 40% POLYESTER 32S/1x4 PLY FLAT KNIT COLLAR | D43: 1051120 | E43: BLUE TANGO 884克莱恩蓝 | F43: S | G43: 13"x3.375” | H43: KD00400 265K0052 -1ST LOT/ S/767468 | I43: 1105 | J43: PCS | K43: =L43-1.45 -> 25 | L43: 26.45 | M43: 0.11 | N43: ĐƠN 10 | O43: =B43&E43&F43 -> SIOB260205012BLUE TANGO 884克莱恩蓝S | Q43: =B43&E43&F43 -> SIOB260205012BLUE TANGO 884克莱恩蓝S
B44: SIOB260205012 | C44: 60% BETTER COTTON (BCI) 40% POLYESTER 32S/1x4 PLY FLAT KNIT COLLAR | D44: 1051120 | E44: BLUE TANGO 884克莱恩蓝 | F44: XL HUSKY | G44: 16-1/2"x3.625” | H44: KD00400 265K0052 -1ST LOT/ S/767468 | I44: 105 | J44: PCS | N44: ĐƠN 10 | O44: =B44&E44&F44 -> SIOB260205012BLUE TANGO 884克莱恩蓝XL HUSKY | Q44: =B44&E44&F44 -> SIOB260205012BLUE TANGO 884克莱恩蓝XL HUSKY
...

Sheet INV
A1: ADVANCE KNITTING VIETNAM CO., LTD
A2: LOT F5-4, THUAN DAO INDUSTRIAL PARK'S EXPANSION PHASE, LONG CANG COMMUNE, TAY NINH PROVINCE, VIETNAM
A3: TEL:(+84)-723-643-733; (+84)-723-643-734 FAX: (+84)-723-643-735
A4: COMMERCIAL INVOICE
A5: Shipper / Exporter: | F5: No. / Date of Invoice :
A6: ADVANCE KNITTING VIETNAM CO.,LTD | F6: =PKL!J7 -> AK/GDI-20260009 | G6: =PKL!L7 -> 46121
A7: LOT F5-4, THUAN DAO INDUSTRIAL PARK'S EXPANSION PHASE, LONG CANG | F7: Contract No. / Date:
A8: COMMUNE, TAY NINH PROVINCE, VIETNAM
A9: TEL:(+84)-723-643-733; (+84)-723-643-734 FAX: (+84)-723-643-735 | F9: =PKL!J12 -> AK/GDI/CT-202602 | G9: =PKL!L12 -> 46035
A10: Buyer:
A11: GDI HK LIMITED
A12: FLAT H, 2/F MANSION INDUSTRIAL BUILDING,
A13: 8 A KUNG NGAM VILLAGE LANE, SHAU KEI WAN, HONG KONG
A15: Consignee: | F15: Term of Delivery: CFR JAKARTA INDONESIA
A16: =PKL!A17 -> PT NIRWANA ALABARE GARMENT | F16: Origin of Goods: Vietnam
A17: =PKL!A18 -> JL. RAYA RANCAEKEK - MAJALAYA , NO.289, DESA SOLOKAN JERUK,
A18: =PKL!A19 -> KECAMATAN SOLOKAN JERUK, KABUPATEN BANDUNG JAWA BARAT
A19: =PKL!A20 -> 40382, INDONESIA
A20: =PKL!A21 -> TAX ID :0745 4069 2644 4000
A21: EMAIL : LUSI@PTNAG.COM YUS.YULIUS@PTNAG.COM
A24: Loading: | C24: Discharge:
A25: =PKL!A25 -> HO CHI MINH | C25: =PKL!E25 -> JAKARTA
A28: FLIGHT NO: | C28: Delivery date | D28: ETA:
A29: =PKL!A28 -> TR 0553 | C29: =PKL!C28 -> 46125 | D29: =PKL!E28 -> 46127 | F29: Term of Payment: By T/T
A30: PO | B30: REF# | C30: ITEM NO | D30: DESCRIPTION OF GOODS | E30: COLOR | F30: SIZE | G30: QUANTITY | H30: Unit | I30: UNIT PRICE (USD) | J30: AMOUNT (USD) | K30: Mô tả tiếng việt | L30: HS CODE
A31: SIOB260205005 | B31: KD00397 265K0051-1ST LOT/ S/416363 | C31: 1051120 | D31: 60% BETTER COTTON (BCI) 40% POLYESTER 32S/1x4 PLY FLAT KNIT COLLAR | E31: CALLA LILY 451漂白 | F31: XS | G31: 2400 | H31: PCS | I31: 0.165 | J31: =ROUND(G31*I31,2) -> 396 | K31: Bo thun cổ áo, màu CALLA LILY 451, size XS. Mới 100%#&VN | L31: 61179000 | N31: =A31&E31&F31 -> SIOB260205005CALLA LILY 451漂白XS | O31: =SUMIF(PKL!O:O,INV!N31,PKL!I:I) -> 2400
A32: SIOB260205005 | B32: KD00397 265K0051-1ST LOT/ S/416363 | C32: 1051120 | D32: 60% BETTER COTTON (BCI) 40% POLYESTER 32S/1x4 PLY FLAT KNIT COLLAR | E32: CALLA LILY 451漂白 | F32: L | G32: 2400 | H32: PCS | I32: 0.165 | J32: =ROUND(G32*I32,2) -> 396 | K32: Bo thun cổ áo, màu CALLA LILY 451, size L. Mới 100%#&VN | L32: 61179000 | N32: =A32&E32&F32 -> SIOB260205005CALLA LILY 451漂白L | O32: =SUMIF(PKL!O:O,INV!N32,PKL!I:I) -> 2400
A33: SIOB260205005 | B33: KD00397 265K0051-1ST LOT/ S/416363 | C33: 1051120 | D33: 60% BETTER COTTON (BCI) 40% POLYESTER 32S/1x4 PLY FLAT KNIT COLLAR | E33: CALLA LILY 451漂白 | F33: XL | G33: 1200 | H33: PCS | I33: 0.165 | J33: =ROUND(G33*I33,2) -> 198 | K33: Bo thun cổ áo, màu CALLA LILY 451, size XL. Mới 100%#&VN | L33: 61179000 | N33: =A33&E33&F33 -> SIOB260205005CALLA LILY 451漂白XL | O33: =SUMIF(PKL!O:O,INV!N33,PKL!I:I) -> 1200
A34: SIOB260205005 | B34: KD00397 265K0051-1ST LOT/ S/416363 | C34: 1051120 | D34: 60% BETTER COTTON (BCI) 40% POLYESTER 32S/1x4 PLY FLAT KNIT COLLAR | E34: BLACK JACK 400黑色 | F34: XS | G34: 414 | H34: PCS | I34: 0.17 | J34: =ROUND(G34*I34,2) -> 70.38 | K34: Bo thun cổ áo, màu BLACK JACK 400, size XS. Mới 100%#&VN | L34: 61179000 | N34: =A34&E34&F34 -> SIOB260205005BLACK JACK 400黑色XS | O34: =SUMIF(PKL!O:O,INV!N34,PKL!I:I) -> 414
A35: SIOB260205005 | B35: KD00397 265K0051-1ST LOT/ S/416363 | C35: 1051120 | D35: 60% BETTER COTTON (BCI) 40% POLYESTER 32S/1x4 PLY FLAT KNIT COLLAR | E35: BLACK JACK 400黑色 | F35: S | G35: 785 | H35: PCS | I35: 0.17 | J35: =ROUND(G35*I35,2) -> 133.45 | K35: Bo thun cổ áo, màu BLACK JACK 400, size S. Mới 100%#&VN | L35: 61179000 | N35: =A35&E35&F35 -> SIOB260205005BLACK JACK 400黑色S | O35: =SUMIF(PKL!O:O,INV!N35,PKL!I:I) -> 785
A36: SIOB260205005 | B36: KD00397 265K0051-1ST LOT/ S/416363 | C36: 1051120 | D36: 60% BETTER COTTON (BCI) 40% POLYESTER 32S/1x4 PLY FLAT KNIT COLLAR | E36: BLACK JACK 400黑色 | F36: M | G36: 799 | H36: PCS | I36: 0.17 | J36: =ROUND(G36*I36,2) -> 135.83 | K36: Bo thun cổ áo, màu BLACK JACK 400, size M. Mới 100%#&VN | L36: 61179000 | N36: =A36&E36&F36 -> SIOB260205005BLACK JACK 400黑色M | O36: =SUMIF(PKL!O:O,INV!N36,PKL!I:I) -> 799
A37: SIOB260205005 | B37: KD00397 265K0051-1ST LOT/ S/416363 | C37: 1051120 | D37: 60% BETTER COTTON (BCI) 40% POLYESTER 32S/1x4 PLY FLAT KNIT COLLAR | E37: BLACK JACK 400黑色 | F37: L | G37: 949 | H37: PCS | I37: 0.17 | J37: =ROUND(G37*I37,2) -> 161.33 | K37: Bo thun cổ áo, màu BLACK JACK 400, size L. Mới 100%#&VN | L37: 61179000 | N37: =A37&E37&F37 -> SIOB260205005BLACK JACK 400黑色L | O37: =SUMIF(PKL!O:O,INV!N37,PKL!I:I) -> 949
A38: SIOB260205005 | B38: KD00397 265K0051-1ST LOT/ S/416363 | C38: 1051120 | D38: 60% BETTER COTTON (BCI) 40% POLYESTER 32S/1x4 PLY FLAT KNIT COLLAR | E38: BLACK JACK 400黑色 | F38: XL | G38: 751 | H38: PCS | I38: 0.17 | J38: =ROUND(G38*I38,2) -> 127.67 | K38: Bo thun cổ áo, màu BLACK JACK 400, size XL. Mới 100%#&VN | L38: 61179000 | N38: =A38&E38&F38 -> SIOB260205005BLACK JACK 400黑色XL | O38: =SUMIF(PKL!O:O,INV!N38,PKL!I:I) -> 751
A39: SIOB260205005 | B39: KD00397 265K0051-1ST LOT/ S/416363 | C39: 1051120 | D39: 60% BETTER COTTON (BCI) 40% POLYESTER 32S/1x4 PLY FLAT KNIT COLLAR | E39: BLACK JACK 400黑色 | F39: XXL | G39: 311 | H39: PCS | I39: 0.17 | J39: =ROUND(G39*I39,2) -> 52.87 | K39: Bo thun cổ áo, màu BLACK JACK 400, size XXL. Mới 100%#&VN | L39: 61179000 | N39: =A39&E39&F39 -> SIOB260205005BLACK JACK 400黑色XXL | O39: =SUMIF(PKL!O:O,INV!N39,PKL!I:I) -> 311
A40: SIOB260205005 | B40: KD00397 265K0051-1ST LOT/ S/416363 | C40: 1051120 | D40: 60% BETTER COTTON (BCI) 40% POLYESTER 32S/1x4 PLY FLAT KNIT COLLAR | E40: BLACK JACK 400黑色 | F40: L HUSKY | G40: 30 | H40: PCS | I40: 0.17 | J40: =ROUND(G40*I40,2) -> 5.1 | K40: Bo thun cổ áo, màu BLACK JACK 400, size L HUSKY. Mới 100%#&VN | L40: 61179000 | N40: =A40&E40&F40 -> SIOB260205005BLACK JACK 400黑色L HUSKY | O40: =SUMIF(PKL!O:O,INV!N40,PKL!I:I) -> 30
A41: SIOB260205005 | B41: KD00397 265K0051-1ST LOT/ S/416363 | C41: 1051120 | D41: 60% BETTER COTTON (BCI) 40% POLYESTER 32S/1x4 PLY FLAT KNIT COLLAR | E41: BLACK JACK 400黑色 | F41: XL HUSKY | G41: 50 | H41: PCS | I41: 0.17 | J41: =ROUND(G41*I41,2) -> 8.5 | K41: Bo thun cổ áo, màu BLACK JACK 400, size XL HUSKY. Mới 100%#&VN | L41: 61179000 | N41: =A41&E41&F41 -> SIOB260205005BLACK JACK 400黑色XL HUSKY | O41: =SUMIF(PKL!O:O,INV!N41,PKL!I:I) -> 50
A42: SIOB260205005 | B42: KD00397 265K0051-1ST LOT/ S/416363 | C42: 1051120 | D42: 60% BETTER COTTON (BCI) 40% POLYESTER 32S/1x4 PLY FLAT KNIT COLLAR | E42: BLACK JACK 400黑色 | F42: XXL HUSKY | G42: 85 | H42: PCS | I42: 0.17 | J42: =ROUND(G42*I42,2) -> 14.45 | K42: Bo thun cổ áo, màu BLACK JACK 400, size XXL HUSKY. Mới 100%#&VN | L42: 61179000 | N42: =A42&E42&F42 -> SIOB260205005BLACK JACK 400黑色XXL HUSKY | O42: =SUMIF(PKL!O:O,INV!N42,PKL!I:I) -> 85
... A87: SIOB260205012 | B87: KD00400 265K0052 -1ST LOT/ S/767468 | C87: 1051120 | D87: 60% BETTER COTTON (BCI) 40% POLYESTER 32S/1x4 PLY FLAT KNIT COLLAR | E87: WINE STAIN 853酒红 | F87: XXL HUSKY | G87: 185 | H87: PCS | I87: 0.17 | J87: =ROUND(G87*I87,2) -> 31.45 | K87: Bo thun cổ áo, màu WINE STAIN 853, size XXL HUSKY. Mới 100%#&VN | L87: 61179000 | N87: =A87&E87&F87 -> SIOB260205012WINE STAIN 853酒红XXL HUSKY | O87: =SUMIF(PKL!O:O,INV!N87,PKL!I:I) -> 185
D88: TOTAL | G88: =SUM(G31:G87) -> 39733 | H88: PCS | I88: USD | J88: =SUM(J31:J87) -> 6724.61
A89: SAY: | B89: US DOLLAR SIX THOUSAND SEVEN HUNDRED TWENTY FOUR AND SIXTY ONE CENTS ONLY.
...

Sheet TEM
A1: SHIMADA 4
A2: Carton No | B2: PO NUMBER | D2: DESCRIPTION OF GOODS | E2: PRODUCT CODE | F2: COLOR | H2: SIZE | I2: LOT | J2: Q'TY | K2: UNIT | L2: Net Weight (Kgs) | M2: Gross Weight (Kgs) | N2: Measurements (CBM)
A3: 14 | B3: PO-DMBK-I-2435/25 | C3: ĐƠN 4 | D3: (H25234206(TL-1)) POLYESTER KNITTED RIB SIZE S 100% POLYESTER | E3: H25234206(TL-1) | F3: 1030 | G3: S | H3: 7.5*37.5 CM | I3: GT250128 | J3: 98 | K3: PCS | L3: =M3-1.35 -> 28.95 | M3: 30.3 | N3: 0.11
B4: PO-DMBK-I-2435/25 | C4: ĐƠN 4 | D4: (H25234206(TL-1)) POLYESTER KNITTED RIB SIZE S 100% POLYESTER | E4: H25234206(TL-1) | F4: 1030 | G4: M | H4: 7.5*38.5 CM | I4: GT250128 | J4: 219 | K4: PCS
B5: PO-DMBK-I-2435/25 | C5: ĐƠN 4 | D5: (H25234206(TL-1)) POLYESTER KNITTED RIB SIZE S 100% POLYESTER | E5: H25234206(TL-1) | F5: 1030 | G5: L | H5: 7.5*39.5 CM | I5: GT250128 | J5: 208 | K5: PCS
B6: PO-DMBK-I-2435/25 | C6: ĐƠN 4 | D6: (H25234206(TL-1)) POLYESTER KNITTED RIB SIZE S 100% POLYESTER | E6: H25234206(TL-1) | F6: 1030 | G6: LL | H6: 7.5*40.5 CM | I6: GT250128 | J6: 84 | K6: PCS
B7: PO-DMBK-I-2432/25 | C7: ĐƠN 4 | D7: (H25234110(TM-1)) POLYESTER KNITTED RIB SIZE 3L 100% POLYESTER | E7: H25234110(TM-1) | F7: 1030 | G7: M | H7: 8*41 CM | I7: GT250128 | J7: 209 | K7: PCS
B8: PO-DMBK-I-2432/25 | C8: ĐƠN 4 | D8: (H25234110(TM-1)) POLYESTER KNITTED RIB SIZE 3L 100% POLYESTER | E8: H25234110(TM-1) | F8: 1030 | G8: L | H8: 8*42.5 CM | I8: GT250128 | J8: 412 | K8: PCS
B9: PO-DMBK-I-2432/25 | C9: ĐƠN 4 | D9: (H25234110(TM-1)) POLYESTER KNITTED RIB SIZE 3L 100% POLYESTER | E9: H25234110(TM-1) | F9: 1030 | G9: LL | H9: 8*44 CM | I9: GT250128 | J9: 330 | K9: PCS
B10: PO-DMBK-I-2432/25 | C10: ĐƠN 4 | D10: (H25234110(TM-1)) POLYESTER KNITTED RIB SIZE 3L 100% POLYESTER | E10: H25234110(TM-1) | F10: 1030 | G10: 3L | H10: 8*45.5 CM | I10: GT250128 | J10: 199 | K10: PCS
A11: =COUNT(A3:A10) -> 1 | J11: =SUM(J3:J10) -> 1759 | K11: PCS | L11: =SUM(L3:L10) -> 28.95 | M11: =SUM(M3:M10) -> 30.3 | N11: =SUM(N3:N10) -> 0.11
A12: MADE IN VIETNAM
F13: ADVANCE KNITTING VIETNAM CO., LTD
J14: Signature, full name, seal

Sheet DELIVERY INSTRUCTION
A2: DELIVERY INSTRUCTION
A3: No. | B3: : | C3: =PKL!J7 -> AK/GDI-20260009
A4: Date | B4: : | C4: =PKL!L7 -> 46121
A6: Pursuant to Contract No. | B6: : | C6: AK/GDI/CT-202512 on Dec. 17, 2025
A9: We (Buyer) hereby | B9: : | C9: =PKL!A11 -> GDI HK LIMITED
C10: ADD: FLAT H, 2/F MANSION INDUSTRIAL BUILDING, 8 A KUNG NGAM VILLAGE LANE, SHAU KEI WAN, HONG KONG
A12: To appoint to Seller | C12: ADVANCE KNITTING VIETNAM CO.,LTD
C13: LOT F5-4, THUAN DAO INDUSTRIAL PARK'S EXPANSION PHASE, LONG CANG COMMUNE, TAY NINH PROVINCE, VIETNAM
C14: TEL:(+84)-723-643-733; (+84)-723-643-734 FAX: (+84)-723-643-735
A15: To release cargo to Consignee | B15: : | C15: =PKL!A17 -> PT NIRWANA ALABARE GARMENT
C16: NO.18 THONG NHAT ROAD, SONG THAN INDUSTRIAL ZONE II,DI AN WARD,
C17: HO CHI MINH CITY, VIETNAM.
C18: TAX CODE :3700346873
C19: TEL :0084-274.3790.780|Ext.:260
A20: Notify party: | C20: KANMAX ENTERPRISES LIMITED
C21: ADD: 60 PAYA LEBAR ROAD, #04-21 PAYA LEBAR SQUARE, SINGAPORE 409051, SINGAPORE.
C22: TEL: 65 6702 1179 FAX : FAX: 65 6702 1182
A23: As the followings
A25: PO | B25: REF# | D25: ITEM NO | E25: DESCRIPTION OF GOODS | F25: COLOR | G25: SIZE | H25: QUANTITY | I25: Unit | J25: UNIT PRICE (USD) | K25: AMOUNT (USD)
A26: SIOB251105016 | B26: KV06800 263K0033-B~E4(3RD MB)/ S/416363 | D26: 1051120 | E26: 60% BETTER COTTON (BCI) 40% POLYESTER 32S/1x4 PLY FLAT KNIT COLLAR | F26: BLACK JACK 400黑色 | G26: XS | H26: 1152 | I26: PCS | J26: 0.17 | K26: =ROUND(H26*J26,3) -> 195.84
A27: SIOB251105016 | B27: KV06800 263K0033-B~E4(3RD MB)/ S/416363 | D27: 1051120 | E27: 60% BETTER COTTON (BCI) 40% POLYESTER 32S/1x4 PLY FLAT KNIT COLLAR | F27: BLACK JACK 400黑色 | G27: S | H27: 2703 | I27: PCS | J27: 0.17 | K27: =ROUND(H27*J27,3) -> 459.51
A28: SIOB251105016 | B28: KV06800 263K0033-B~E4(3RD MB)/ S/416363 | D28: 1051120 | E28: 60% BETTER COTTON (BCI) 40% POLYESTER 32S/1x4 PLY FLAT KNIT COLLAR | F28: BLACK JACK 400黑色 | G28: M | H28: 1869 | I28: PCS | J28: 0.17 | K28: =ROUND(H28*J28,3) -> 317.73
A29: SIOB251105016 | B29: KV06800 263K0033-B~E4(3RD MB)/ S/416363 | D29: 1051120 | E29: 60% BETTER COTTON (BCI) 40% POLYESTER 32S/1x4 PLY FLAT KNIT COLLAR | F29: BLACK JACK 400黑色 | G29: L | H29: 3823 | I29: PCS | J29: 0.17 | K29: =ROUND(H29*J29,3) -> 649.91
A30: SIOB251105016 | B30: KV06800 263K0033-B~E4(3RD MB)/ S/416363 | D30: 1051120 | E30: 60% BETTER COTTON (BCI) 40% POLYESTER 32S/1x4 PLY FLAT KNIT COLLAR | F30: BLACK JACK 400黑色 | G30: XL | H30: 2332 | I30: PCS | J30: 0.17 | K30: =ROUND(H30*J30,3) -> 396.44
A31: SIOB251105016 | B31: KV06800 263K0033-B~E4(3RD MB)/ S/416363 | D31: 1051120 | E31: 60% BETTER COTTON (BCI) 40% POLYESTER 32S/1x4 PLY FLAT KNIT COLLAR | F31: BLACK JACK 400黑色 | G31: XXL | H31: 1744 | I31: PCS | J31: 0.17 | K31: =ROUND(H31*J31,3) -> 296.48
A32: SIOB251105016 | B32: KV06800 263K0033-B~E4(3RD MB)/ S/416363 | D32: 1051120 | E32: 60% BETTER COTTON (BCI) 40% POLYESTER 32S/1x4 PLY FLAT KNIT COLLAR | F32: BLACK JACK 400黑色 | G32: L HUSKY | H32: 205 | I32: PCS | J32: 0.17 | K32: =ROUND(H32*J32,3) -> 34.85
A33: SIOB251105016 | B33: KV06800 263K0033-B~E4(3RD MB)/ S/416363 | D33: 1051120 | E33: 60% BETTER COTTON (BCI) 40% POLYESTER 32S/1x4 PLY FLAT KNIT COLLAR | F33: BLACK JACK 400黑色 | G33: XL HUSKY | H33: 147 | I33: PCS | J33: 0.17 | K33: =ROUND(H33*J33,3) -> 24.99
A34: SIOB251105016 | B34: KV06800 263K0033-B~E4(3RD MB)/ S/416363 | D34: 1051120 | E34: 60% BETTER COTTON (BCI) 40% POLYESTER 32S/1x4 PLY FLAT KNIT COLLAR | F34: BLACK JACK 400黑色 | G34: XXL HUSKY | H34: 186 | I34: PCS | J34: 0.17 | K34: =ROUND(H34*J34,3) -> 31.62
B35: TOTAL | H35: =SUM(H26:H34) -> 14161 | I35: PCS | J35: USD | K35: =SUM(K26:K34) -> 2407.37
A38: AMOUNT IN WORDS | C38: =INV!#REF! -> #REF!
A39: ARTICLE 2: ORIGIN OF VIETNAM
A40: ARTICLE 3: PACKING | C40: Export Standard Packing
A41: ARTICLE 4: DELIVERY AND PAYMENT
A42: *Delivery | C42: By Truck/ Lalamove
A43: *Delivery Time | C43: =PKL!E28 -> 46127
A44: *Delivery Term | C44: DAP HO CHI MINH
A45: *Bill To | C45: =C9 -> GDI HK LIMITED
A46: We kindly request the relevant parties to perform the delivery and receipt of goods in accordance with the above instruction and comply with the customs
A48: For and on behalf of Buyer

Sheet SC
A1: ADVANCE KNITTING VIETNAM CO., LTD
A2: LOT F5-4, THUAN DAO INDUSTRIAL PARK'S EXPANSION PHASE, LONG CANG COMMUNE, TAY NINH PROVINCE, VIETNAM
A3: TEL:(+84)-723-643-733; (+84)-723-643-734 FAX: (+84)-723-643-735
A4: SALE CONTRACT
A6: BUYER: GDI HK LIMITED | H6: No: | I6: SIOB251103005-1
A7: FLAT H, 2/F MANSION INDUSTRIAL BUILDING, 8 A KUNG NGAM VILLAGE LANE, SHAU KEI WAN, HONG KONG | H7: Date: | I7: 46018
A9: BASE ON PO NO SIOB251103005 SIGNED ON NOVEMBER 03, 2025 ; ADVANCE KNITTING VIETNAM CO.,LTD AS SELLER , HEREBY CONFIRMS HAVING SOLD THE REMAIN QUANTITY OF THIS PO TO YOUR FIRM
A10: THE FOLLOWING GOODS BY CONTRACT OF SALE MADE ON THE ABOVE DATE AND ON THE TERNMS AND
A11: CONDITIONS HEREAFTER SET FORTH:
A12: COMMODITY | C12: : | D12: CLOTHING ACCESSORIES
A14: PO | B14: REF# | C14: ITEM NO | D14: DESCRIPTION OF GOODS | E14: COLOR | F14: SIZE | G14: QUANTITY | H14: Unit | I14: UNIT PRICE (USD) | J14: AMOUNT (USD)
A15: SIOB251103005 | B15: KV06798 263K0033-A2+~A4(1ST LOT)/S/416363 | C15: 1051120 | D15: 60% BETTER COTTON (BCI) 40% POLYESTER 32S/1x4 PLY FLAT KNIT COLLAR | E15: MONET BLUE 744油画蓝 | F15: XL | G15: 41 | H15: PCS | I15: 0.17 | J15: 6.97
A16: SIOB251103005 | B16: KV06798 263K0033-A2+~A4(1ST LOT)/S/416363 | C16: 1051120 | D16: 60% BETTER COTTON (BCI) 40% POLYESTER 32S/1x4 PLY FLAT KNIT COLLAR | E16: MONET BLUE 744油画蓝 | F16: XXL | G16: 12 | H16: PCS | I16: 0.17 | J16: 2.04
A17: SIOB251103005 | B17: KV06798 263K0033-A2+~A4(1ST LOT)/S/416363 | C17: 1051120 | D17: 60% BETTER COTTON (BCI) 40% POLYESTER 32S/1x4 PLY FLAT KNIT COLLAR | E17: BLACK JACK 400黑色 | F17: S | G17: 123 | H17: PCS | I17: 0.17 | J17: 20.91
A18: SIOB251103005 | B18: KV06798 263K0033-A2+~A4(1ST LOT)/S/416363 | C18: 1051120 | D18: 60% BETTER COTTON (BCI) 40% POLYESTER 32S/1x4 PLY FLAT KNIT COLLAR | E18: BLACK JACK 400黑色 | F18: XL HUSKY | G18: 52 | H18: PCS | I18: 0.17 | J18: 8.84
A19: SIOB251103005 | B19: KV06798 263K0033-A2+~A4(1ST LOT)/S/416363 | C19: 1051120 | D19: 60% BETTER COTTON (BCI) 40% POLYESTER 32S/1x4 PLY FLAT KNIT COLLAR | E19: BLACK JACK 400黑色 | F19: XXL HUSKY | G19: 31 | H19: PCS | I19: 0.17 | J19: 5.27
C20: TOTAL | G20: =SUM(G15:G19) -> 259 | H20: PCS | I20: USD | J20: =SUM(J15:J19) -> 44.03
A23: QUALITY | C23: : | D23: AS PER ADVANCE KNITTING VIETNAM'S STANDARD GRADE
A24: QUANTITY | C24: : | D24: =G20 -> 259 | E24: PCS
A25: PACKING MARKING | C25: : | D25: EXPORT STANDARD PACKING IN TRUCK
A26: TOTAL AMOUNT OF CONTRACT | C26: : | D26: =J20 -> 44.03
D27: US DOLLAR FORTY FOUR AND THREE CENTS ONLY.
A28: TERMS OF PAYMENT | C28: : | D28: T/T 100% PAYMENT WITHIN 30 DAYS DELIVERY
A29: DELIVERY PLACE: | C29: : | D29: BUYER NOMINATE SELLER DELIVER GOODS TO CONSIGNEE BELOW:
D30: CHUTEX INTERNATIONAL CO.,LTD
D31: NO.18 THONG NHAT ROAD, SONG THAN INDUSTRIAL ZONE II,DI AN WARD,
D32: HO CHI MINH CITY, VIETNAM.
A33: DELIVERY TERM: | D33: DAP HO CHI MINH
A34: NOTIFY PARTY (IF NEEDED) | D34: =PKL!#REF! -> #REF!
D35: =PKL!#REF! -> #REF!
D36: =PKL!#REF! -> #REF!
A37: OUR BANK | C37: : | D37: JOINT STOCK COMMERCIAL BANK FOR FOREIGN TRADE OF VIET NAM (VIETCOMBANK)
A38: BRANCH | C38: : | D38: 2A PHAM VAN NGU STREET, BEN LUC DISTRICT, LONG AN PROVINCE, VIET NAM
A39: ACCOUNT NO. | C39: : | D39: 0631370457237
A40: SWIFT CODE | C40: : | D40: BFTVVNVX
A41: TIME OF SHIPMENT | C41: : | D41: =PKL!C28 -> 46125
A42: FROM | C42: : | D42: TAY NINH
A43: DESTINATION : | C43: : | D43: HO CHI MINH
A44: INSPECTION | C44: : | D44: ADVANCE KNITTING VIETNAM FACTORY 'S INSPECTION TO BE TAKEN AS FINAL
A45: OTHER CONDITIONS | C45: : | D45: PRICE ADJUSTMENT FOR INFERIOR PRODUCTS IF ANY SHALL BE SETTLED BY THE
...

Sheet IN PHIẾU XUẤT 
I1: Mẫu số: 02-VT
D2: 出货明细 PHIẾU XUẤT KHO | I2: (Ban hành theo TT số: 200/2014/TT-BTC)
A3: Lô F5-4, KCN Thuận Đạo, huyện Cần Đước, tỉnh Long An | I3: Ngày 22/12/2014 của bộ trưởng BTC
C4: =NOW() -> 46123.426 | I4: Nợ……………...........
C5: PXK:SH28032025 | I5: Có……………............
A6: Họ tên người nhận hàng 领料员: | H6: PO:
A7: Khách hàng/ Bộ phận 部门SHIMADA SHOJI (VIETNAM) CO., LTD | H7: Biển kiểm soát :
A8: Địa chỉ 地址Lô số 21-1, 21-2 và 21-3, Đường số 8B, Khu Công Nghiệp Quốc Tế Protrade,Xã An Tây, Thị xã Bến Cát, T.BD.VN
A9: Lý do xuất kho: | C9: XUẤT THÀNH PHẨM 出口成品
A10: Xuất tại kho: | C10: CÔNG TY TNHH ADVANCE KNITTING VIỆT NAM
A11: Ghi chú备注: 15 THÙNG
A12: STT | B12: PO | C12: 色號 Mã màu | D12: 缸号 Mã Lot | E12: 尺寸 Quy cách | G12: 单位 Đơn vị | H12: 数量 Số lượng | I12: Ghi chú 备注
H13: 良品数量 Thực xuất
A14: 1 | B14: PO-DMBK-I-1669(HN)/25 | C14: NVY | D14: GT240114 | E14: 140MMX500MM | G14: PCS | H14: 238
A15: 2 | B15: PO-DMBK-I-1669(HN)/25 | C15: WHT | D15: GT240815 | E15: 140MMX500MM | G15: PCS | H15: 361
A16: 3 | B16: PO-DMBK-I-1669(HN)/25 | C16: ABN | D16: GT250221 | E16: 140MMX500MM | G16: PCS | H16: 64
A17: 4 | B17: PO-DMBK-I-2418/25 | C17: 1120(NAVY) | D17: GT250204 | E17: M | F17: 6.5X50CM | G17: PCS | H17: 214
A18: 5 | B18: PO-DMBK-I-2418/25 | C18: 1120(NAVY) | D18: GT250204 | E18: L | F18: 6.5X50CM | G18: PCS | H18: 353
A19: 6 | B19: PO-DMBK-I-2418/25 | C19: 1120(NAVY) | D19: GT250204 | E19: LL | F19: 6.5X50CM | G19: PCS | H19: 177
A20: 7 | B20: PO-DMBK-I-2418/25 | C20: 1120(NAVY) | D20: GT250204 | E20: 3L | F20: 6.5X50CM | G20: PCS | H20: 96
A21: 8 | B21: PO-DMBK-I-2418/25 | C21: 1030(WHITE) | D21: GT250204 | E21: M | F21: 6.5X50CM | G21: PCS | H21: 298
A22: 9 | B22: PO-DMBK-I-2418/25 | C22: 1030(WHITE) | D22: GT250204 | E22: L | F22: 6.5X50CM | G22: PCS | H22: 496
A23: 10 | B23: PO-DMBK-I-2418/25 | C23: 1030(WHITE) | D23: GT250204 | E23: LL | F23: 6.5X50CM | G23: PCS | H23: 247
A24: 11 | B24: PO-DMBK-I-2418/25 | C24: 1030(WHITE) | D24: GT250204 | E24: 3L | F24: 6.5X50CM | G24: PCS | H24: 129
A25: 12 | B25: PO-DMBK-I-2418/25 | C25: 1140(GREEN) | D25: GT250204 | E25: M | F25: 6.5X50CM | G25: PCS | H25: 162
A26: 13 | B26: PO-DMBK-I-2418/25 | C26: 1140(GREEN) | D26: GT250204 | E26: L | F26: 6.5X50CM | G26: PCS | H26: 272
A27: 14 | B27: PO-DMBK-I-2418/25 | C27: 1140(GREEN) | D27: GT250204 | E27: LL | F27: 6.5X50CM | G27: PCS | H27: 135
A28: 15 | B28: PO-DMBK-I-2418/25 | C28: 1140(GREEN) | D28: GT250204 | E28: 3L | F28: 6.5X50CM | G28: PCS | H28: 71
... A32: 19 | B32: PO-DMBK-I-2418/25 | C32: 1110(RED) | D32: GT250204 | E32: 3L | F32: 6.5X50CM | G32: PCS | H32: 47
A33: 20 | B33: PO-DMBK-I-2435/25 | C33: 1030 | D33: GT250128 | E33: S | F33: 7.5*37.5 CM | G33: PCS | H33: 98
A34: 21 | B34: PO-DMBK-I-2435/25 | C34: 1030 | D34: GT250128 | E34: M | F34: 7.5*38.5 CM | G34: PCS | H34: 219
A35: 22 | B35: PO-DMBK-I-2435/25 | C35: 1030 | D35: GT250128 | E35: L | F35: 7.5*39.5 CM | G35: PCS | H35: 208
A36: 23 | B36: PO-DMBK-I-2435/25 | C36: 1030 | D36: GT250128 | E36: LL | F36: 7.5*40.5 CM | G36: PCS | H36: 84
A37: 24 | B37: PO-DMBK-I-2432/25 | C37: 1030 | D37: GT250128 | E37: M | F37: 8*41 CM | G37: PCS | H37: 209
A38: 25 | B38: PO-DMBK-I-2432/25 | C38: 1030 | D38: GT250128 | E38: L | F38: 8*42.5 CM | G38: PCS | H38: 412
A39: 26 | B39: PO-DMBK-I-2432/25 | C39: 1030 | D39: GT250128 | E39: LL | F39: 8*44 CM | G39: PCS | H39: 330
A40: 27 | B40: PO-DMBK-I-2432/25 | C40: 1030 | D40: GT250128 | E40: 3L | F40: 8*45.5 CM | G40: PCS | H40: 199
A41: 28 | B41: PO-DMBK-I-2435/25 | C41: 1120 | D41: GT250128 | E41: S | F41: 7.5*37.5 CM | G41: PCS | H41: 42
A42: 29 | B42: PO-DMBK-I-2435/25 | C42: 1120 | D42: GT250128 | E42: M | F42: 7.5*38.5 CM | G42: PCS | H42: 112
A43: 30 | B43: PO-DMBK-I-2435/25 | C43: 1120 | D43: GT250128 | E43: L | F43: 7.5*39.5 CM | G43: PCS | H43: 105
...
