Workbook

Sheet invoice for payment
A1: SHAOXING XIEHENG TEXTILE CO., LTD.
A2: ROOM 1608, 1 ZEYU, QIXIAN STREET, KEQIAO DISTRICT,SHAOXING CITY, ZHEJIANG PROVINCE, CHINA 312000
A3: TEL:0575-85197880 FAX:0575-85198881
A4: COMMERCIAL INVOICE
A6: INVOICE NO.: | B6: WAN-26003-TN-20260413 | G6: Date.: | I6: APR. 13, 2026
A8: MESSRS.: | B8: PT. NIRWANA ALABARE GARMENT
B9: Jl. Raya Rancaekek - Majalaya No. 289
B10: Solokanjeruk, Kec. Solokanjeruk
B11: Kab. Bandung, Jawa Barat 40376
B12: Phone : +62-22-85962076
B13: Attn : Ayu/Della/Pak Gun Gun
A15: PER S.S.: | B15: BY AIR CARGO | F15: ETD : 4/14 ETA : 4/14
A17: SHIP FROM : | B17: SHANGHAI, CHINA | F17: TO. : | G17: JAKARTA, INDONESIA
A19: Item No. | B19: DESCRIPTION OF GOODS | C19: Q'TY | D19: Q'TY | E19: Q'TY | G19: Unit | J19: Amount
C20: (YDS) | D20: (METER) | E20: (KGS) | G20: Price | J20: (US$)
B21: KNITTED FABRIC | F21: (CIF JAKARTA)
B22: *********************
B23: HS CODE : 6006
B24: PO#REEF SP27 SMS
B25: 70%BAMBOO VISCOSE 30%POLYESTER
B26: 155GSM - 245G/Y - 66"WIDTH
B27: OYSTER MUSHROOM | C27: 65 | D27: 59 | E27: 18.6 | F27: KGS | G27: 5.9 | H27: /KG | J27: FOC
B28: GREEN BAY | C28: 30 | D28: 27 | E28: 8.1 | F28: KGS | G28: 5.9 | H28: /KG | J28: FOC
B29: CAVIAR | C29: 70 | D29: 64 | E29: 20.4 | F29: KGS | G29: 5.9 | H29: /KG | J29: FOC
B30: QUIET SHADE | C30: 40 | D30: 36 | E30: 11.2 | F30: KGS | G30: 5.9 | H30: /KG | J30: FOC
B31: INSIGNIA BLUE | C31: 40 | D31: 36 | E31: 11.6 | F31: KGS | G31: 5.9 | H31: /KG | J31: FOC
B32: BLUE HAZY | C32: 65 | D32: 59 | E32: 18.6 | F32: KGS | G32: 5.9 | H32: /KG | J32: FOC
B33: SACHET PINK | C33: 40 | D33: 36 | E33: 12.9 | F33: KGS | G33: 5.9 | H33: /KG | J33: FOC
B36: 71%POLYESTER 25%RAYON 4%SPANDEX
B37: 330GSM - 475G/Y - 60"WIDTH
B38: INSIGNIA BLUE | C38: 50 | D38: 45 | E38: 23.1 | F38: KGS | G38: 5.2 | H38: /KG | J38: FOC
B39: CAVIAR | C39: 50 | D39: 45 | E39: 23.2 | F39: KGS | G39: 5.2 | H39: /KG | J39: FOC
B42: 100%POLYESTER MESH
B43: 75GSM - 105G/Y - 60"WIDTH
B44: BLCAK | C44: 4 | D44: 3 | E44: 0.3 | F44: KGS | G44: 4 | H44: /KG | I44: US$ | J44: FOC
A46: Total : | C46: =SUM(C25:C45) -> 454 | D46: =SUM(D25:D45) -> 410 | E46: =SUM(E27:E44) -> 148 | F46: KGS | I46: US$ | J46: FOC
C47: vvvvvvvvvvvv | D47: vvvvvvvvvvvv | E47: vvvvvvvvvvv | F47: vvvvv | I47: vvvv | J47: vvvvvvvvvvvvv
E55: FARM JOY CO., LTD.
E59: ………………………………………

Sheet invoice for shipping
A1: SHAOXING XIEHENG TEXTILE CO., LTD.
A2: ROOM 1608, 1 ZEYU, QIXIAN STREET, KEQIAO DISTRICT,SHAOXING CITY, ZHEJIANG PROVINCE, CHINA 312000
A3: TEL:0575-85197880 FAX:0575-85198881
A4: COMMERCIAL INVOICE
A6: INVOICE NO.: | B6: WAN-26003-TN-20260413 | G6: Date.: | I6: APR. 13, 2026
A8: MESSRS.: | B8: PT. NIRWANA ALABARE GARMENT
B9: Jl. Raya Rancaekek - Majalaya No. 289
B10: Solokanjeruk, Kec. Solokanjeruk
B11: Kab. Bandung, Jawa Barat 40376
B12: Phone : +62-22-85962076
B13: Attn : Ayu/Della/Pak Gun Gun
A15: PER S.S.: | B15: BY AIR CARGO | F15: ETD : 4/14 ETA : 4/14
A17: SHIP FROM : | B17: SHANGHAI, CHINA | F17: TO. : | G17: JAKARTA, INDONESIA
A19: Item No. | B19: DESCRIPTION OF GOODS | C19: Q'TY | D19: Q'TY | E19: Q'TY | G19: Unit | J19: Amount
C20: (YDS) | D20: (METER) | E20: (KGS) | G20: Price | J20: (US$)
B21: KNITTED FABRIC | F21: (CIF JAKARTA)
B22: *********************
B23: HS CODE : 6006
B24: PO#REEF SP27 SMS
B25: 70%BAMBOO VISCOSE 30%POLYESTER
B26: 155GSM - 245G/Y - 66"WIDTH
B27: OYSTER MUSHROOM | C27: 65 | D27: 59 | E27: 18.6 | F27: KGS | G27: 5.9 | H27: /KG | J27: =E27*G27 -> 109.74
B28: GREEN BAY | C28: 30 | D28: 27 | E28: 8.1 | F28: KGS | G28: 5.9 | H28: /KG | J28: =E28*G28 -> 47.79
B29: CAVIAR | C29: 70 | D29: 64 | E29: 20.4 | F29: KGS | G29: 5.9 | H29: /KG | J29: =E29*G29 -> 120.36
B30: QUIET SHADE | C30: 40 | D30: 36 | E30: 11.2 | F30: KGS | G30: 5.9 | H30: /KG | J30: =E30*G30 -> 66.08
B31: INSIGNIA BLUE | C31: 40 | D31: 36 | E31: 11.6 | F31: KGS | G31: 5.9 | H31: /KG | J31: =E31*G31 -> 68.44
B32: BLUE HAZY | C32: 65 | D32: 59 | E32: 18.6 | F32: KGS | G32: 5.9 | H32: /KG | J32: =E32*G32 -> 109.74
B33: SACHET PINK | C33: 40 | D33: 36 | E33: 12.9 | F33: KGS | G33: 5.9 | H33: /KG | J33: =E33*G33 -> 76.11
B36: 71%POLYESTER 25%RAYON 4%SPANDEX
B37: 330GSM - 475G/Y - 60"WIDTH
B38: INSIGNIA BLUE | C38: 50 | D38: 45 | E38: 23.1 | F38: KGS | G38: 5.2 | H38: /KG | J38: =E38*G38 -> 120.12
B39: CAVIAR | C39: 50 | D39: 45 | E39: 23.2 | F39: KGS | G39: 5.2 | H39: /KG | J39: =E39*G39 -> 120.64
B42: 100%POLYESTER MESH
B43: 75GSM - 105G/Y - 60"WIDTH
B44: BLCAK | C44: 4 | D44: 3 | E44: 0.3 | F44: KGS | G44: 4 | H44: /KG | I44: US$ | J44: =E44*G44 -> 1.2
A46: Total : | C46: =SUM(C25:C45) -> 454 | D46: =SUM(D25:D45) -> 410 | E46: =SUM(E27:E44) -> 148 | F46: KGS | I46: US$ | J46: =SUM(J25:J45) -> 840.22
C47: vvvvvvvvvvvv | D47: vvvvvvvvvvvv | E47: vvvvvvvvvvv | F47: vvvvv | I47: vvvv | J47: vvvvvvvvvvvvv
A49: SAY TOTAL U.S. DOLLARS EIGHT HUNDRED FORTY AND CENTS TWENTY TWO ONLY.
E55: FARM JOY CO., LTD.
E59: ………………………………………

Sheet PL
A1: SHAOXING XIEHENG TEXTILE CO., LTD.
A2: ROOM 1608, 1 ZEYU, QIXIAN STREET, KEQIAO DISTRICT,SHAOXING CITY, ZHEJIANG PROVINCE, CHINA 312000
A3: TEL:0575-85197880 FAX:0575-85198881
A4: PACKING LIST
A6: PACKING NO.: | C6: ='invoice for shipping'!B6 -> WAN-26003-TN-20260413 | H6: Date: | I6: ='invoice for shipping'!I6 -> APR. 13, 2026
A8: MESSRS.: | C8: ='invoice for shipping'!B8 -> PT. NIRWANA ALABARE GARMENT
C9: ='invoice for shipping'!B9 -> Jl. Raya Rancaekek - Majalaya No. 289
C10: ='invoice for shipping'!B10 -> Solokanjeruk, Kec. Solokanjeruk
C11: ='invoice for shipping'!B11 -> Kab. Bandung, Jawa Barat 40376
C12: ='invoice for shipping'!B12 -> Phone : +62-22-85962076
C13: ='invoice for shipping'!B13 -> Attn : Ayu/Della/Pak Gun Gun
A15: PER S.S.: | C15: ='invoice for shipping'!B15 -> BY AIR CARGO
A17: SHIP FROM : | C17: ='invoice for shipping'!B17 -> SHANGHAI, CHINA | G17: TO. : | H17: ='invoice for shipping'!G17 -> JAKARTA, INDONESIA
A19: P/No. | C19: Item No.(Style No.)/Description of Goods. | F19: YDS | G19: METER | H19: N.W. | J19: G.W.
H20: (KGS) | J20: (KGS)
C21: ='invoice for shipping'!B21 -> KNITTED FABRIC
C22: ='invoice for shipping'!B22 -> *********************
C23: ='invoice for shipping'!B23 -> HS CODE : 6006
C24: ='invoice for shipping'!B24 -> PO#REEF SP27 SMS
C25: ='invoice for shipping'!B25 -> 70%BAMBOO VISCOSE 30%POLYESTER
C26: ='invoice for shipping'!B26 -> 155GSM - 245G/Y - 66"WIDTH
A27: 1 | B27: PKG | C27: ='invoice for shipping'!B27 -> OYSTER MUSHROOM | F27: 65 | G27: 59 | H27: 18.6 | I27: KGS | J27: 18.9
A28: 1 | B28: PKG | C28: ='invoice for shipping'!B28 -> GREEN BAY | F28: 30 | G28: 27 | H28: 8.1 | I28: KGS | J28: 8.4
A29: 1 | B29: PKG | C29: ='invoice for shipping'!B29 -> CAVIAR | F29: 70 | G29: 64 | H29: 20.4 | I29: KGS | J29: 20.7
A30: 1 | B30: PKG | C30: ='invoice for shipping'!B30 -> QUIET SHADE | F30: 40 | G30: 36 | H30: 11.2 | I30: KGS | J30: 11.5
A31: 1 | B31: PKG | C31: ='invoice for shipping'!B31 -> INSIGNIA BLUE | F31: 40 | G31: 36 | H31: 11.6 | I31: KGS | J31: 11.9
A32: 1 | B32: PKG | C32: ='invoice for shipping'!B32 -> BLUE HAZY | F32: 65 | G32: 59 | H32: 18.6 | I32: KGS | J32: 18.9
A33: 1 | B33: PKG | C33: ='invoice for shipping'!B33 -> SACHET PINK | F33: 40 | G33: 36 | H33: 12.9 | I33: KGS | J33: 13.2
C35: ='invoice for shipping'!B36 -> 71%POLYESTER 25%RAYON 4%SPANDEX
C36: ='invoice for shipping'!B37 -> 330GSM - 475G/Y - 60"WIDTH
A37: 1 | B37: PKG | C37: ='invoice for shipping'!B38 -> INSIGNIA BLUE | F37: 50 | G37: 45 | H37: 23.1 | I37: KGS | J37: 23.4
C39: ='invoice for shipping'!B39 -> CAVIAR | F39: 50 | G39: 45 | H39: 23.2 | I39: KGS | J39: 23.5
C41: ='invoice for shipping'!B42 -> 100%POLYESTER MESH
C42: ='invoice for shipping'!B43 -> 75GSM - 105G/Y - 60"WIDTH
C43: ='invoice for shipping'!B44 -> BLCAK | F43: 4 | G43: 3 | H43: 0.3 | I43: KGS | J43: 0.6
A44: TTL : | B44: 1 | C44: PKG | F44: =SUM(F39:F43) -> 54 | G44: =SUM(G39:G43) -> 48 | H44: =SUM(H39:H43) -> 23.5 | I44: KGS | J44: =SUM(J39:J43) -> 24.1
A46: Total: | B46: =SUM(A27:A37)+B44 -> 9 | C46: PACKAGES | F46: =SUM(F27:F37)+F44 -> 454 | G46: =SUM(G27:G37)+G44 -> 410 | H46: =SUM(H27:H37)+H44 -> 148 | I46: KGS | J46: =SUM(J27:J37)+J44 -> 151
B47: vvvvvv | C47: vvvvvvvvvvvvvv | F47: vvvvvvvvvvvv | G47: vvvvvvvvvvvv | H47: vvvvvvvvvvv | J47: vvvvvvvvvvv
A49: SAY TOTAL NINE ( 9 ) PACKAGES ONLY.
G51: FARM JOY CO., LTD.
...
