Workbook
Name \z: '[1]COAT&WRAP-QIOT-#3'!#REF!
Name ________________________________________________________cao1: #REF!
Name ________________________________________________________cao1: #REF!
Name ________________________________________________________cao2: #REF!
Name ________________________________________________________cao2: #REF!
Name ________________________________________________________cao3: #REF!
Name ________________________________________________________cao3: #REF!
Name ________________________________________________________cao4: #REF!
Name ________________________________________________________cao4: #REF!
Name ________________________________________________________cao5: #REF!
Name ________________________________________________________cao5: #REF!
Name ________________________________________________________cao6: #REF!
Name ________________________________________________________cao6: #REF!
Name ________________________________________________________dai1: #REF!
Name ________________________________________________________dai1: #REF!
Name ________________________________________________________dai2: #REF!
Name ________________________________________________________dai2: #REF!
Name ________________________________________________________dai3: #REF!
Name ________________________________________________________dai3: #REF!
Name ________________________________________________________dai4: #REF!
Name ________________________________________________________dai4: #REF!
Name ________________________________________________________dai5: #REF!
Name ________________________________________________________dai5: #REF!
Name ________________________________________________________dai6: #REF!
Name ________________________________________________________dai6: #REF!
Name ________________________________________________________dan1: #REF!
Name ________________________________________________________dan1: #REF!
Name ________________________________________________________dan2: #REF!
Name ________________________________________________________dan2: #REF!
Name ________________________________________________________phi10: #REF!
Name ________________________________________________________phi10: #REF!
Name ________________________________________________________phi12: #REF!
Name ________________________________________________________phi12: #REF!
Name ________________________________________________________phi14: #REF!
Name ________________________________________________________phi14: #REF!
Name ________________________________________________________phi16: #REF!
Name ________________________________________________________phi16: #REF!
Name ________________________________________________________phi18: #REF!
Name ________________________________________________________phi18: #REF!
Name ________________________________________________________phi20: #REF!
Name ________________________________________________________phi20: #REF!
Name ________________________________________________________phi22: #REF!
Name ________________________________________________________phi22: #REF!
Name ________________________________________________________phi25: #REF!
Name ________________________________________________________phi25: #REF!
Name ________________________________________________________phi28: #REF!
Name ________________________________________________________phi28: #REF!
Name ________________________________________________________phi6: #REF!
Name ________________________________________________________phi6: #REF!
Name ________________________________________________________phi8: #REF!
Name ________________________________________________________phi8: #REF!
Name ________________________________________________________slg1: #REF!
Name ________________________________________________________slg1: #REF!
Name ________________________________________________________slg2: #REF!
Name ________________________________________________________slg2: #REF!
Name ________________________________________________________slg3: #REF!
Name ________________________________________________________slg3: #REF!
Name ________________________________________________________slg4: #REF!
Name ________________________________________________________slg4: #REF!
Name ________________________________________________________slg5: #REF!

Sheet PKL
A1: ADVANCE KNITTING VIETNAM CO., LTD
A2: LOT F5-4, THUAN DAO INDUSTRIAL PARK'S EXPANSION PHASE, LONG CANG COMMUNE, TAY NINH PROVINCE, VIETNAM
A3: TEL:(+84)-723-643-733; (+84)-723-643-734 FAX: (+84)-723-643-735
A4: PACKING LIST
A6: Shipper / Exporter: | J6: No. / Date of Packing List :
A7: ADVANCE KNITTING VIETNAM CO.,LTD | J7: AK/GDI-20260013 | L7: 46174
A8: LOT F5-4, THUAN DAO INDUSTRIAL PARK'S EXPANSION PHASE, LONG CANG COMMUNE, TAY NINH PROVINCE, VIETNAM | J8: No. / Date of Invoice :
A9: TEL:(+84)-723-643-733; (+84)-723-643-734 FAX: (+84)-723-643-735 | J9: =J7 -> AK/GDI-20260013 | L9: =L7 -> 46174
A10: Buyer:
A11: GDI HK LIMITED | J11: No. / Date of Contract :
A12: FLAT H, 2/F MANSION INDUSTRIAL BUILDING, | J12: AK/GDI/CT-202603 | L12: 46163
A13: 8 A KUNG NGAM VILLAGE LANE, SHAU KEI WAN, HONG KONG
A16: Consignee:
A17: PT NIRWANA ALABARE GARMENT
A18: JL. RAYA RANCAEKEK - MAJALAYA , NO.289, DESA SOLOKAN JERUK,
A19: KECAMATAN SOLOKAN JERUK, KABUPATEN BANDUNG JAWA BARAT
A20: 40382, INDONESIA
A21: TAX ID :0745 4069 2644 4000
A22: EMAIL : LUSI@PTNAG.COM YUS.YULIUS@PTNAG.COM
A25: Loading: | E25: Discharge: | J25: Term of Delivery: | L25: CFR JAKARTA INDONESIA
A26: HO CHI MINH | E26: JAKARTA | J26: Origin of Goods: | L26: Vietnam
J27: PO No:
A28: VESSEL: | C28: Delivery date | E28: ETA:
A29: HF LUCKY 2609S | C29: 46180 | E29: 46183 | J29: Term of Payment: | K29: By T/T
C30: POLYESTER KNITTED RIB
A31: CARTON NO | B31: PO | C31: DESCRIPTION OF GOODS | D31: ITEM NO | E31: COLOR | F31: SIZE | H31: REF# | I31: Q'TY | J31: UNIT | K31: Net Weight (Kgs) | L31: Gross Weight (Kgs) | M31: Measurements (CBM)
A32: 1 | B32: SIOB260424002 | C32: 60% BETTER COTTON (BCI) 40% POLYESTER 32S/1x4 PLY FLAT KNIT COLLAR | D32: 1051120 | E32: CALLA LILY 451漂白 | F32: XS | G32: 13-1/4"x3.375” | H32: KD00410 265K0087-A4/ S/769950 | I32: 1003 | J32: PCS | K32: =L32-1.35 -> 20.55 | L32: 21.9 | M32: 0.11
A33: 2 | B33: SIOB260424002 | C33: 60% BETTER COTTON (BCI) 40% POLYESTER 32S/1x4 PLY FLAT KNIT COLLAR | D33: 1051120 | E33: CALLA LILY 451漂白 | F33: S | G33: 13-3/4"x3.375” | H33: KD00410 265K0087-A4/ S/769950 | I33: 1266 | J33: PCS | K33: =L33-1.35 -> 26.85 | L33: 28.2 | M33: 0.11
A34: 3 | B34: SIOB260424002 | C34: 60% BETTER COTTON (BCI) 40% POLYESTER 32S/1x4 PLY FLAT KNIT COLLAR | D34: 1051120 | E34: CALLA LILY 451漂白 | F34: M | G34: 14-1/4"x3.625” | H34: KD00410 265K0087-A4/ S/769950 | I34: 1000 | J34: PCS | K34: =L34-1.35 -> 23.8 | L34: 25.15 | M34: 0.11
A35: 4 | B35: SIOB260424002 | C35: 60% BETTER COTTON (BCI) 40% POLYESTER 32S/1x4 PLY FLAT KNIT COLLAR | D35: 1051120 | E35: CALLA LILY 451漂白 | F35: M | G35: 14-1/4"x3.625” | H35: KD00410 265K0087-A4/ S/769950 | I35: =525+31 -> 556 | J35: PCS | K35: =L35-1.35 -> 29.3 | L35: 30.65 | M35: 0.11
B36: SIOB260424002 | C36: 60% BETTER COTTON (BCI) 40% POLYESTER 32S/1x4 PLY FLAT KNIT COLLAR | D36: 1051120 | E36: CALLA LILY 451漂白 | F36: L | G36: 15"x3.625” | H36: KD00410 265K0087-A4/ S/769950 | I36: =596+52 -> 648 | J36: PCS
A37: 5 | B37: SIOB260424002 | C37: 60% BETTER COTTON (BCI) 40% POLYESTER 32S/1x4 PLY FLAT KNIT COLLAR | D37: 1051120 | E37: CALLA LILY 451漂白 | F37: L | G37: 15"x3.625” | H37: KD00410 265K0087-A4/ S/769950 | I37: 1200 | J37: PCS | K37: =L37-1.35 -> 29.85 | L37: 31.2 | M37: 0.11
A38: 6 | B38: SIOB260424002 | C38: 60% BETTER COTTON (BCI) 40% POLYESTER 32S/1x4 PLY FLAT KNIT COLLAR | D38: 1051120 | E38: CALLA LILY 451漂白 | F38: L | G38: 15"x3.625” | H38: KD00410 265K0087-A4/ S/769950 | I38: 800 | J38: PCS | K38: =L38-1.35 -> 31.2 | L38: 32.55 | M38: 0.11
B39: SIOB260424002 | C39: 60% BETTER COTTON (BCI) 40% POLYESTER 32S/1x4 PLY FLAT KNIT COLLAR | D39: 1051120 | E39: CALLA LILY 451漂白 | F39: XL HUSKY | G39: 16-1/2"x3.625” | H39: KD00410 265K0087-A4/ S/769950 | I39: =406+8 -> 414 | J39: PCS
A40: 7 | B40: SIOB260424002 | C40: 60% BETTER COTTON (BCI) 40% POLYESTER 32S/1x4 PLY FLAT KNIT COLLAR | D40: 1051120 | E40: CALLA LILY 451漂白 | F40: XL | G40: 16"x3.625” | H40: KD00410 265K0087-A4/ S/769950 | I40: 1200 | J40: PCS | K40: =L40-1.35 -> 31.9 | L40: 33.25 | M40: 0.11
A41: 8 | B41: SIOB260424002 | C41: 60% BETTER COTTON (BCI) 40% POLYESTER 32S/1x4 PLY FLAT KNIT COLLAR | D41: 1051120 | E41: CALLA LILY 451漂白 | F41: XL | G41: 16"x3.625” | H41: KD00410 265K0087-A4/ S/769950 | I41: =476+34 -> 510 | J41: PCS | K41: =L41-1.35 -> 30.95 | L41: 32.3 | M41: 0.11
B42: SIOB260424002 | C42: 60% BETTER COTTON (BCI) 40% POLYESTER 32S/1x4 PLY FLAT KNIT COLLAR | D42: 1051120 | E42: CALLA LILY 451漂白 | F42: XXL HUSKY | G42: 17-1/2"x3.625” | H42: KD00410 265K0087-A4/ S/769950 | I42: =595+12 -> 607 | J42: PCS
A43: 9 | B43: SIOB260424002 | C43: 60% BETTER COTTON (BCI) 40% POLYESTER 32S/1x4 PLY FLAT KNIT COLLAR | D43: 1051120 | E43: CALLA LILY 451漂白 | F43: XXL | G43: 17"x3.625” | H43: KD00410 265K0087-A4/ S/769950 | I43: =860+17 -> 877 | J43: PCS | K43: =L43-1.35 -> 30.1 | L43: 31.45 | M43: 0.11
B44: SIOB260424002 | C44: 60% BETTER COTTON (BCI) 40% POLYESTER 32S/1x4 PLY FLAT KNIT COLLAR | D44: 1051120 | E44: CALLA LILY 451漂白 | F44: L HUSKY | G44: 15-1/2"x3.625” | H44: KD00410 265K0087-A4/ S/769950 | I44: =198+4 -> 202 | J44: PCS
A45: 10 | B45: SIOB260424002 | C45: 60% BETTER COTTON (BCI) 40% POLYESTER 32S/1x4 PLY FLAT KNIT COLLAR | D45: 1051120 | E45: IN THE NAVY 172宝蓝色 | F45: XS | G45: 13-1/4"x3.375” | H45: KD00410 265K0087-A4/ S/769950 | I45: =832+17 -> 849 | J45: PCS | K45: =L45-1.35 -> 23.5 | L45: 24.85 | M45: 0.11
...

Sheet PL 
A1: ADVANCE KNITTING VIETNAM CO., LTD
A2: LOT F5-4, THUAN DAO INDUSTRIAL PARK'S EXPANSION PHASE, LONG CANG COMMUNE, TAY NINH PROVINCE, VIETNAM
A3: TEL:(+84)-723-643-733; (+84)-723-643-734 FAX: (+84)-723-643-735
A4: PACKING LIST
A6: Shipper / Exporter: | J6: No. / Date of Packing List :
A7: ADVANCE KNITTING VIETNAM CO.,LTD | J7: AK/GDI-20260013 | L7: 46174
A8: LOT F5-4, THUAN DAO INDUSTRIAL PARK'S EXPANSION PHASE, LONG CANG COMMUNE, TAY NINH PROVINCE, VIETNAM | J8: No. / Date of Invoice :
A9: TEL:(+84)-723-643-733; (+84)-723-643-734 FAX: (+84)-723-643-735 | J9: =J7 -> AK/GDI-20260013 | L9: =L7 -> 46174
A10: Buyer:
A11: GDI HK LIMITED | J11: No. / Date of Contract :
A12: FLAT H, 2/F MANSION INDUSTRIAL BUILDING, | J12: AK/GDI/CT-202603 | L12: 46163
A13: 8 A KUNG NGAM VILLAGE LANE, SHAU KEI WAN, HONG KONG
A16: Consignee:
A17: PT NIRWANA ALABARE GARMENT
A18: JL. RAYA RANCAEKEK - MAJALAYA , NO.289, DESA SOLOKAN JERUK,
A19: KECAMATAN SOLOKAN JERUK, KABUPATEN BANDUNG JAWA BARAT
A20: 40382, INDONESIA
A21: TAX ID :0745 4069 2644 4000
A22: EMAIL : LUSI@PTNAG.COM YUS.YULIUS@PTNAG.COM
A25: Loading: | E25: Discharge: | J25: Term of Delivery: | L25: CFR JAKARTA INDONESIA
A26: HO CHI MINH | E26: JAKARTA | J26: Origin of Goods: | L26: Vietnam
J27: PO No:
A28: VESSEL: | C28: Delivery date | E28: ETA:
A29: HF LUCKY 2609S | C29: 46180 | E29: 46183 | J29: Term of Payment: | K29: By T/T
C30: POLYESTER KNITTED RIB
A31: CARTON NO | B31: PO | C31: DESCRIPTION OF GOODS | D31: ITEM NO | E31: COLOR | F31: SIZE | H31: REF# | I31: Q'TY | J31: UNIT | K31: Net Weight (Kgs) | L31: Gross Weight (Kgs) | M31: Measurements (CBM)
B32: SIOB260424002 | C32: 60% BETTER COTTON (BCI) 40% POLYESTER 32S/1x4 PLY FLAT KNIT COLLAR | D32: 1051120 | E32: CALLA LILY 451漂白 | F32: XS | G32: 13-1/4"x3.375” | H32: KD00410 265K0087-A4/ S/769950 | I32: 1003 | J32: PCS | K32: =L32-1.35 -> 20.55 | L32: 21.9 | M32: 0.11
B33: SIOB260424002 | C33: 60% BETTER COTTON (BCI) 40% POLYESTER 32S/1x4 PLY FLAT KNIT COLLAR | D33: 1051120 | E33: CALLA LILY 451漂白 | F33: S | G33: 13-3/4"x3.375” | H33: KD00410 265K0087-A4/ S/769950 | I33: 1266 | J33: PCS | K33: =L33-1.35 -> 26.85 | L33: 28.2 | M33: 0.11
B34: SIOB260424002 | C34: 60% BETTER COTTON (BCI) 40% POLYESTER 32S/1x4 PLY FLAT KNIT COLLAR | D34: 1051120 | E34: CALLA LILY 451漂白 | F34: M | G34: 14-1/4"x3.625” | H34: KD00410 265K0087-A4/ S/769950 | I34: 1556 | J34: PCS | K34: =L34-1.35 -> 23.8 | L34: 25.15 | M34: 0.11
B35: SIOB260424002 | C35: 60% BETTER COTTON (BCI) 40% POLYESTER 32S/1x4 PLY FLAT KNIT COLLAR | D35: 1051120 | E35: CALLA LILY 451漂白 | F35: L | G35: 15"x3.625” | H35: KD00410 265K0087-A4/ S/769950 | I35: 2648 | J35: PCS | K35: 59.15 | L35: 61.85 | M35: 0.22
B36: SIOB260424002 | C36: 60% BETTER COTTON (BCI) 40% POLYESTER 32S/1x4 PLY FLAT KNIT COLLAR | D36: 1051120 | E36: CALLA LILY 451漂白 | F36: XL HUSKY | G36: 16-1/2"x3.625” | H36: KD00410 265K0087-A4/ S/769950 | I36: =406+8 -> 414 | J36: PCS | K36: =L36-1.35 -> 31.2 | L36: 32.55 | M36: 0.11
B37: SIOB260424002 | C37: 60% BETTER COTTON (BCI) 40% POLYESTER 32S/1x4 PLY FLAT KNIT COLLAR | D37: 1051120 | E37: CALLA LILY 451漂白 | F37: XL | G37: 16"x3.625” | H37: KD00410 265K0087-A4/ S/769950 | I37: 1710 | J37: PCS | K37: =L37-1.35 -> 31.9 | L37: 33.25 | M37: 0.11
B38: SIOB260424002 | C38: 60% BETTER COTTON (BCI) 40% POLYESTER 32S/1x4 PLY FLAT KNIT COLLAR | D38: 1051120 | E38: CALLA LILY 451漂白 | F38: XXL HUSKY | G38: 17-1/2"x3.625” | H38: KD00410 265K0087-A4/ S/769950 | I38: =595+12 -> 607 | J38: PCS | K38: =L38-1.35 -> 30.95 | L38: 32.3 | M38: 0.11
B39: SIOB260424002 | C39: 60% BETTER COTTON (BCI) 40% POLYESTER 32S/1x4 PLY FLAT KNIT COLLAR | D39: 1051120 | E39: CALLA LILY 451漂白 | F39: XXL | G39: 17"x3.625” | H39: KD00410 265K0087-A4/ S/769950 | I39: =860+17 -> 877 | J39: PCS | K39: =L39-1.35 -> 30.1 | L39: 31.45 | M39: 0.11
B40: SIOB260424002 | C40: 60% BETTER COTTON (BCI) 40% POLYESTER 32S/1x4 PLY FLAT KNIT COLLAR | D40: 1051120 | E40: CALLA LILY 451漂白 | F40: L HUSKY | G40: 15-1/2"x3.625” | H40: KD00410 265K0087-A4/ S/769950 | I40: =198+4 -> 202 | J40: PCS
B41: SIOB260424002 | C41: 60% BETTER COTTON (BCI) 40% POLYESTER 32S/1x4 PLY FLAT KNIT COLLAR | D41: 1051120 | E41: IN THE NAVY 172宝蓝色 | F41: XS | G41: 13-1/4"x3.375” | H41: KD00410 265K0087-A4/ S/769950 | I41: =832+17 -> 849 | J41: PCS | K41: =L41-1.35 -> 23.5 | L41: 24.85 | M41: 0.11
B42: SIOB260424002 | C42: 60% BETTER COTTON (BCI) 40% POLYESTER 32S/1x4 PLY FLAT KNIT COLLAR | D42: 1051120 | E42: IN THE NAVY 172宝蓝色 | F42: L HUSKY | G42: 15-1/2"x3.625” | H42: KD00410 265K0087-A4/ S/769950 | I42: =208+4 -> 212 | J42: PCS
B43: SIOB260424002 | C43: 60% BETTER COTTON (BCI) 40% POLYESTER 32S/1x4 PLY FLAT KNIT COLLAR | D43: 1051120 | E43: IN THE NAVY 172宝蓝色 | F43: S | G43: 13-3/4"x3.375” | H43: KD00410 265K0087-A4/ S/769950 | I43: =1336+27 -> 1363 | J43: PCS | K43: =L43-1.35 -> 29.4 | L43: 30.75 | M43: 0.11
B44: SIOB260424002 | C44: 60% BETTER COTTON (BCI) 40% POLYESTER 32S/1x4 PLY FLAT KNIT COLLAR | D44: 1051120 | E44: IN THE NAVY 172宝蓝色 | F44: M | G44: 14-1/4"x3.625” | H44: KD00410 265K0087-A4/ S/769950 | I44: 1680 | J44: PCS | K44: =L44-1.35 -> 28.15 | L44: 29.5 | M44: 0.11
B45: SIOB260424002 | C45: 60% BETTER COTTON (BCI) 40% POLYESTER 32S/1x4 PLY FLAT KNIT COLLAR | D45: 1051120 | E45: IN THE NAVY 172宝蓝色 | F45: XXL | G45: 17"x3.625” | H45: KD00410 265K0087-A4/ S/769950 | I45: =671+13 -> 684 | J45: PCS | K45: =L45-1.35 -> 30.7 | L45: 32.05 | M45: 0.11
...

Sheet INV
A1: ADVANCE KNITTING VIETNAM CO., LTD
A2: LOT F5-4, THUAN DAO INDUSTRIAL PARK'S EXPANSION PHASE, LONG CANG COMMUNE, TAY NINH PROVINCE, VIETNAM
A3: TEL:(+84)-723-643-733; (+84)-723-643-734 FAX: (+84)-723-643-735
A4: COMMERCIAL INVOICE
A5: Shipper / Exporter: | F5: No. / Date of Invoice :
A6: ADVANCE KNITTING VIETNAM CO.,LTD | F6: =PKL!J7 -> AK/GDI-20260013 | G6: =PKL!L7 -> 46174
A7: LOT F5-4, THUAN DAO INDUSTRIAL PARK'S EXPANSION PHASE, LONG CANG | F7: Contract No. / Date:
A8: COMMUNE, TAY NINH PROVINCE, VIETNAM
A9: TEL:(+84)-723-643-733; (+84)-723-643-734 FAX: (+84)-723-643-735 | F9: =PKL!J12 -> AK/GDI/CT-202603 | G9: =PKL!L12 -> 46163
A10: Buyer:
A11: GDI HK LIMITED
A12: FLAT H, 2/F MANSION INDUSTRIAL BUILDING,
A13: 8 A KUNG NGAM VILLAGE LANE, SHAU KEI WAN, HONG KONG
A15: Consignee: | F15: Term of Delivery: CFR JAKARTA INDONESIA
A16: =PKL!A17 -> PT NIRWANA ALABARE GARMENT | F16: Origin of Goods: Vietnam
A17: =PKL!A18 -> JL. RAYA RANCAEKEK - MAJALAYA , NO.289, DESA SOLOKAN JERUK,
A18: =PKL!A19 -> KECAMATAN SOLOKAN JERUK, KABUPATEN BANDUNG JAWA BARAT
A19: =PKL!A20 -> 40382, INDONESIA
A20: =PKL!A21 -> TAX ID :0745 4069 2644 4000
A21: EMAIL : LUSI@PTNAG.COM YUS.YULIUS@PTNAG.COM
A23: Loading: | C23: Discharge:
A24: =PKL!A26 -> HO CHI MINH | C24: =PKL!E26 -> JAKARTA
A27: VESSEL: | C27: Delivery date | D27: ETA:
A28: =PKL!A29 -> HF LUCKY 2609S | C28: 46180 | D28: 46183 | F28: Term of Payment: By T/T
A29: PO | B29: REF# | C29: ITEM NO | D29: DESCRIPTION OF GOODS | E29: COLOR | F29: SIZE | G29: QUANTITY | H29: Unit | I29: UNIT PRICE (USD) | J29: AMOUNT (USD)
A30: SIOB260424002 | B30: KD00410 265K0087-A4/ S/769950 | C30: 1051120 | D30: 60% BETTER COTTON (BCI) 40% POLYESTER 32S/1x4 PLY FLAT KNIT COLLAR | E30: CALLA LILY 451漂白 | F30: XS | G30: 1003 | H30: PCS | I30: 0.19 | J30: =ROUND(G30*I30,2) -> 190.57
A31: SIOB260424002 | B31: KD00410 265K0087-A4/ S/769950 | C31: 1051120 | D31: 60% BETTER COTTON (BCI) 40% POLYESTER 32S/1x4 PLY FLAT KNIT COLLAR | E31: CALLA LILY 451漂白 | F31: S | G31: 1266 | H31: PCS | I31: 0.19 | J31: =ROUND(G31*I31,2) -> 240.54
A32: SIOB260424002 | B32: KD00410 265K0087-A4/ S/769950 | C32: 1051120 | D32: 60% BETTER COTTON (BCI) 40% POLYESTER 32S/1x4 PLY FLAT KNIT COLLAR | E32: CALLA LILY 451漂白 | F32: M | G32: 1556 | H32: PCS | I32: 0.19 | J32: =ROUND(G32*I32,2) -> 295.64
A33: SIOB260424002 | B33: KD00410 265K0087-A4/ S/769950 | C33: 1051120 | D33: 60% BETTER COTTON (BCI) 40% POLYESTER 32S/1x4 PLY FLAT KNIT COLLAR | E33: CALLA LILY 451漂白 | F33: L | G33: 2648 | H33: PCS | I33: 0.19 | J33: =ROUND(G33*I33,2) -> 503.12
A34: SIOB260424002 | B34: KD00410 265K0087-A4/ S/769950 | C34: 1051120 | D34: 60% BETTER COTTON (BCI) 40% POLYESTER 32S/1x4 PLY FLAT KNIT COLLAR | E34: CALLA LILY 451漂白 | F34: XL | G34: 1710 | H34: PCS | I34: 0.19 | J34: =ROUND(G34*I34,2) -> 324.9
A35: SIOB260424002 | B35: KD00410 265K0087-A4/ S/769950 | C35: 1051120 | D35: 60% BETTER COTTON (BCI) 40% POLYESTER 32S/1x4 PLY FLAT KNIT COLLAR | E35: CALLA LILY 451漂白 | F35: XXL | G35: 877 | H35: PCS | I35: 0.19 | J35: =ROUND(G35*I35,2) -> 166.63
A36: SIOB260424002 | B36: KD00410 265K0087-A4/ S/769950 | C36: 1051120 | D36: 60% BETTER COTTON (BCI) 40% POLYESTER 32S/1x4 PLY FLAT KNIT COLLAR | E36: CALLA LILY 451漂白 | F36: L HUSKY | G36: 202 | H36: PCS | I36: 0.19 | J36: =ROUND(G36*I36,2) -> 38.38
A37: SIOB260424002 | B37: KD00410 265K0087-A4/ S/769950 | C37: 1051120 | D37: 60% BETTER COTTON (BCI) 40% POLYESTER 32S/1x4 PLY FLAT KNIT COLLAR | E37: CALLA LILY 451漂白 | F37: XL HUSKY | G37: 414 | H37: PCS | I37: 0.19 | J37: =ROUND(G37*I37,2) -> 78.66
A38: SIOB260424002 | B38: KD00410 265K0087-A4/ S/769950 | C38: 1051120 | D38: 60% BETTER COTTON (BCI) 40% POLYESTER 32S/1x4 PLY FLAT KNIT COLLAR | E38: CALLA LILY 451漂白 | F38: XXL HUSKY | G38: 607 | H38: PCS | I38: 0.19 | J38: =ROUND(G38*I38,2) -> 115.33
A39: SIOB260424002 | B39: KD00410 265K0087-A4/ S/769950 | C39: 1051120 | D39: 60% BETTER COTTON (BCI) 40% POLYESTER 32S/1x4 PLY FLAT KNIT COLLAR | E39: IN THE NAVY 172宝蓝色 | F39: XS | G39: 849 | H39: PCS | I39: 0.182 | J39: =ROUND(G39*I39,2) -> 154.52
A40: SIOB260424002 | B40: KD00410 265K0087-A4/ S/769950 | C40: 1051120 | D40: 60% BETTER COTTON (BCI) 40% POLYESTER 32S/1x4 PLY FLAT KNIT COLLAR | E40: IN THE NAVY 172宝蓝色 | F40: S | G40: 1363 | H40: PCS | I40: 0.182 | J40: =ROUND(G40*I40,2) -> 248.07
A41: SIOB260424002 | B41: KD00410 265K0087-A4/ S/769950 | C41: 1051120 | D41: 60% BETTER COTTON (BCI) 40% POLYESTER 32S/1x4 PLY FLAT KNIT COLLAR | E41: IN THE NAVY 172宝蓝色 | F41: M | G41: 1680 | H41: PCS | I41: 0.182 | J41: =ROUND(G41*I41,2) -> 305.76
... A47: SIOB260424002 | B47: KD00410 265K0087-A4/ S/769950 | C47: 1051120 | D47: 60% BETTER COTTON (BCI) 40% POLYESTER 32S/1x4 PLY FLAT KNIT COLLAR | E47: IN THE NAVY 172宝蓝色 | F47: XXL HUSKY | G47: 560 | H47: PCS | I47: 0.182 | J47: =ROUND(G47*I47,2) -> 101.92
D48: TOTAL | G48: =SUM(G30:G47) -> 19888 | H48: PCS | I48: USD | J48: =SUM(J30:J47) -> 3701.89
A49: SAY: | B49: US DOLLAR THREE THOUSAND SEVEN HUNDRED ONE AND EIGHTY NINE CENTS ONLY.
...

Sheet TEM
A1: SHIMADA 4
A2: Carton No | B2: PO NUMBER | D2: DESCRIPTION OF GOODS | E2: PRODUCT CODE | F2: COLOR | H2: SIZE | I2: LOT | J2: Q'TY | K2: UNIT | L2: Net Weight (Kgs) | M2: Gross Weight (Kgs) | N2: Measurements (CBM)
A3: 14 | B3: PO-DMBK-I-2435/25 | C3: ĐƠN 4 | D3: (H25234206(TL-1)) POLYESTER KNITTED RIB SIZE S 100% POLYESTER | E3: H25234206(TL-1) | F3: 1030 | G3: S | H3: 7.5*37.5 CM | I3: GT250128 | J3: 98 | K3: PCS | L3: =M3-1.35 -> 28.95 | M3: 30.3 | N3: 0.11
B4: PO-DMBK-I-2435/25 | C4: ĐƠN 4 | D4: (H25234206(TL-1)) POLYESTER KNITTED RIB SIZE S 100% POLYESTER | E4: H25234206(TL-1) | F4: 1030 | G4: M | H4: 7.5*38.5 CM | I4: GT250128 | J4: 219 | K4: PCS
B5: PO-DMBK-I-2435/25 | C5: ĐƠN 4 | D5: (H25234206(TL-1)) POLYESTER KNITTED RIB SIZE S 100% POLYESTER | E5: H25234206(TL-1) | F5: 1030 | G5: L | H5: 7.5*39.5 CM | I5: GT250128 | J5: 208 | K5: PCS
B6: PO-DMBK-I-2435/25 | C6: ĐƠN 4 | D6: (H25234206(TL-1)) POLYESTER KNITTED RIB SIZE S 100% POLYESTER | E6: H25234206(TL-1) | F6: 1030 | G6: LL | H6: 7.5*40.5 CM | I6: GT250128 | J6: 84 | K6: PCS
B7: PO-DMBK-I-2432/25 | C7: ĐƠN 4 | D7: (H25234110(TM-1)) POLYESTER KNITTED RIB SIZE 3L 100% POLYESTER | E7: H25234110(TM-1) | F7: 1030 | G7: M | H7: 8*41 CM | I7: GT250128 | J7: 209 | K7: PCS
B8: PO-DMBK-I-2432/25 | C8: ĐƠN 4 | D8: (H25234110(TM-1)) POLYESTER KNITTED RIB SIZE 3L 100% POLYESTER | E8: H25234110(TM-1) | F8: 1030 | G8: L | H8: 8*42.5 CM | I8: GT250128 | J8: 412 | K8: PCS
B9: PO-DMBK-I-2432/25 | C9: ĐƠN 4 | D9: (H25234110(TM-1)) POLYESTER KNITTED RIB SIZE 3L 100% POLYESTER | E9: H25234110(TM-1) | F9: 1030 | G9: LL | H9: 8*44 CM | I9: GT250128 | J9: 330 | K9: PCS
B10: PO-DMBK-I-2432/25 | C10: ĐƠN 4 | D10: (H25234110(TM-1)) POLYESTER KNITTED RIB SIZE 3L 100% POLYESTER | E10: H25234110(TM-1) | F10: 1030 | G10: 3L | H10: 8*45.5 CM | I10: GT250128 | J10: 199 | K10: PCS
A11: =COUNT(A3:A10) -> 1 | J11: =SUM(J3:J10) -> 1759 | K11: PCS | L11: =SUM(L3:L10) -> 28.95 | M11: =SUM(M3:M10) -> 30.3 | N11: =SUM(N3:N10) -> 0.11
A12: MADE IN VIETNAM
F13: ADVANCE KNITTING VIETNAM CO., LTD
J14: Signature, full name, seal

Sheet DELIVERY INSTRUCTION
A2: DELIVERY INSTRUCTION
A3: No. | B3: : | C3: =PKL!J7 -> AK/GDI-20260013
A4: Date | B4: : | C4: =PKL!L7 -> 46174
A6: Pursuant to Contract No. | B6: : | C6: AK/GDI/CT-202512 on Dec. 17, 2025
A9: We (Buyer) hereby | B9: : | C9: =PKL!A11 -> GDI HK LIMITED
C10: ADD: FLAT H, 2/F MANSION INDUSTRIAL BUILDING, 8 A KUNG NGAM VILLAGE LANE, SHAU KEI WAN, HONG KONG
A12: To appoint to Seller | C12: ADVANCE KNITTING VIETNAM CO.,LTD
C13: LOT F5-4, THUAN DAO INDUSTRIAL PARK'S EXPANSION PHASE, LONG CANG COMMUNE, TAY NINH PROVINCE, VIETNAM
C14: TEL:(+84)-723-643-733; (+84)-723-643-734 FAX: (+84)-723-643-735
A15: To release cargo to Consignee | B15: : | C15: =PKL!A17 -> PT NIRWANA ALABARE GARMENT
C16: NO.18 THONG NHAT ROAD, SONG THAN INDUSTRIAL ZONE II,DI AN WARD,
C17: HO CHI MINH CITY, VIETNAM.
C18: TAX CODE :3700346873
C19: TEL :0084-274.3790.780|Ext.:260
A20: Notify party: | C20: KANMAX ENTERPRISES LIMITED
C21: ADD: 60 PAYA LEBAR ROAD, #04-21 PAYA LEBAR SQUARE, SINGAPORE 409051, SINGAPORE.
C22: TEL: 65 6702 1179 FAX : FAX: 65 6702 1182
A23: As the followings
A25: PO | B25: REF# | D25: ITEM NO | E25: DESCRIPTION OF GOODS | F25: COLOR | G25: SIZE | H25: QUANTITY | I25: Unit | J25: UNIT PRICE (USD) | K25: AMOUNT (USD)
A26: SIOB251105016 | B26: KV06800 263K0033-B~E4(3RD MB)/ S/416363 | D26: 1051120 | E26: 60% BETTER COTTON (BCI) 40% POLYESTER 32S/1x4 PLY FLAT KNIT COLLAR | F26: BLACK JACK 400黑色 | G26: XS | H26: 1152 | I26: PCS | J26: 0.17 | K26: =ROUND(H26*J26,3) -> 195.84
A27: SIOB251105016 | B27: KV06800 263K0033-B~E4(3RD MB)/ S/416363 | D27: 1051120 | E27: 60% BETTER COTTON (BCI) 40% POLYESTER 32S/1x4 PLY FLAT KNIT COLLAR | F27: BLACK JACK 400黑色 | G27: S | H27: 2703 | I27: PCS | J27: 0.17 | K27: =ROUND(H27*J27,3) -> 459.51
A28: SIOB251105016 | B28: KV06800 263K0033-B~E4(3RD MB)/ S/416363 | D28: 1051120 | E28: 60% BETTER COTTON (BCI) 40% POLYESTER 32S/1x4 PLY FLAT KNIT COLLAR | F28: BLACK JACK 400黑色 | G28: M | H28: 1869 | I28: PCS | J28: 0.17 | K28: =ROUND(H28*J28,3) -> 317.73
A29: SIOB251105016 | B29: KV06800 263K0033-B~E4(3RD MB)/ S/416363 | D29: 1051120 | E29: 60% BETTER COTTON (BCI) 40% POLYESTER 32S/1x4 PLY FLAT KNIT COLLAR | F29: BLACK JACK 400黑色 | G29: L | H29: 3823 | I29: PCS | J29: 0.17 | K29: =ROUND(H29*J29,3) -> 649.91
A30: SIOB251105016 | B30: KV06800 263K0033-B~E4(3RD MB)/ S/416363 | D30: 1051120 | E30: 60% BETTER COTTON (BCI) 40% POLYESTER 32S/1x4 PLY FLAT KNIT COLLAR | F30: BLACK JACK 400黑色 | G30: XL | H30: 2332 | I30: PCS | J30: 0.17 | K30: =ROUND(H30*J30,3) -> 396.44
A31: SIOB251105016 | B31: KV06800 263K0033-B~E4(3RD MB)/ S/416363 | D31: 1051120 | E31: 60% BETTER COTTON (BCI) 40% POLYESTER 32S/1x4 PLY FLAT KNIT COLLAR | F31: BLACK JACK 400黑色 | G31: XXL | H31: 1744 | I31: PCS | J31: 0.17 | K31: =ROUND(H31*J31,3) -> 296.48
A32: SIOB251105016 | B32: KV06800 263K0033-B~E4(3RD MB)/ S/416363 | D32: 1051120 | E32: 60% BETTER COTTON (BCI) 40% POLYESTER 32S/1x4 PLY FLAT KNIT COLLAR | F32: BLACK JACK 400黑色 | G32: L HUSKY | H32: 205 | I32: PCS | J32: 0.17 | K32: =ROUND(H32*J32,3) -> 34.85
A33: SIOB251105016 | B33: KV06800 263K0033-B~E4(3RD MB)/ S/416363 | D33: 1051120 | E33: 60% BETTER COTTON (BCI) 40% POLYESTER 32S/1x4 PLY FLAT KNIT COLLAR | F33: BLACK JACK 400黑色 | G33: XL HUSKY | H33: 147 | I33: PCS | J33: 0.17 | K33: =ROUND(H33*J33,3) -> 24.99
A34: SIOB251105016 | B34: KV06800 263K0033-B~E4(3RD MB)/ S/416363 | D34: 1051120 | E34: 60% BETTER COTTON (BCI) 40% POLYESTER 32S/1x4 PLY FLAT KNIT COLLAR | F34: BLACK JACK 400黑色 | G34: XXL HUSKY | H34: 186 | I34: PCS | J34: 0.17 | K34: =ROUND(H34*J34,3) -> 31.62
B35: TOTAL | H35: =SUM(H26:H34) -> 14161 | I35: PCS | J35: USD | K35: =SUM(K26:K34) -> 2407.37
A38: AMOUNT IN WORDS | C38: =INV!B49 -> US DOLLAR THREE THOUSAND SEVEN HUNDRED ONE AND EIGHTY NINE CENTS ONLY.
A39: ARTICLE 2: ORIGIN OF VIETNAM
A40: ARTICLE 3: PACKING | C40: Export Standard Packing
A41: ARTICLE 4: DELIVERY AND PAYMENT
A42: *Delivery | C42: By Truck/ Lalamove
A43: *Delivery Time | C43: =PKL!E29 -> 46183
A44: *Delivery Term | C44: DAP HO CHI MINH
A45: *Bill To | C45: =C9 -> GDI HK LIMITED
A46: We kindly request the relevant parties to perform the delivery and receipt of goods in accordance with the above instruction and comply with the customs
A48: For and on behalf of Buyer

Sheet SC
A1: ADVANCE KNITTING VIETNAM CO., LTD
A2: LOT F5-4, THUAN DAO INDUSTRIAL PARK'S EXPANSION PHASE, LONG CANG COMMUNE, TAY NINH PROVINCE, VIETNAM
A3: TEL:(+84)-723-643-733; (+84)-723-643-734 FAX: (+84)-723-643-735
A4: SALE CONTRACT
A6: BUYER: GDI HK LIMITED | H6: No: | I6: SIOB251103005-1
A7: FLAT H, 2/F MANSION INDUSTRIAL BUILDING, 8 A KUNG NGAM VILLAGE LANE, SHAU KEI WAN, HONG KONG | H7: Date: | I7: 46018
A9: BASE ON PO NO SIOB251103005 SIGNED ON NOVEMBER 03, 2025 ; ADVANCE KNITTING VIETNAM CO.,LTD AS SELLER , HEREBY CONFIRMS HAVING SOLD THE REMAIN QUANTITY OF THIS PO TO YOUR FIRM
A10: THE FOLLOWING GOODS BY CONTRACT OF SALE MADE ON THE ABOVE DATE AND ON THE TERNMS AND
A11: CONDITIONS HEREAFTER SET FORTH:
A12: COMMODITY | C12: : | D12: CLOTHING ACCESSORIES
A14: PO | B14: REF# | C14: ITEM NO | D14: DESCRIPTION OF GOODS | E14: COLOR | F14: SIZE | G14: QUANTITY | H14: Unit | I14: UNIT PRICE (USD) | J14: AMOUNT (USD)
A15: SIOB251103005 | B15: KV06798 263K0033-A2+~A4(1ST LOT)/S/416363 | C15: 1051120 | D15: 60% BETTER COTTON (BCI) 40% POLYESTER 32S/1x4 PLY FLAT KNIT COLLAR | E15: MONET BLUE 744油画蓝 | F15: XL | G15: 41 | H15: PCS | I15: 0.17 | J15: 6.97
A16: SIOB251103005 | B16: KV06798 263K0033-A2+~A4(1ST LOT)/S/416363 | C16: 1051120 | D16: 60% BETTER COTTON (BCI) 40% POLYESTER 32S/1x4 PLY FLAT KNIT COLLAR | E16: MONET BLUE 744油画蓝 | F16: XXL | G16: 12 | H16: PCS | I16: 0.17 | J16: 2.04
A17: SIOB251103005 | B17: KV06798 263K0033-A2+~A4(1ST LOT)/S/416363 | C17: 1051120 | D17: 60% BETTER COTTON (BCI) 40% POLYESTER 32S/1x4 PLY FLAT KNIT COLLAR | E17: BLACK JACK 400黑色 | F17: S | G17: 123 | H17: PCS | I17: 0.17 | J17: 20.91
A18: SIOB251103005 | B18: KV06798 263K0033-A2+~A4(1ST LOT)/S/416363 | C18: 1051120 | D18: 60% BETTER COTTON (BCI) 40% POLYESTER 32S/1x4 PLY FLAT KNIT COLLAR | E18: BLACK JACK 400黑色 | F18: XL HUSKY | G18: 52 | H18: PCS | I18: 0.17 | J18: 8.84
A19: SIOB251103005 | B19: KV06798 263K0033-A2+~A4(1ST LOT)/S/416363 | C19: 1051120 | D19: 60% BETTER COTTON (BCI) 40% POLYESTER 32S/1x4 PLY FLAT KNIT COLLAR | E19: BLACK JACK 400黑色 | F19: XXL HUSKY | G19: 31 | H19: PCS | I19: 0.17 | J19: 5.27
C20: TOTAL | G20: =SUM(G15:G19) -> 259 | H20: PCS | I20: USD | J20: =SUM(J15:J19) -> 44.03
A23: QUALITY | C23: : | D23: AS PER ADVANCE KNITTING VIETNAM'S STANDARD GRADE
A24: QUANTITY | C24: : | D24: =G20 -> 259 | E24: PCS
A25: PACKING MARKING | C25: : | D25: EXPORT STANDARD PACKING IN TRUCK
A26: TOTAL AMOUNT OF CONTRACT | C26: : | D26: =J20 -> 44.03
D27: US DOLLAR FORTY FOUR AND THREE CENTS ONLY.
A28: TERMS OF PAYMENT | C28: : | D28: T/T 100% PAYMENT WITHIN 30 DAYS DELIVERY
A29: DELIVERY PLACE: | C29: : | D29: BUYER NOMINATE SELLER DELIVER GOODS TO CONSIGNEE BELOW:
D30: CHUTEX INTERNATIONAL CO.,LTD
D31: NO.18 THONG NHAT ROAD, SONG THAN INDUSTRIAL ZONE II,DI AN WARD,
D32: HO CHI MINH CITY, VIETNAM.
A33: DELIVERY TERM: | D33: DAP HO CHI MINH
A34: NOTIFY PARTY (IF NEEDED) | D34: =PKL!#REF! -> #REF!
D35: =PKL!#REF! -> #REF!
D36: =PKL!#REF! -> #REF!
A37: OUR BANK | C37: : | D37: JOINT STOCK COMMERCIAL BANK FOR FOREIGN TRADE OF VIET NAM (VIETCOMBANK)
A38: BRANCH | C38: : | D38: 2A PHAM VAN NGU STREET, BEN LUC DISTRICT, LONG AN PROVINCE, VIET NAM
A39: ACCOUNT NO. | C39: : | D39: 0631370457237
A40: SWIFT CODE | C40: : | D40: BFTVVNVX
A41: TIME OF SHIPMENT | C41: : | D41: =PKL!C29 -> 46180
A42: FROM | C42: : | D42: TAY NINH
A43: DESTINATION : | C43: : | D43: HO CHI MINH
A44: INSPECTION | C44: : | D44: ADVANCE KNITTING VIETNAM FACTORY 'S INSPECTION TO BE TAKEN AS FINAL
A45: OTHER CONDITIONS | C45: : | D45: PRICE ADJUSTMENT FOR INFERIOR PRODUCTS IF ANY SHALL BE SETTLED BY THE
...

Sheet IN PHIẾU XUẤT 
I1: Mẫu số: 02-VT
D2: 出货明细 PHIẾU XUẤT KHO | I2: (Ban hành theo TT số: 200/2014/TT-BTC)
A3: Lô F5-4, KCN Thuận Đạo, huyện Cần Đước, tỉnh Long An | I3: Ngày 22/12/2014 của bộ trưởng BTC
C4: =NOW() -> 46177.79 | I4: Nợ……………...........
C5: PXK:SH28032025 | I5: Có……………............
A6: Họ tên người nhận hàng 领料员: | H6: PO:
A7: Khách hàng/ Bộ phận 部门SHIMADA SHOJI (VIETNAM) CO., LTD | H7: Biển kiểm soát :
A8: Địa chỉ 地址Lô số 21-1, 21-2 và 21-3, Đường số 8B, Khu Công Nghiệp Quốc Tế Protrade,Xã An Tây, Thị xã Bến Cát, T.BD.VN
A9: Lý do xuất kho: | C9: XUẤT THÀNH PHẨM 出口成品
A10: Xuất tại kho: | C10: CÔNG TY TNHH ADVANCE KNITTING VIỆT NAM
A11: Ghi chú备注: 15 THÙNG
A12: STT | B12: PO | C12: 色號 Mã màu | D12: 缸号 Mã Lot | E12: 尺寸 Quy cách | G12: 单位 Đơn vị | H12: 数量 Số lượng | I12: Ghi chú 备注
H13: 良品数量 Thực xuất
A14: 1 | B14: PO-DMBK-I-1669(HN)/25 | C14: NVY | D14: GT240114 | E14: 140MMX500MM | G14: PCS | H14: 238
A15: 2 | B15: PO-DMBK-I-1669(HN)/25 | C15: WHT | D15: GT240815 | E15: 140MMX500MM | G15: PCS | H15: 361
A16: 3 | B16: PO-DMBK-I-1669(HN)/25 | C16: ABN | D16: GT250221 | E16: 140MMX500MM | G16: PCS | H16: 64
A17: 4 | B17: PO-DMBK-I-2418/25 | C17: 1120(NAVY) | D17: GT250204 | E17: M | F17: 6.5X50CM | G17: PCS | H17: 214
A18: 5 | B18: PO-DMBK-I-2418/25 | C18: 1120(NAVY) | D18: GT250204 | E18: L | F18: 6.5X50CM | G18: PCS | H18: 353
A19: 6 | B19: PO-DMBK-I-2418/25 | C19: 1120(NAVY) | D19: GT250204 | E19: LL | F19: 6.5X50CM | G19: PCS | H19: 177
A20: 7 | B20: PO-DMBK-I-2418/25 | C20: 1120(NAVY) | D20: GT250204 | E20: 3L | F20: 6.5X50CM | G20: PCS | H20: 96
A21: 8 | B21: PO-DMBK-I-2418/25 | C21: 1030(WHITE) | D21: GT250204 | E21: M | F21: 6.5X50CM | G21: PCS | H21: 298
A22: 9 | B22: PO-DMBK-I-2418/25 | C22: 1030(WHITE) | D22: GT250204 | E22: L | F22: 6.5X50CM | G22: PCS | H22: 496
A23: 10 | B23: PO-DMBK-I-2418/25 | C23: 1030(WHITE) | D23: GT250204 | E23: LL | F23: 6.5X50CM | G23: PCS | H23: 247
A24: 11 | B24: PO-DMBK-I-2418/25 | C24: 1030(WHITE) | D24: GT250204 | E24: 3L | F24: 6.5X50CM | G24: PCS | H24: 129
A25: 12 | B25: PO-DMBK-I-2418/25 | C25: 1140(GREEN) | D25: GT250204 | E25: M | F25: 6.5X50CM | G25: PCS | H25: 162
A26: 13 | B26: PO-DMBK-I-2418/25 | C26: 1140(GREEN) | D26: GT250204 | E26: L | F26: 6.5X50CM | G26: PCS | H26: 272
A27: 14 | B27: PO-DMBK-I-2418/25 | C27: 1140(GREEN) | D27: GT250204 | E27: LL | F27: 6.5X50CM | G27: PCS | H27: 135
A28: 15 | B28: PO-DMBK-I-2418/25 | C28: 1140(GREEN) | D28: GT250204 | E28: 3L | F28: 6.5X50CM | G28: PCS | H28: 71
... A32: 19 | B32: PO-DMBK-I-2418/25 | C32: 1110(RED) | D32: GT250204 | E32: 3L | F32: 6.5X50CM | G32: PCS | H32: 47
A33: 20 | B33: PO-DMBK-I-2435/25 | C33: 1030 | D33: GT250128 | E33: S | F33: 7.5*37.5 CM | G33: PCS | H33: 98
A34: 21 | B34: PO-DMBK-I-2435/25 | C34: 1030 | D34: GT250128 | E34: M | F34: 7.5*38.5 CM | G34: PCS | H34: 219
A35: 22 | B35: PO-DMBK-I-2435/25 | C35: 1030 | D35: GT250128 | E35: L | F35: 7.5*39.5 CM | G35: PCS | H35: 208
A36: 23 | B36: PO-DMBK-I-2435/25 | C36: 1030 | D36: GT250128 | E36: LL | F36: 7.5*40.5 CM | G36: PCS | H36: 84
A37: 24 | B37: PO-DMBK-I-2432/25 | C37: 1030 | D37: GT250128 | E37: M | F37: 8*41 CM | G37: PCS | H37: 209
A38: 25 | B38: PO-DMBK-I-2432/25 | C38: 1030 | D38: GT250128 | E38: L | F38: 8*42.5 CM | G38: PCS | H38: 412
A39: 26 | B39: PO-DMBK-I-2432/25 | C39: 1030 | D39: GT250128 | E39: LL | F39: 8*44 CM | G39: PCS | H39: 330
A40: 27 | B40: PO-DMBK-I-2432/25 | C40: 1030 | D40: GT250128 | E40: 3L | F40: 8*45.5 CM | G40: PCS | H40: 199
A41: 28 | B41: PO-DMBK-I-2435/25 | C41: 1120 | D41: GT250128 | E41: S | F41: 7.5*37.5 CM | G41: PCS | H41: 42
A42: 29 | B42: PO-DMBK-I-2435/25 | C42: 1120 | D42: GT250128 | E42: M | F42: 7.5*38.5 CM | G42: PCS | H42: 112
A43: 30 | B43: PO-DMBK-I-2435/25 | C43: 1120 | D43: GT250128 | E43: L | F43: 7.5*39.5 CM | G43: PCS | H43: 105
...
