Workbook
Name _box2: [1]参数!$B$3
Name a: [2]xdata!#REF!
Name a: [2]xdata!#REF!
Name a: [2]xdata!#REF!
Name a: [2]xdata!#REF!
Name a: [2]xdata!#REF!
Name a: [2]xdata!#REF!
Name a: [2]xdata!#REF!
Name a: [2]xdata!#REF!
Name a: [2]xdata!#REF!
Name a: [2]xdata!#REF!
Name a: [2]xdata!#REF!
Name b: [2]xdata!#REF!
Name b: [2]xdata!#REF!
Name b: [2]xdata!#REF!
Name b: [2]xdata!#REF!
Name b: [2]xdata!#REF!
Name b: [2]xdata!#REF!
Name b: [2]xdata!#REF!
Name b: [2]xdata!#REF!
Name b: [2]xdata!#REF!
Name b: [2]xdata!#REF!
Name b: [2]xdata!#REF!
Name C_O: [2]xdata!#REF!
Name C_O: [2]xdata!#REF!
Name C_O: [2]xdata!#REF!
Name C_O: [2]xdata!#REF!
Name C_O: [2]xdata!#REF!
Name C_O: [2]xdata!#REF!
Name C_O: [2]xdata!#REF!
Name C_O: [2]xdata!#REF!
Name C_O: [2]xdata!#REF!
Name C_O: [2]xdata!#REF!
Name C_O: [2]xdata!#REF!
Name CBM: [3]参数!$E$3
Name Dept_no: [2]xdata!#REF!
Name Dept_no: [2]xdata!#REF!
Name Dept_no: [2]xdata!#REF!
Name Dept_no: [2]xdata!#REF!
Name Dept_no: [2]xdata!#REF!
Name Dept_no: [2]xdata!#REF!
Name Dept_no: [2]xdata!#REF!
Name Dept_no: [2]xdata!#REF!
Name Dept_no: [2]xdata!#REF!
Name Dept_no: [2]xdata!#REF!
Name Dept_no: [2]xdata!#REF!
Name Description: [3]参数!$E$1
Name E_L: [2]xdata!#REF!
Name E_L: [2]xdata!#REF!
Name E_L: [2]xdata!#REF!
Name E_L: [2]xdata!#REF!
Name E_L: [2]xdata!#REF!
Name E_L: [2]xdata!#REF!
Name E_L: [2]xdata!#REF!
Name E_L: [2]xdata!#REF!
Name E_L: [2]xdata!#REF!
Name E_L: [2]xdata!#REF!
Name E_L: [2]xdata!#REF!
Name INVOICE: [2]xdata!$B$2
Name v: [2]xdata!#REF!

Sheet Sheet1
B3: Seller | D3: Buyer | F3: Final Destination
B5: KANMAX ENTERPRISES LTD | D5: OLD NAVY, LLC | F5: FISHKILL NY ONLINE-0007 | G5: ODC-0018 | H5: OHO OHIO OMNI-0016 | I5: WESTERN OMNI WEO-0008 | K5: =D5 -> OLD NAVY, LLC | L5: =F5 -> FISHKILL NY ONLINE-0007
B6: 60 PAYA LEBAR ROAD | D6: 2 FOLSOM STREET | F6: 110 MERRITT BLVD | G6: 110 MERRITT BLVD | H6: 6001 GREEN POINTE DR S | I6: 3400 NORTH GAP DR | K6: =D11 -> GPS STRATEGIC ALLIANCES, LLC | L6: =G5 -> ODC-0018
B7: #04-21 PAYA LEBAR SQUARE | D7: SAN FRANCISCO, CALIFORNIA | F7: FISHKILL, NY | G7: FISHKILL, NY | H7: GROVEPORT, OH | I7: FRESNO, CA | K7: =D17 -> OLD NAVY (CANADA) INC. | L7: =H5 -> OHO OHIO OMNI-0016
B8: 409051 | D8: 94105 | F8: 12524 | G8: 12524 | H8: 43125 | I8: 93727 | K8: =D23 -> GAP (UK HOLDINGS) LIMITED | L8: =I5 -> WESTERN OMNI WEO-0008
B9: SINGAPORE | D9: UNITED STATES | F9: UNITED STATES | G9: UNITED STATES | H9: UNITED STATES | I9: UNITED STATES | K9: =D29 -> GAP EUROPE LIMITED | L9: =F11 -> FDC-0026
K10: =D35 -> GPS STRATEGIC ALLIANCES, LLC | L10: =G11 -> LVO LONGVIEW OMNI-0047
B11: CHARLES'S WAIN WORLDWIDE CORP | D11: GPS STRATEGIC ALLIANCES, LLC | F11: FDC-0026 | G11: LVO LONGVIEW OMNI-0047 | H11: SDC-0017 | I11: EXPEDITORS INTL LRD OLD NAVY, LLC | K11: =D41 -> THE GAP, INC. | L11: =H11 -> SDC-0017
B12: 8A JALAN HARMONIUM 35/2 | D12: 55 THOMAS ST | F12: 3685 NORTH GAP DRIVE | G12: 5401 MICKEY MELTON BLD | H12: 100 GAP BOULEVARD | I12: 8510 BOB BULLOCK LOOP | K12: =D47 -> GAP JAPAN K.K. | L12: =I11 -> EXPEDITORS INTL LRD OLD NAVY, LLC
B13: TAMAN DESA TERBAU, JOHOR BAHRU | D13: NEW YORK, NY | F13: FRESNO, CA | G13: LONGVIEW, TX | H13: GALLATIN, TN | I13: LAREDO, TX | L13: =F17 -> BDC-0015
B14: JOHOR 81100 | D14: 10013 | F14: 93727 | G14: 75605 | H14: 37066 | I14: 78045 | L14: =G17 -> CANADA OMNI CAO-0040
B15: MALAYSIA | D15: UNITED STATES | F15: UNITED STATES | G15: UNITED STATES | H15: UNITED STATES | I15: UNITED STATES | L15: =H17 -> MDC OLD NAVY, LLC
L16: =I17 -> MULTIBRAND WHLSL GPS STRATEGIC ALLIANCES, LLC
B17: =B5 -> KANMAX ENTERPRISES LTD | D17: OLD NAVY (CANADA) INC. | F17: BDC-0015 | G17: CANADA OMNI CAO-0040 | H17: MDC OLD NAVY, LLC | I17: MULTIBRAND WHLSL GPS STRATEGIC ALLIANCES, LLC | L17: =F23 -> HKG DC
B18: =B11 -> CHARLES'S WAIN WORLDWIDE CORP | D18: 9500 MCLAUGHLIN ROAD N | F18: 9500 MCLAUGHLIN ROAD N | G18: 9500 MCLAUGHLIN ROAD N | H18: 9271 MERIDIAN WAY | I18: AVENIDA RANDOLPH | L18: =G23 -> EDC(EU FRANCHISE HUB)
D19: BRAMPTON, ONTARIO | F19: BRAMPTON, ONTARIO | G19: BRAMPTON, ONTARIO | H19: WEST CHESTER, OH | I19: MANZANA 10 | L19: =H23 -> EXPEDITORS INT'L GPS STRATEGIC ALLIANCES, LLC
D20: L6X 0B8 | F20: L6X 0B8 | G20: L6X 0B8 | H20: 45069 | I20: COLON FREE ZONE | L20: =I23 -> PFC -0024
D21: CANADA | F21: CANADA | G21: CANADA | H21: UNITED STATES | I21: PANAMA | L21: =F29 -> TDC - 0020
L22: =G29 -> US EASTERN EAO-0004
D23: GAP (UK HOLDINGS) LIMITED | F23: HKG DC | G23: EDC(EU FRANCHISE HUB) | H23: EXPEDITORS INT'L GPS STRATEGIC ALLIANCES, LLC | I23: PFC -0024 | L23: =H29 -> NDC-0028
D24: 13TH FLOOR, ONE ANGEL COURT | F24: COMPARTMENT 1503, 15/F, | G24: SESE NETHERLANDS B.V | H24: AL TAYER HC-3 & H4 | I24: 2225 S 75TH AVE | L24: =I29 -> PDC-0014
D25: LONDON, UNITED KINGDOM | F25: KERRY CARGO CENTRE, | G25: KAAPSTADWEG 38A | H25: JEBEL ALI FZE | I25: PHOENIX, AZ | L25: =F35 -> JPD-0030
D26: EC2R 7HJ | F26: 55 WING KEI ROAD, KWAI CHUNG, NT | G26: THE NETHERLANDS | H26: DUBAI | I26: 85043
D27: UNITED KINGDOM | F27: HONG KONG | G27: NETHERLANDS | H27: UNITED ARAB EMIRATES | I27: UNITED STATES
D29: GAP EUROPE LIMITED | F29: TDC - 0020 | G29: US EASTERN EAO-0004 | H29: NDC-0028 | I29: PDC-0014
D30: 13TH FLOOR,ONE ANGEL COURT | F30: 200 GAP BLVD. | G30: 100 MERRITT BOULEVARD | H30: 100 MERRITT BOULEVARD | I30: 3400 NORTH GAP DR.
D31: LONDON | F31: GALLATIN, TN | G31: FISHKILL, NY | H31: FISHKILL, NY | I31: FRESNO, CA
D32: EC2R 7HJ | F32: 37066 | G32: 12524 | H32: 12524 | I32: 93727
D33: UNITED KINGDOM | F33: UNITED STATES | G33: UNITED STATES | H33: UNITED STATES | I33: UNITED STATES
D35: GPS STRATEGIC ALLIANCES, LLC | F35: JPD-0030
D36: 55 THOMAS ST | F36: 15-27 CHIDORI
D37: NEW YORK, NY | F37: URAYASU, TIBA [CHIBA]
D38: 10013 | F38: 279-0032
D39: UNITED STATES | F39: JAPAN
D41: THE GAP, INC.
D42: 2 FOLSOM STREET
D43: SAN FRANCISCO, CALIFORNIA
D44: 94105
D45: UNITED STATES
D47: GAP JAPAN K.K.
...

Sheet reff
B2: 1 | C2: 265K0051 | E2: 1 | F2: 416363 | H2: 1 | I2: ONLINE
B3: 2 | C3: 265K0058 | E3: 2 | F3: 905994 | H3: 2 | I3: ONLINE
B4: 3 | C4: 265K0059 | E4: 3 | F4: 906033 | H4: 3 | I4: ONLINE
B5: 4 | C5: 265K0058 | E5: 4 | F5: 905994 | H5: 4 | I5: ONLINE
B6: 5 | C6: 265K0059 | E6: 5 | F6: 906033 | H6: 5 | I6: RETAIL
B7: 6 | C7: 265K0059 | E7: 6 | F7: 906033 | H7: 6 | I7: ONLINE
B8: 7 | C8: 265K0075 | E8: 7 | F8: 692926 | H8: 7 | I8: ONLINE
B9: 8 | C9: 265K0075 | E9: 8 | F9: 692926 | H9: 8 | I9: RETAIL
B10: 9 | C10: 265K0075 | E10: 9 | F10: 692926 | H10: 9 | I10: RETAIL
B11: 10 | C11: 265K0075 | E11: 10 | F11: 692926 | H11: 10 | I11: ONLINE
B12: 11 | E12: 11 | H12: 11
B13: 12 | E13: 12 | H13: 12
B14: 13 | E14: 13 | H14: 13
B15: 14 | E15: 14 | H15: 14
B16: 15 | E16: 15 | H16: 15
B17: 16 | E17: 16 | H17: 16
B18: 17 | E18: 17 | H18: 17
B19: 18 | E19: 18 | H19: 18
B20: 19 | E20: 19 | H20: 19
B21: 20 | E21: 20 | H21: 20
B22: 21 | E22: 21 | H22: 21
B23: 22 | E23: 22 | H23: 22
... B29: 28 | E29: 28 | H29: 28

Sheet 114
K1: Item Qty | L1: Pkg Count | M1: Net Net | N1: Net | O1: Gross | P1: Unit | Q1: Vol
B2: COMERCIAL INVOICE CMT | J2: 61472727 | K2: 981 | L2: 18 | M2: 115.643 | N2: 117.605 | O2: 131.905 | P2: KG | Q2: 0.626 | R2: CBM
B3: INVOICE NO : | C3: 114 | G3: DATE | H3: 46215
K4: BOYS COTTON FIBERS, KNIT SHIRT, WITH NECK CLOSURE, STITCH COUNT EQUAL OR IS GREATER THAN 10/1CM, HEM BOTTOM [60% COTTON 40% POLYESTER]
B5: SHIP FROM | F5: SELLER | G5: KANMAX ENTERPRISES LTD
B6: PT NIRWANA ALABARE GARMENT | G6: 60 PAYA LEBAR ROAD
B7: JL RAYA RAANCAEKEK - MAJALAYA NO 289 | G7: #04-21 PAYA LEBAR SQUARE
B8: SOLOKAN JERUK - MAJALAYA | G8: 409051 SINGAPORE
B9: KABUPATEN BANDUNG
B10: JAWABARAT 40382 INDONESIA
B13: PURCHASER | F13: SHIP TO : | G13: CANADA OMNI CAO-0040
B14: OLD NAVY (CANADA) INC. | G14: =IF(G13=Sheet1!F5,Sheet1!F6,IF(G13=Sheet1!G5,Sheet1!G6,IF(G13=Sheet1!H5,Sheet1!H6,IF(G13=Sheet1!I5,Sheet1!I6,IF(G13=Sheet1!F11,Sheet1!F12,IF(G13=Sheet1!G11,Sheet1!G12,IF(G13=Sheet1!H11,Sheet1!H12,IF(G13=Sheet1!I11,Sheet1!I12,IF(G13=Sheet1!F17,Sheet1!F18,IF(G13=Sheet1!G17,Sheet1!G18,IF(G13=Sheet1!H17,Sheet1!H18,IF(G13=Sheet1!I17,Sheet1!I18,IF(G13=Sheet1!F23,Sheet1!F24,IF(G13=Sheet1!G23,Sheet1!G24,IF(G13=Sheet1!H23,Sheet1!H24,IF(G13=Sheet1!I23,Sheet1!I24,IF(G13=Sheet1!F29,Sheet1!F30,IF(G13=Sheet1!G29,Sheet1!G30,IF(G13=Sheet1!H29,Sheet1!H30,IF(G13=Sheet1!I29,Sheet1!I30,IF(G13=Sheet1!F35,Sheet1!F36))))))))))))))))))))) -> 9500 MCLAUGHLIN ROAD N
B15: =IF(B14=Sheet1!D5,Sheet1!D6,IF(B14=Sheet1!D11,Sheet1!D12,IF(B14=Sheet1!D17,Sheet1!D18,IF(B14=Sheet1!D23,Sheet1!D24,IF(B14=Sheet1!D29,Sheet1!D30,IF(B14=Sheet1!D35,Sheet1!D36,IF(B14=Sheet1!D41,Sheet1!D42,IF(B14=Sheet1!D47,Sheet1!D48)))))))) -> 9500 MCLAUGHLIN ROAD N | G15: =IF(G14=Sheet1!F6,Sheet1!F7,IF(G14=Sheet1!G6,Sheet1!G7,IF(G14=Sheet1!H6,Sheet1!H7,IF(G14=Sheet1!I6,Sheet1!I7,IF(G14=Sheet1!F12,Sheet1!F13,IF(G14=Sheet1!G12,Sheet1!G13,IF(G14=Sheet1!H12,Sheet1!H13,IF(G14=Sheet1!I12,Sheet1!I13,IF(G14=Sheet1!F18,Sheet1!F19,IF(G14=Sheet1!G18,Sheet1!G19,IF(G14=Sheet1!H18,Sheet1!H19,IF(G14=Sheet1!I18,Sheet1!I19,IF(G14=Sheet1!F24,Sheet1!F25,IF(G14=Sheet1!G24,Sheet1!G25,IF(G14=Sheet1!H24,Sheet1!H25,IF(G14=Sheet1!I24,Sheet1!I25,IF(G14=Sheet1!F30,Sheet1!F31,IF(G14=Sheet1!G30,Sheet1!G31,IF(G14=Sheet1!H30,Sheet1!H31,IF(G14=Sheet1!I30,Sheet1!I31,IF(G14=Sheet1!F36,Sheet1!F37))))))))))))))))))))) -> BRAMPTON, ONTARIO
B16: =IF(B15=Sheet1!D6,Sheet1!D7,IF(B15=Sheet1!D12,Sheet1!D13,IF(B15=Sheet1!D18,Sheet1!D19,IF(B15=Sheet1!D24,Sheet1!D25,IF(B15=Sheet1!D30,Sheet1!D31,IF(B15=Sheet1!D36,Sheet1!D37,IF(B15=Sheet1!D42,Sheet1!D43,IF(B15=Sheet1!D48,Sheet1!D49)))))))) -> BRAMPTON, ONTARIO | G16: =IF(G15=Sheet1!F7,Sheet1!F8,IF(G15=Sheet1!G7,Sheet1!G8,IF(G15=Sheet1!H7,Sheet1!H8,IF(G15=Sheet1!I7,Sheet1!I8,IF(G15=Sheet1!F13,Sheet1!F14,IF(G15=Sheet1!G13,Sheet1!G14,IF(G15=Sheet1!H13,Sheet1!H14,IF(G15=Sheet1!I13,Sheet1!I14,IF(G15=Sheet1!F19,Sheet1!F20,IF(G15=Sheet1!G19,Sheet1!G20,IF(G15=Sheet1!H19,Sheet1!H20,IF(G15=Sheet1!I19,Sheet1!I20,IF(G15=Sheet1!F25,Sheet1!F26,IF(G15=Sheet1!G25,Sheet1!G26,IF(G15=Sheet1!H25,Sheet1!H26,IF(G15=Sheet1!I25,Sheet1!I26,IF(G15=Sheet1!F31,Sheet1!F32,IF(G15=Sheet1!G31,Sheet1!G32,IF(G15=Sheet1!H31,Sheet1!H32,IF(G15=Sheet1!I31,Sheet1!I32,IF(G15=Sheet1!F37,Sheet1!F38))))))))))))))))))))) -> L6X 0B8
B17: =IF(B16=Sheet1!D7,Sheet1!D8,IF(B16=Sheet1!D13,Sheet1!D14,IF(B16=Sheet1!D19,Sheet1!D20,IF(B16=Sheet1!D25,Sheet1!D26,IF(B16=Sheet1!D31,Sheet1!D32,IF(B16=Sheet1!D37,Sheet1!D38,IF(B16=Sheet1!D43,Sheet1!D44,IF(B16=Sheet1!D49,Sheet1!D50)))))))) -> L6X 0B8 | G17: =IF(G16=Sheet1!F8,Sheet1!F9,IF(G16=Sheet1!G8,Sheet1!G9,IF(G16=Sheet1!H8,Sheet1!H9,IF(G16=Sheet1!I8,Sheet1!I9,IF(G16=Sheet1!F14,Sheet1!F15,IF(G16=Sheet1!G14,Sheet1!G15,IF(G16=Sheet1!H14,Sheet1!H15,IF(G16=Sheet1!I14,Sheet1!I15,IF(G16=Sheet1!F20,Sheet1!F21,IF(G16=Sheet1!G20,Sheet1!G21,IF(G16=Sheet1!H20,Sheet1!H21,IF(G16=Sheet1!I20,Sheet1!I21,IF(G16=Sheet1!F26,Sheet1!F27,IF(G16=Sheet1!G26,Sheet1!G27,IF(G16=Sheet1!H26,Sheet1!H27,IF(G16=Sheet1!I26,Sheet1!I27,IF(G16=Sheet1!F32,Sheet1!F33,IF(G16=Sheet1!G32,Sheet1!G33,IF(G16=Sheet1!H32,Sheet1!H33,IF(G16=Sheet1!I32,Sheet1!I33,IF(G16=Sheet1!F38,Sheet1!F39))))))))))))))))))))) -> CANADA
B18: =IF(B17=Sheet1!D8,Sheet1!D9,IF(B17=Sheet1!D14,Sheet1!D15,IF(B17=Sheet1!D20,Sheet1!D21,IF(B17=Sheet1!D26,Sheet1!D27,IF(B17=Sheet1!D32,Sheet1!D33,IF(B17=Sheet1!D38,Sheet1!D39,IF(B17=Sheet1!D44,Sheet1!D45,IF(B17=Sheet1!D50,Sheet1!D51)))))))) -> CANADA
B20: Dest Purchase | C20: Style NO | D20: Brand | E20: Chanel Description | F20: Currency | G20: Payment Term | H20: Final Destination | I20: Country of origin
B21: =J2 -> 61472727 | C21: =VLOOKUP($K56,reff!E2:F29,2,0) -> 416363 | D21: =IF(LEFT(B14,2)="OL","OLD NAVY",IF(LEFT(B14,2)="TH","THE GAP",IF(LEFT(B14,2)="GA","GAP",IF(LEFT(B14,2)="GP","OLD NAVY")))) -> OLD NAVY | E21: =VLOOKUP($K21,reff!H2:I29,2,0) -> ONLINE | F21: USD | H21: =IF(LEFT(G17,2)="CA","CA",IF(LEFT(G17,2)="UN","US",IF(LEFT(G17,2)="PA","PA",IF(LEFT(G17,2)="JA","JP")))) -> CA | I21: ID | K21: 1
B22: Ship Mode | C22: Term of Sale | D22: Transfer Point | E22: Port Of Loading | F22: Total Gross Weight(KGS) | G22: Total Net Weight(KGS) | H22: Total Net Net Weight(KGS) | I22: Total Carton
B23: OCEAN | D23: JAKARTA,ID | E23: =+D23 -> JAKARTA,ID | F23: =+O2 -> 131.905 | G23: =+N2 -> 117.605 | H23: =+M2 -> 115.643 | I23: =+L2 -> 18
B26: Product Description
B27: =+K4 -> BOYS COTTON FIBERS, KNIT SHIRT, WITH NECK CLOSURE, STITCH COUNT EQUAL OR IS GREATER THAN 10/1CM, HEM BOTTOM [60% COTTON 40% POLYESTER]
B29: Invoice Summary
B31: Color Code | C31: Color Name | D31: Total Pieces (Custom Units) | F31: Quantity Invoiced (Each) | H31: Unit Cost | I31: Extended Line Total
B32: 09, 10 | C32: DARK FOREST GREEN, RON BURGUNDY | F32: =+K2 -> 981 | H32: 0.9 | I32: =+H32*F32 -> 882.9
B33: Total Dozens
B34: Sub Total | F34: =SUM(F32:G32) -> 981 | I34: =SUM(I32:I32) -> 882.9
B35: Hard Tag Cost
B36: Gross Invoice Sub total | I36: =+I34 -> 882.9
B37: Discount | C37: Less early Payment discount of 5% per term and conditions of the purchase order(s)
B38: Net Invoice Total | I38: =+I36+I37 -> 882.9
B41: Invoice Notes :
B42: (NO FS)
B44: Manufacturer Information
B46: PT NIRWANA ALABARE GARMENT | E46: JL RAYA RANCAEKEK-MAJALAYA NO 289 , SOLOKAN JERUK- MAJALAYA
E47: KABUPATEN BANDUNG 40382 JABAR , INDONESIA
B49: I hereby certify that all information provided is true and correct
B50: Prepare's Name
G52: REFF | H52: =VLOOKUP($K52,reff!B2:C29,2,0) -> 265K0051 | K52: 1
C55: Yus Yulius
...

Sheet 115
K1: Item Qty | L1: Pkg Count | M1: Net Net | N1: Net | O1: Gross | P1: Unit | Q1: Vol
B2: COMERCIAL INVOICE CMT | J2: 61646959 | K2: 1306 | L2: 16 | M2: 95.998 | N2: 98.61 | O2: 111.31 | P2: KG | Q2: 0.548 | R2: CBM
B3: INVOICE NO : | C3: =+'114'!C3+1 -> 115 | G3: DATE | H3: 46215
K4: GIRLS COTTON FIBERS, KNIT PULLOVER, WITH NO NECK CLOSURE, STITCH COUNT IS GREATER THAN 9/2CM, REACHES WAIST [100% COTTON]
B5: SHIP FROM | F5: SELLER | G5: KANMAX ENTERPRISES LTD
B6: PT NIRWANA ALABARE GARMENT | G6: 60 PAYA LEBAR ROAD
B7: JL RAYA RAANCAEKEK - MAJALAYA NO 289 | G7: #04-21 PAYA LEBAR SQUARE
B8: SOLOKAN JERUK - MAJALAYA | G8: 409051 SINGAPORE
B9: KABUPATEN BANDUNG
B10: JAWABARAT 40382 INDONESIA
B13: PURCHASER | F13: SHIP TO : | G13: OHO OHIO OMNI-0016
B14: OLD NAVY, LLC | G14: =IF(G13=Sheet1!F5,Sheet1!F6,IF(G13=Sheet1!G5,Sheet1!G6,IF(G13=Sheet1!H5,Sheet1!H6,IF(G13=Sheet1!I5,Sheet1!I6,IF(G13=Sheet1!F11,Sheet1!F12,IF(G13=Sheet1!G11,Sheet1!G12,IF(G13=Sheet1!H11,Sheet1!H12,IF(G13=Sheet1!I11,Sheet1!I12,IF(G13=Sheet1!F17,Sheet1!F18,IF(G13=Sheet1!G17,Sheet1!G18,IF(G13=Sheet1!H17,Sheet1!H18,IF(G13=Sheet1!I17,Sheet1!I18,IF(G13=Sheet1!F23,Sheet1!F24,IF(G13=Sheet1!G23,Sheet1!G24,IF(G13=Sheet1!H23,Sheet1!H24,IF(G13=Sheet1!I23,Sheet1!I24,IF(G13=Sheet1!F29,Sheet1!F30,IF(G13=Sheet1!G29,Sheet1!G30,IF(G13=Sheet1!H29,Sheet1!H30,IF(G13=Sheet1!I29,Sheet1!I30,IF(G13=Sheet1!F35,Sheet1!F36))))))))))))))))))))) -> 6001 GREEN POINTE DR S
B15: =IF(B14=Sheet1!D5,Sheet1!D6,IF(B14=Sheet1!D11,Sheet1!D12,IF(B14=Sheet1!D17,Sheet1!D18,IF(B14=Sheet1!D23,Sheet1!D24,IF(B14=Sheet1!D29,Sheet1!D30,IF(B14=Sheet1!D35,Sheet1!D36,IF(B14=Sheet1!D41,Sheet1!D42,IF(B14=Sheet1!D47,Sheet1!D48)))))))) -> 2 FOLSOM STREET | G15: =IF(G14=Sheet1!F6,Sheet1!F7,IF(G14=Sheet1!G6,Sheet1!G7,IF(G14=Sheet1!H6,Sheet1!H7,IF(G14=Sheet1!I6,Sheet1!I7,IF(G14=Sheet1!F12,Sheet1!F13,IF(G14=Sheet1!G12,Sheet1!G13,IF(G14=Sheet1!H12,Sheet1!H13,IF(G14=Sheet1!I12,Sheet1!I13,IF(G14=Sheet1!F18,Sheet1!F19,IF(G14=Sheet1!G18,Sheet1!G19,IF(G14=Sheet1!H18,Sheet1!H19,IF(G14=Sheet1!I18,Sheet1!I19,IF(G14=Sheet1!F24,Sheet1!F25,IF(G14=Sheet1!G24,Sheet1!G25,IF(G14=Sheet1!H24,Sheet1!H25,IF(G14=Sheet1!I24,Sheet1!I25,IF(G14=Sheet1!F30,Sheet1!F31,IF(G14=Sheet1!G30,Sheet1!G31,IF(G14=Sheet1!H30,Sheet1!H31,IF(G14=Sheet1!I30,Sheet1!I31,IF(G14=Sheet1!F36,Sheet1!F37))))))))))))))))))))) -> GROVEPORT, OH
B16: =IF(B15=Sheet1!D6,Sheet1!D7,IF(B15=Sheet1!D12,Sheet1!D13,IF(B15=Sheet1!D18,Sheet1!D19,IF(B15=Sheet1!D24,Sheet1!D25,IF(B15=Sheet1!D30,Sheet1!D31,IF(B15=Sheet1!D36,Sheet1!D37,IF(B15=Sheet1!D42,Sheet1!D43,IF(B15=Sheet1!D48,Sheet1!D49)))))))) -> SAN FRANCISCO, CALIFORNIA | G16: =IF(G15=Sheet1!F7,Sheet1!F8,IF(G15=Sheet1!G7,Sheet1!G8,IF(G15=Sheet1!H7,Sheet1!H8,IF(G15=Sheet1!I7,Sheet1!I8,IF(G15=Sheet1!F13,Sheet1!F14,IF(G15=Sheet1!G13,Sheet1!G14,IF(G15=Sheet1!H13,Sheet1!H14,IF(G15=Sheet1!I13,Sheet1!I14,IF(G15=Sheet1!F19,Sheet1!F20,IF(G15=Sheet1!G19,Sheet1!G20,IF(G15=Sheet1!H19,Sheet1!H20,IF(G15=Sheet1!I19,Sheet1!I20,IF(G15=Sheet1!F25,Sheet1!F26,IF(G15=Sheet1!G25,Sheet1!G26,IF(G15=Sheet1!H25,Sheet1!H26,IF(G15=Sheet1!I25,Sheet1!I26,IF(G15=Sheet1!F31,Sheet1!F32,IF(G15=Sheet1!G31,Sheet1!G32,IF(G15=Sheet1!H31,Sheet1!H32,IF(G15=Sheet1!I31,Sheet1!I32,IF(G15=Sheet1!F37,Sheet1!F38))))))))))))))))))))) -> 43125
B17: =IF(B16=Sheet1!D7,Sheet1!D8,IF(B16=Sheet1!D13,Sheet1!D14,IF(B16=Sheet1!D19,Sheet1!D20,IF(B16=Sheet1!D25,Sheet1!D26,IF(B16=Sheet1!D31,Sheet1!D32,IF(B16=Sheet1!D37,Sheet1!D38,IF(B16=Sheet1!D43,Sheet1!D44,IF(B16=Sheet1!D49,Sheet1!D50)))))))) -> 94105 | G17: =IF(G16=Sheet1!F8,Sheet1!F9,IF(G16=Sheet1!G8,Sheet1!G9,IF(G16=Sheet1!H8,Sheet1!H9,IF(G16=Sheet1!I8,Sheet1!I9,IF(G16=Sheet1!F14,Sheet1!F15,IF(G16=Sheet1!G14,Sheet1!G15,IF(G16=Sheet1!H14,Sheet1!H15,IF(G16=Sheet1!I14,Sheet1!I15,IF(G16=Sheet1!F20,Sheet1!F21,IF(G16=Sheet1!G20,Sheet1!G21,IF(G16=Sheet1!H20,Sheet1!H21,IF(G16=Sheet1!I20,Sheet1!I21,IF(G16=Sheet1!F26,Sheet1!F27,IF(G16=Sheet1!G26,Sheet1!G27,IF(G16=Sheet1!H26,Sheet1!H27,IF(G16=Sheet1!I26,Sheet1!I27,IF(G16=Sheet1!F32,Sheet1!F33,IF(G16=Sheet1!G32,Sheet1!G33,IF(G16=Sheet1!H32,Sheet1!H33,IF(G16=Sheet1!I32,Sheet1!I33,IF(G16=Sheet1!F38,Sheet1!F39))))))))))))))))))))) -> UNITED STATES
B18: =IF(B17=Sheet1!D8,Sheet1!D9,IF(B17=Sheet1!D14,Sheet1!D15,IF(B17=Sheet1!D20,Sheet1!D21,IF(B17=Sheet1!D26,Sheet1!D27,IF(B17=Sheet1!D32,Sheet1!D33,IF(B17=Sheet1!D38,Sheet1!D39,IF(B17=Sheet1!D44,Sheet1!D45,IF(B17=Sheet1!D50,Sheet1!D51)))))))) -> UNITED STATES
B20: Dest Purchase | C20: Style NO | D20: Brand | E20: Chanel Description | F20: Currency | G20: Payment Term | H20: Final Destination | I20: Country of origin
B21: =J2 -> 61646959 | C21: =VLOOKUP($K56,reff!E2:F29,2,0) -> 905994 | D21: =IF(LEFT(B14,2)="OL","OLD NAVY",IF(LEFT(B14,2)="TH","THE GAP",IF(LEFT(B14,2)="GA","GAP",IF(LEFT(B14,2)="GP","OLD NAVY")))) -> OLD NAVY | E21: =VLOOKUP($K21,reff!H2:I29,2,0) -> ONLINE | F21: USD | H21: =IF(LEFT(G17,2)="CA","CA",IF(LEFT(G17,2)="UN","US",IF(LEFT(G17,2)="PA","PA",IF(LEFT(G17,2)="JA","JP")))) -> US | I21: ID | K21: 2
B22: Ship Mode | C22: Term of Sale | D22: Transfer Point | E22: Port Of Loading | F22: Total Gross Weight(KGS) | G22: Total Net Weight(KGS) | H22: Total Net Net Weight(KGS) | I22: Total Carton
B23: OCEAN | D23: JAKARTA,ID | E23: =+D23 -> JAKARTA,ID | F23: =+O2 -> 111.31 | G23: =+N2 -> 98.61 | H23: =+M2 -> 95.998 | I23: =+L2 -> 16
B26: Product Description
B27: =+K4 -> GIRLS COTTON FIBERS, KNIT PULLOVER, WITH NO NECK CLOSURE, STITCH COUNT IS GREATER THAN 9/2CM, REACHES WAIST [100% COTTON]
B29: Invoice Summary
B31: Color Code | C31: Color Name | D31: Total Pieces (Custom Units) | F31: Quantity Invoiced (Each) | H31: Unit Cost | I31: Extended Line Total
B32: 00, 01 | C32: BLACK LEOPARD, PINK LEOPARD HEART | F32: =+K2 -> 1306 | H32: 0.81 | I32: =+H32*F32 -> 1057.86
B33: Total Dozens
B34: Sub Total | F34: =SUM(F31:G33) -> 1306 | I34: =SUM(I32:I33) -> 1057.86
B35: Hard Tag Cost
B36: Gross Invoice Sub total | I36: =+I34 -> 1057.86
B37: Discount | C37: Less early Payment discount of 5% per term and conditions of the purchase order(s)
B38: Net Invoice Total | I38: =+I36+I37 -> 1057.86
B41: Invoice Notes :
B42: (NO FS)
B44: Manufacturer Information
B46: PT NIRWANA ALABARE GARMENT | E46: JL RAYA RANCAEKEK-MAJALAYA NO 289 , SOLOKAN JERUK- MAJALAYA
E47: KABUPATEN BANDUNG 40382 JABAR , INDONESIA
B49: I hereby certify that all information provided is true and correct
B50: Prepare's Name
G52: REFF | H52: =VLOOKUP($K52,reff!B2:C29,2,0) -> 265K0058 | K52: 2
C55: Yus Yulius
...

Sheet 116
K1: Item Qty | L1: Pkg Count | M1: Net Net | N1: Net | O1: Gross | P1: Unit | Q1: Vol
B2: COMERCIAL INVOICE CMT | J2: 61646964 | K2: 2969 | L2: 31 | M2: 248.607 | N2: 254.545 | O2: 282.445 | P2: KG | Q2: 1.588 | R2: CBM
B3: INVOICE NO : | C3: =+'115'!C3+1 -> 116 | G3: DATE | H3: 46215
K4: GIRLS COTTON FIBERS, KNIT PULLOVER, WITH NO NECK CLOSURE, STITCH COUNT IS GREATER THAN 9/2CM, REACHES WAIST [100% COTTON]
B5: SHIP FROM | F5: SELLER | G5: KANMAX ENTERPRISES LTD
B6: PT NIRWANA ALABARE GARMENT | G6: 60 PAYA LEBAR ROAD
B7: JL RAYA RAANCAEKEK - MAJALAYA NO 289 | G7: #04-21 PAYA LEBAR SQUARE
B8: SOLOKAN JERUK - MAJALAYA | G8: 409051 SINGAPORE
B9: KABUPATEN BANDUNG
B10: JAWABARAT 40382 INDONESIA
B13: PURCHASER | F13: SHIP TO : | G13: OHO OHIO OMNI-0016
B14: OLD NAVY, LLC | G14: =IF(G13=Sheet1!F5,Sheet1!F6,IF(G13=Sheet1!G5,Sheet1!G6,IF(G13=Sheet1!H5,Sheet1!H6,IF(G13=Sheet1!I5,Sheet1!I6,IF(G13=Sheet1!F11,Sheet1!F12,IF(G13=Sheet1!G11,Sheet1!G12,IF(G13=Sheet1!H11,Sheet1!H12,IF(G13=Sheet1!I11,Sheet1!I12,IF(G13=Sheet1!F17,Sheet1!F18,IF(G13=Sheet1!G17,Sheet1!G18,IF(G13=Sheet1!H17,Sheet1!H18,IF(G13=Sheet1!I17,Sheet1!I18,IF(G13=Sheet1!F23,Sheet1!F24,IF(G13=Sheet1!G23,Sheet1!G24,IF(G13=Sheet1!H23,Sheet1!H24,IF(G13=Sheet1!I23,Sheet1!I24,IF(G13=Sheet1!F29,Sheet1!F30,IF(G13=Sheet1!G29,Sheet1!G30,IF(G13=Sheet1!H29,Sheet1!H30,IF(G13=Sheet1!I29,Sheet1!I30,IF(G13=Sheet1!F35,Sheet1!F36))))))))))))))))))))) -> 6001 GREEN POINTE DR S
B15: =IF(B14=Sheet1!D5,Sheet1!D6,IF(B14=Sheet1!D11,Sheet1!D12,IF(B14=Sheet1!D17,Sheet1!D18,IF(B14=Sheet1!D23,Sheet1!D24,IF(B14=Sheet1!D29,Sheet1!D30,IF(B14=Sheet1!D35,Sheet1!D36,IF(B14=Sheet1!D41,Sheet1!D42,IF(B14=Sheet1!D47,Sheet1!D48)))))))) -> 2 FOLSOM STREET | G15: =IF(G14=Sheet1!F6,Sheet1!F7,IF(G14=Sheet1!G6,Sheet1!G7,IF(G14=Sheet1!H6,Sheet1!H7,IF(G14=Sheet1!I6,Sheet1!I7,IF(G14=Sheet1!F12,Sheet1!F13,IF(G14=Sheet1!G12,Sheet1!G13,IF(G14=Sheet1!H12,Sheet1!H13,IF(G14=Sheet1!I12,Sheet1!I13,IF(G14=Sheet1!F18,Sheet1!F19,IF(G14=Sheet1!G18,Sheet1!G19,IF(G14=Sheet1!H18,Sheet1!H19,IF(G14=Sheet1!I18,Sheet1!I19,IF(G14=Sheet1!F24,Sheet1!F25,IF(G14=Sheet1!G24,Sheet1!G25,IF(G14=Sheet1!H24,Sheet1!H25,IF(G14=Sheet1!I24,Sheet1!I25,IF(G14=Sheet1!F30,Sheet1!F31,IF(G14=Sheet1!G30,Sheet1!G31,IF(G14=Sheet1!H30,Sheet1!H31,IF(G14=Sheet1!I30,Sheet1!I31,IF(G14=Sheet1!F36,Sheet1!F37))))))))))))))))))))) -> GROVEPORT, OH
B16: =IF(B15=Sheet1!D6,Sheet1!D7,IF(B15=Sheet1!D12,Sheet1!D13,IF(B15=Sheet1!D18,Sheet1!D19,IF(B15=Sheet1!D24,Sheet1!D25,IF(B15=Sheet1!D30,Sheet1!D31,IF(B15=Sheet1!D36,Sheet1!D37,IF(B15=Sheet1!D42,Sheet1!D43,IF(B15=Sheet1!D48,Sheet1!D49)))))))) -> SAN FRANCISCO, CALIFORNIA | G16: =IF(G15=Sheet1!F7,Sheet1!F8,IF(G15=Sheet1!G7,Sheet1!G8,IF(G15=Sheet1!H7,Sheet1!H8,IF(G15=Sheet1!I7,Sheet1!I8,IF(G15=Sheet1!F13,Sheet1!F14,IF(G15=Sheet1!G13,Sheet1!G14,IF(G15=Sheet1!H13,Sheet1!H14,IF(G15=Sheet1!I13,Sheet1!I14,IF(G15=Sheet1!F19,Sheet1!F20,IF(G15=Sheet1!G19,Sheet1!G20,IF(G15=Sheet1!H19,Sheet1!H20,IF(G15=Sheet1!I19,Sheet1!I20,IF(G15=Sheet1!F25,Sheet1!F26,IF(G15=Sheet1!G25,Sheet1!G26,IF(G15=Sheet1!H25,Sheet1!H26,IF(G15=Sheet1!I25,Sheet1!I26,IF(G15=Sheet1!F31,Sheet1!F32,IF(G15=Sheet1!G31,Sheet1!G32,IF(G15=Sheet1!H31,Sheet1!H32,IF(G15=Sheet1!I31,Sheet1!I32,IF(G15=Sheet1!F37,Sheet1!F38))))))))))))))))))))) -> 43125
B17: =IF(B16=Sheet1!D7,Sheet1!D8,IF(B16=Sheet1!D13,Sheet1!D14,IF(B16=Sheet1!D19,Sheet1!D20,IF(B16=Sheet1!D25,Sheet1!D26,IF(B16=Sheet1!D31,Sheet1!D32,IF(B16=Sheet1!D37,Sheet1!D38,IF(B16=Sheet1!D43,Sheet1!D44,IF(B16=Sheet1!D49,Sheet1!D50)))))))) -> 94105 | G17: =IF(G16=Sheet1!F8,Sheet1!F9,IF(G16=Sheet1!G8,Sheet1!G9,IF(G16=Sheet1!H8,Sheet1!H9,IF(G16=Sheet1!I8,Sheet1!I9,IF(G16=Sheet1!F14,Sheet1!F15,IF(G16=Sheet1!G14,Sheet1!G15,IF(G16=Sheet1!H14,Sheet1!H15,IF(G16=Sheet1!I14,Sheet1!I15,IF(G16=Sheet1!F20,Sheet1!F21,IF(G16=Sheet1!G20,Sheet1!G21,IF(G16=Sheet1!H20,Sheet1!H21,IF(G16=Sheet1!I20,Sheet1!I21,IF(G16=Sheet1!F26,Sheet1!F27,IF(G16=Sheet1!G26,Sheet1!G27,IF(G16=Sheet1!H26,Sheet1!H27,IF(G16=Sheet1!I26,Sheet1!I27,IF(G16=Sheet1!F32,Sheet1!F33,IF(G16=Sheet1!G32,Sheet1!G33,IF(G16=Sheet1!H32,Sheet1!H33,IF(G16=Sheet1!I32,Sheet1!I33,IF(G16=Sheet1!F38,Sheet1!F39))))))))))))))))))))) -> UNITED STATES
B18: =IF(B17=Sheet1!D8,Sheet1!D9,IF(B17=Sheet1!D14,Sheet1!D15,IF(B17=Sheet1!D20,Sheet1!D21,IF(B17=Sheet1!D26,Sheet1!D27,IF(B17=Sheet1!D32,Sheet1!D33,IF(B17=Sheet1!D38,Sheet1!D39,IF(B17=Sheet1!D44,Sheet1!D45,IF(B17=Sheet1!D50,Sheet1!D51)))))))) -> UNITED STATES
B20: Dest Purchase | C20: Style NO | D20: Brand | E20: Chanel Description | F20: Currency | G20: Payment Term | H20: Final Destination | I20: Country of origin
B21: =J2 -> 61646964 | C21: =VLOOKUP($K56,reff!E2:F29,2,0) -> 906033 | D21: =IF(LEFT(B14,2)="OL","OLD NAVY",IF(LEFT(B14,2)="TH","THE GAP",IF(LEFT(B14,2)="GA","GAP",IF(LEFT(B14,2)="GP","OLD NAVY")))) -> OLD NAVY | E21: =VLOOKUP($K21,reff!H2:I29,2,0) -> ONLINE | F21: USD | H21: =IF(LEFT(G17,2)="CA","CA",IF(LEFT(G17,2)="UN","US",IF(LEFT(G17,2)="PA","PA",IF(LEFT(G17,2)="JA","JP")))) -> US | I21: ID | K21: 3
B22: Ship Mode | C22: Term of Sale | D22: Transfer Point | E22: Port Of Loading | F22: Total Gross Weight(KGS) | G22: Total Net Weight(KGS) | H22: Total Net Net Weight(KGS) | I22: Total Carton
B23: OCEAN | D23: JAKARTA,ID | E23: =+D23 -> JAKARTA,ID | F23: =+O2 -> 282.445 | G23: =+N2 -> 254.545 | H23: =+M2 -> 248.607 | I23: =+L2 -> 31
B26: Product Description
B27: =+K4 -> GIRLS COTTON FIBERS, KNIT PULLOVER, WITH NO NECK CLOSURE, STITCH COUNT IS GREATER THAN 9/2CM, REACHES WAIST [100% COTTON]
B29: Invoice Summary
B31: Color Code | C31: Color Name | D31: Total Pieces (Custom Units) | F31: Quantity Invoiced (Each) | H31: Unit Cost | I31: Extended Line Total
B32: 00, 01 | C32: BLACK LEOPARD, PINK LEOPARD HEART | F32: =+K2 -> 2969 | H32: 0.84 | I32: =+H32*F32 -> 2493.96
B33: Total Dozens
B34: Sub Total | F34: =SUM(F31:G33) -> 2969 | I34: =SUM(I32:I33) -> 2493.96
B35: Hard Tag Cost
B36: Gross Invoice Sub total | I36: =+I34 -> 2493.96
B37: Discount | C37: Less early Payment discount of 5% per term and conditions of the purchase order(s)
B38: Net Invoice Total | I38: =+I36+I37 -> 2493.96
B41: Invoice Notes :
B42: (NO FS)
B44: Manufacturer Information
B46: PT NIRWANA ALABARE GARMENT | E46: JL RAYA RANCAEKEK-MAJALAYA NO 289 , SOLOKAN JERUK- MAJALAYA
E47: KABUPATEN BANDUNG 40382 JABAR , INDONESIA
B49: I hereby certify that all information provided is true and correct
B50: Prepare's Name
G52: REFF | H52: =VLOOKUP($K52,reff!B2:C29,2,0) -> 265K0059 | K52: 3
C55: Yus Yulius
...

Sheet 117
K1: Item Qty | L1: Pkg Count | M1: Net Net | N1: Net | O1: Gross | P1: Unit | Q1: Vol
B2: COMERCIAL INVOICE CMT | J2: 61646969 | K2: 648 | L2: 7 | M2: 47.559 | N2: 48.855 | O2: 54.555 | P2: KG | Q2: 0.268 | R2: CBM
B3: INVOICE NO : | C3: =+'116'!C3+1 -> 117 | G3: DATE | H3: 46215
K4: GIRLS COTTON FIBERS, KNIT PULLOVER, WITH NO NECK CLOSURE, STITCH COUNT IS GREATER THAN 9/2CM, REACHES WAIST [100% COTTON]
B5: SHIP FROM | F5: SELLER | G5: KANMAX ENTERPRISES LTD
B6: PT NIRWANA ALABARE GARMENT | G6: 60 PAYA LEBAR ROAD
B7: JL RAYA RAANCAEKEK - MAJALAYA NO 289 | G7: #04-21 PAYA LEBAR SQUARE
B8: SOLOKAN JERUK - MAJALAYA | G8: 409051 SINGAPORE
B9: KABUPATEN BANDUNG
B10: JAWABARAT 40382 INDONESIA
B13: PURCHASER | F13: SHIP TO : | G13: FISHKILL NY ONLINE-0007
B14: OLD NAVY, LLC | G14: =IF(G13=Sheet1!F5,Sheet1!F6,IF(G13=Sheet1!G5,Sheet1!G6,IF(G13=Sheet1!H5,Sheet1!H6,IF(G13=Sheet1!I5,Sheet1!I6,IF(G13=Sheet1!F11,Sheet1!F12,IF(G13=Sheet1!G11,Sheet1!G12,IF(G13=Sheet1!H11,Sheet1!H12,IF(G13=Sheet1!I11,Sheet1!I12,IF(G13=Sheet1!F17,Sheet1!F18,IF(G13=Sheet1!G17,Sheet1!G18,IF(G13=Sheet1!H17,Sheet1!H18,IF(G13=Sheet1!I17,Sheet1!I18,IF(G13=Sheet1!F23,Sheet1!F24,IF(G13=Sheet1!G23,Sheet1!G24,IF(G13=Sheet1!H23,Sheet1!H24,IF(G13=Sheet1!I23,Sheet1!I24,IF(G13=Sheet1!F29,Sheet1!F30,IF(G13=Sheet1!G29,Sheet1!G30,IF(G13=Sheet1!H29,Sheet1!H30,IF(G13=Sheet1!I29,Sheet1!I30,IF(G13=Sheet1!F35,Sheet1!F36))))))))))))))))))))) -> 110 MERRITT BLVD
B15: =IF(B14=Sheet1!D5,Sheet1!D6,IF(B14=Sheet1!D11,Sheet1!D12,IF(B14=Sheet1!D17,Sheet1!D18,IF(B14=Sheet1!D23,Sheet1!D24,IF(B14=Sheet1!D29,Sheet1!D30,IF(B14=Sheet1!D35,Sheet1!D36,IF(B14=Sheet1!D41,Sheet1!D42,IF(B14=Sheet1!D47,Sheet1!D48)))))))) -> 2 FOLSOM STREET | G15: =IF(G14=Sheet1!F6,Sheet1!F7,IF(G14=Sheet1!G6,Sheet1!G7,IF(G14=Sheet1!H6,Sheet1!H7,IF(G14=Sheet1!I6,Sheet1!I7,IF(G14=Sheet1!F12,Sheet1!F13,IF(G14=Sheet1!G12,Sheet1!G13,IF(G14=Sheet1!H12,Sheet1!H13,IF(G14=Sheet1!I12,Sheet1!I13,IF(G14=Sheet1!F18,Sheet1!F19,IF(G14=Sheet1!G18,Sheet1!G19,IF(G14=Sheet1!H18,Sheet1!H19,IF(G14=Sheet1!I18,Sheet1!I19,IF(G14=Sheet1!F24,Sheet1!F25,IF(G14=Sheet1!G24,Sheet1!G25,IF(G14=Sheet1!H24,Sheet1!H25,IF(G14=Sheet1!I24,Sheet1!I25,IF(G14=Sheet1!F30,Sheet1!F31,IF(G14=Sheet1!G30,Sheet1!G31,IF(G14=Sheet1!H30,Sheet1!H31,IF(G14=Sheet1!I30,Sheet1!I31,IF(G14=Sheet1!F36,Sheet1!F37))))))))))))))))))))) -> FISHKILL, NY
B16: =IF(B15=Sheet1!D6,Sheet1!D7,IF(B15=Sheet1!D12,Sheet1!D13,IF(B15=Sheet1!D18,Sheet1!D19,IF(B15=Sheet1!D24,Sheet1!D25,IF(B15=Sheet1!D30,Sheet1!D31,IF(B15=Sheet1!D36,Sheet1!D37,IF(B15=Sheet1!D42,Sheet1!D43,IF(B15=Sheet1!D48,Sheet1!D49)))))))) -> SAN FRANCISCO, CALIFORNIA | G16: =IF(G15=Sheet1!F7,Sheet1!F8,IF(G15=Sheet1!G7,Sheet1!G8,IF(G15=Sheet1!H7,Sheet1!H8,IF(G15=Sheet1!I7,Sheet1!I8,IF(G15=Sheet1!F13,Sheet1!F14,IF(G15=Sheet1!G13,Sheet1!G14,IF(G15=Sheet1!H13,Sheet1!H14,IF(G15=Sheet1!I13,Sheet1!I14,IF(G15=Sheet1!F19,Sheet1!F20,IF(G15=Sheet1!G19,Sheet1!G20,IF(G15=Sheet1!H19,Sheet1!H20,IF(G15=Sheet1!I19,Sheet1!I20,IF(G15=Sheet1!F25,Sheet1!F26,IF(G15=Sheet1!G25,Sheet1!G26,IF(G15=Sheet1!H25,Sheet1!H26,IF(G15=Sheet1!I25,Sheet1!I26,IF(G15=Sheet1!F31,Sheet1!F32,IF(G15=Sheet1!G31,Sheet1!G32,IF(G15=Sheet1!H31,Sheet1!H32,IF(G15=Sheet1!I31,Sheet1!I32,IF(G15=Sheet1!F37,Sheet1!F38))))))))))))))))))))) -> 12524
B17: =IF(B16=Sheet1!D7,Sheet1!D8,IF(B16=Sheet1!D13,Sheet1!D14,IF(B16=Sheet1!D19,Sheet1!D20,IF(B16=Sheet1!D25,Sheet1!D26,IF(B16=Sheet1!D31,Sheet1!D32,IF(B16=Sheet1!D37,Sheet1!D38,IF(B16=Sheet1!D43,Sheet1!D44,IF(B16=Sheet1!D49,Sheet1!D50)))))))) -> 94105 | G17: =IF(G16=Sheet1!F8,Sheet1!F9,IF(G16=Sheet1!G8,Sheet1!G9,IF(G16=Sheet1!H8,Sheet1!H9,IF(G16=Sheet1!I8,Sheet1!I9,IF(G16=Sheet1!F14,Sheet1!F15,IF(G16=Sheet1!G14,Sheet1!G15,IF(G16=Sheet1!H14,Sheet1!H15,IF(G16=Sheet1!I14,Sheet1!I15,IF(G16=Sheet1!F20,Sheet1!F21,IF(G16=Sheet1!G20,Sheet1!G21,IF(G16=Sheet1!H20,Sheet1!H21,IF(G16=Sheet1!I20,Sheet1!I21,IF(G16=Sheet1!F26,Sheet1!F27,IF(G16=Sheet1!G26,Sheet1!G27,IF(G16=Sheet1!H26,Sheet1!H27,IF(G16=Sheet1!I26,Sheet1!I27,IF(G16=Sheet1!F32,Sheet1!F33,IF(G16=Sheet1!G32,Sheet1!G33,IF(G16=Sheet1!H32,Sheet1!H33,IF(G16=Sheet1!I32,Sheet1!I33,IF(G16=Sheet1!F38,Sheet1!F39))))))))))))))))))))) -> UNITED STATES
B18: =IF(B17=Sheet1!D8,Sheet1!D9,IF(B17=Sheet1!D14,Sheet1!D15,IF(B17=Sheet1!D20,Sheet1!D21,IF(B17=Sheet1!D26,Sheet1!D27,IF(B17=Sheet1!D32,Sheet1!D33,IF(B17=Sheet1!D38,Sheet1!D39,IF(B17=Sheet1!D44,Sheet1!D45,IF(B17=Sheet1!D50,Sheet1!D51)))))))) -> UNITED STATES
B20: Dest Purchase | C20: Style NO | D20: Brand | E20: Chanel Description | F20: Currency | G20: Payment Term | H20: Final Destination | I20: Country of origin
B21: =J2 -> 61646969 | C21: =VLOOKUP($K56,reff!E2:F29,2,0) -> 905994 | D21: =IF(LEFT(B14,2)="OL","OLD NAVY",IF(LEFT(B14,2)="TH","THE GAP",IF(LEFT(B14,2)="GA","GAP",IF(LEFT(B14,2)="GP","OLD NAVY")))) -> OLD NAVY | E21: =VLOOKUP($K21,reff!H2:I29,2,0) -> ONLINE | F21: USD | H21: =IF(LEFT(G17,2)="CA","CA",IF(LEFT(G17,2)="UN","US",IF(LEFT(G17,2)="PA","PA",IF(LEFT(G17,2)="JA","JP")))) -> US | I21: ID | K21: 4
B22: Ship Mode | C22: Term of Sale | D22: Transfer Point | E22: Port Of Loading | F22: Total Gross Weight(KGS) | G22: Total Net Weight(KGS) | H22: Total Net Net Weight(KGS) | I22: Total Carton
B23: OCEAN | D23: JAKARTA,ID | E23: =+D23 -> JAKARTA,ID | F23: =+O2 -> 54.555 | G23: =+N2 -> 48.855 | H23: =+M2 -> 47.559 | I23: =+L2 -> 7
B26: Product Description
B27: =+K4 -> GIRLS COTTON FIBERS, KNIT PULLOVER, WITH NO NECK CLOSURE, STITCH COUNT IS GREATER THAN 9/2CM, REACHES WAIST [100% COTTON]
B29: Invoice Summary
B31: Color Code | C31: Color Name | D31: Total Pieces (Custom Units) | F31: Quantity Invoiced (Each) | H31: Unit Cost | I31: Extended Line Total
B32: 00, 01 | C32: BLACK LEOPARD, PINK LEOPARD HEART | F32: =+K2 -> 648 | H32: 0.81 | I32: =+H32*F32 -> 524.88
B33: Total Dozens
B34: Sub Total | F34: =SUM(F32:G33) -> 648 | I34: =SUM(I32:I33) -> 524.88
B35: Hard Tag Cost
B36: Gross Invoice Sub total | I36: =+I34 -> 524.88
B37: Discount | C37: Less early Payment discount of 5% per term and conditions of the purchase order(s)
B38: Net Invoice Total | I38: =+I36+I37 -> 524.88
B41: Invoice Notes :
B42: (NO FS)
B44: Manufacturer Information
B46: PT NIRWANA ALABARE GARMENT | E46: JL RAYA RANCAEKEK-MAJALAYA NO 289 , SOLOKAN JERUK- MAJALAYA
E47: KABUPATEN BANDUNG 40382 JABAR , INDONESIA
B49: I hereby certify that all information provided is true and correct
B50: Prepare's Name
G52: REFF | H52: =VLOOKUP($K52,reff!B2:C29,2,0) -> 265K0058 | K52: 4
C55: Yus Yulius
...

Sheet 118
K1: Item Qty | L1: Pkg Count | M1: Net Net | N1: Net | O1: Gross | P1: Unit | Q1: Vol
B2: COMERCIAL INVOICE CMT | J2: 61646973 | K2: 1624 | L2: 19 | M2: 135.957 | N2: 139.205 | O2: 155.705 | P2: KG | Q2: 0.872 | R2: CBM
B3: INVOICE NO : | C3: =+'117'!C3+1 -> 118 | G3: DATE | H3: 46215
K4: GIRLS COTTON FIBERS, KNIT PULLOVER, WITH NO NECK CLOSURE, STITCH COUNT IS GREATER THAN 9/2CM, REACHES WAIST [100% COTTON]
B5: SHIP FROM | F5: SELLER | G5: KANMAX ENTERPRISES LTD
B6: PT NIRWANA ALABARE GARMENT | G6: 60 PAYA LEBAR ROAD
B7: JL RAYA RAANCAEKEK - MAJALAYA NO 289 | G7: #04-21 PAYA LEBAR SQUARE
B8: SOLOKAN JERUK - MAJALAYA | G8: 409051 SINGAPORE
B9: KABUPATEN BANDUNG
B10: JAWABARAT 40382 INDONESIA
B13: PURCHASER | F13: SHIP TO : | G13: FISHKILL NY ONLINE-0007
B14: OLD NAVY, LLC | G14: =IF(G13=Sheet1!F5,Sheet1!F6,IF(G13=Sheet1!G5,Sheet1!G6,IF(G13=Sheet1!H5,Sheet1!H6,IF(G13=Sheet1!I5,Sheet1!I6,IF(G13=Sheet1!F11,Sheet1!F12,IF(G13=Sheet1!G11,Sheet1!G12,IF(G13=Sheet1!H11,Sheet1!H12,IF(G13=Sheet1!I11,Sheet1!I12,IF(G13=Sheet1!F17,Sheet1!F18,IF(G13=Sheet1!G17,Sheet1!G18,IF(G13=Sheet1!H17,Sheet1!H18,IF(G13=Sheet1!I17,Sheet1!I18,IF(G13=Sheet1!F23,Sheet1!F24,IF(G13=Sheet1!G23,Sheet1!G24,IF(G13=Sheet1!H23,Sheet1!H24,IF(G13=Sheet1!I23,Sheet1!I24,IF(G13=Sheet1!F29,Sheet1!F30,IF(G13=Sheet1!G29,Sheet1!G30,IF(G13=Sheet1!H29,Sheet1!H30,IF(G13=Sheet1!I29,Sheet1!I30,IF(G13=Sheet1!F35,Sheet1!F36))))))))))))))))))))) -> 110 MERRITT BLVD
B15: =IF(B14=Sheet1!D5,Sheet1!D6,IF(B14=Sheet1!D11,Sheet1!D12,IF(B14=Sheet1!D17,Sheet1!D18,IF(B14=Sheet1!D23,Sheet1!D24,IF(B14=Sheet1!D29,Sheet1!D30,IF(B14=Sheet1!D35,Sheet1!D36,IF(B14=Sheet1!D41,Sheet1!D42,IF(B14=Sheet1!D47,Sheet1!D48)))))))) -> 2 FOLSOM STREET | G15: =IF(G14=Sheet1!F6,Sheet1!F7,IF(G14=Sheet1!G6,Sheet1!G7,IF(G14=Sheet1!H6,Sheet1!H7,IF(G14=Sheet1!I6,Sheet1!I7,IF(G14=Sheet1!F12,Sheet1!F13,IF(G14=Sheet1!G12,Sheet1!G13,IF(G14=Sheet1!H12,Sheet1!H13,IF(G14=Sheet1!I12,Sheet1!I13,IF(G14=Sheet1!F18,Sheet1!F19,IF(G14=Sheet1!G18,Sheet1!G19,IF(G14=Sheet1!H18,Sheet1!H19,IF(G14=Sheet1!I18,Sheet1!I19,IF(G14=Sheet1!F24,Sheet1!F25,IF(G14=Sheet1!G24,Sheet1!G25,IF(G14=Sheet1!H24,Sheet1!H25,IF(G14=Sheet1!I24,Sheet1!I25,IF(G14=Sheet1!F30,Sheet1!F31,IF(G14=Sheet1!G30,Sheet1!G31,IF(G14=Sheet1!H30,Sheet1!H31,IF(G14=Sheet1!I30,Sheet1!I31,IF(G14=Sheet1!F36,Sheet1!F37))))))))))))))))))))) -> FISHKILL, NY
B16: =IF(B15=Sheet1!D6,Sheet1!D7,IF(B15=Sheet1!D12,Sheet1!D13,IF(B15=Sheet1!D18,Sheet1!D19,IF(B15=Sheet1!D24,Sheet1!D25,IF(B15=Sheet1!D30,Sheet1!D31,IF(B15=Sheet1!D36,Sheet1!D37,IF(B15=Sheet1!D42,Sheet1!D43,IF(B15=Sheet1!D48,Sheet1!D49)))))))) -> SAN FRANCISCO, CALIFORNIA | G16: =IF(G15=Sheet1!F7,Sheet1!F8,IF(G15=Sheet1!G7,Sheet1!G8,IF(G15=Sheet1!H7,Sheet1!H8,IF(G15=Sheet1!I7,Sheet1!I8,IF(G15=Sheet1!F13,Sheet1!F14,IF(G15=Sheet1!G13,Sheet1!G14,IF(G15=Sheet1!H13,Sheet1!H14,IF(G15=Sheet1!I13,Sheet1!I14,IF(G15=Sheet1!F19,Sheet1!F20,IF(G15=Sheet1!G19,Sheet1!G20,IF(G15=Sheet1!H19,Sheet1!H20,IF(G15=Sheet1!I19,Sheet1!I20,IF(G15=Sheet1!F25,Sheet1!F26,IF(G15=Sheet1!G25,Sheet1!G26,IF(G15=Sheet1!H25,Sheet1!H26,IF(G15=Sheet1!I25,Sheet1!I26,IF(G15=Sheet1!F31,Sheet1!F32,IF(G15=Sheet1!G31,Sheet1!G32,IF(G15=Sheet1!H31,Sheet1!H32,IF(G15=Sheet1!I31,Sheet1!I32,IF(G15=Sheet1!F37,Sheet1!F38))))))))))))))))))))) -> 12524
B17: =IF(B16=Sheet1!D7,Sheet1!D8,IF(B16=Sheet1!D13,Sheet1!D14,IF(B16=Sheet1!D19,Sheet1!D20,IF(B16=Sheet1!D25,Sheet1!D26,IF(B16=Sheet1!D31,Sheet1!D32,IF(B16=Sheet1!D37,Sheet1!D38,IF(B16=Sheet1!D43,Sheet1!D44,IF(B16=Sheet1!D49,Sheet1!D50)))))))) -> 94105 | G17: =IF(G16=Sheet1!F8,Sheet1!F9,IF(G16=Sheet1!G8,Sheet1!G9,IF(G16=Sheet1!H8,Sheet1!H9,IF(G16=Sheet1!I8,Sheet1!I9,IF(G16=Sheet1!F14,Sheet1!F15,IF(G16=Sheet1!G14,Sheet1!G15,IF(G16=Sheet1!H14,Sheet1!H15,IF(G16=Sheet1!I14,Sheet1!I15,IF(G16=Sheet1!F20,Sheet1!F21,IF(G16=Sheet1!G20,Sheet1!G21,IF(G16=Sheet1!H20,Sheet1!H21,IF(G16=Sheet1!I20,Sheet1!I21,IF(G16=Sheet1!F26,Sheet1!F27,IF(G16=Sheet1!G26,Sheet1!G27,IF(G16=Sheet1!H26,Sheet1!H27,IF(G16=Sheet1!I26,Sheet1!I27,IF(G16=Sheet1!F32,Sheet1!F33,IF(G16=Sheet1!G32,Sheet1!G33,IF(G16=Sheet1!H32,Sheet1!H33,IF(G16=Sheet1!I32,Sheet1!I33,IF(G16=Sheet1!F38,Sheet1!F39))))))))))))))))))))) -> UNITED STATES
B18: =IF(B17=Sheet1!D8,Sheet1!D9,IF(B17=Sheet1!D14,Sheet1!D15,IF(B17=Sheet1!D20,Sheet1!D21,IF(B17=Sheet1!D26,Sheet1!D27,IF(B17=Sheet1!D32,Sheet1!D33,IF(B17=Sheet1!D38,Sheet1!D39,IF(B17=Sheet1!D44,Sheet1!D45,IF(B17=Sheet1!D50,Sheet1!D51)))))))) -> UNITED STATES
B20: Dest Purchase | C20: Style NO | D20: Brand | E20: Chanel Description | F20: Currency | G20: Payment Term | H20: Final Destination | I20: Country of origin
B21: =J2 -> 61646973 | C21: =VLOOKUP($K56,reff!E2:F29,2,0) -> 906033 | D21: =IF(LEFT(B14,2)="OL","OLD NAVY",IF(LEFT(B14,2)="TH","THE GAP",IF(LEFT(B14,2)="GA","GAP",IF(LEFT(B14,2)="GP","OLD NAVY")))) -> OLD NAVY | E21: =VLOOKUP($K21,reff!H2:I29,2,0) -> RETAIL | F21: USD | H21: =IF(LEFT(G17,2)="CA","CA",IF(LEFT(G17,2)="UN","US",IF(LEFT(G17,2)="PA","PA",IF(LEFT(G17,2)="JA","JP")))) -> US | I21: ID | K21: 5
B22: Ship Mode | C22: Term of Sale | D22: Transfer Point | E22: Port Of Loading | F22: Total Gross Weight(KGS) | G22: Total Net Weight(KGS) | H22: Total Net Net Weight(KGS) | I22: Total Carton
B23: OCEAN | D23: JAKARTA,ID | E23: =+D23 -> JAKARTA,ID | F23: =+O2 -> 155.705 | G23: =+N2 -> 139.205 | H23: =+M2 -> 135.957 | I23: =+L2 -> 19
B26: Product Description
B27: =+K4 -> GIRLS COTTON FIBERS, KNIT PULLOVER, WITH NO NECK CLOSURE, STITCH COUNT IS GREATER THAN 9/2CM, REACHES WAIST [100% COTTON]
B29: Invoice Summary
B31: Color Code | C31: Color Name | D31: Total Pieces (Custom Units) | F31: Quantity Invoiced (Each) | H31: Unit Cost | I31: Extended Line Total
B32: 00, 01 | C32: BLACK LEOPARD, PINK LEOPARD HEART | F32: =+K2 -> 1624 | H32: 0.84 | I32: =+H32*F32 -> 1364.16
B33: Total Dozens
B34: Sub Total | F34: =SUM(F32:G33) -> 1624 | I34: =SUM(I32:I32) -> 1364.16
B35: Hard Tag Cost
B36: Gross Invoice Sub total | I36: =+I34 -> 1364.16
B37: Discount | C37: Less early Payment discount of 5% per term and conditions of the purchase order(s)
B38: Net Invoice Total | I38: =+I36+I37 -> 1364.16
B41: Invoice Notes :
B42: (NO FS)
B44: Manufacturer Information
B46: PT NIRWANA ALABARE GARMENT | E46: JL RAYA RANCAEKEK-MAJALAYA NO 289 , SOLOKAN JERUK- MAJALAYA
E47: KABUPATEN BANDUNG 40382 JABAR , INDONESIA
B49: I hereby certify that all information provided is true and correct
B50: Prepare's Name
G52: REFF | H52: =VLOOKUP($K52,reff!B2:C29,2,0) -> 265K0059 | K52: 5
C55: Yus Yulius
...

Sheet 119
K1: Item Qty | L1: Pkg Count | M1: Net Net | N1: Net | O1: Gross | P1: Unit | Q1: Vol
B2: COMERCIAL INVOICE CMT | J2: 61613702 | K2: 8644 | L2: 81 | M2: 702.287 | N2: 719.575 | O2: 793.975 | P2: KG | Q2: 4.663 | R2: CBM
B3: INVOICE NO : | C3: =+'118'!C3+1 -> 119 | G3: DATE | H3: 46215
K4: GIRLS COTTON FIBERS, KNIT PULLOVER, WITH NO NECK CLOSURE, STITCH COUNT IS GREATER THAN 9/2CM, REACHES WAIST [100% COTTON]
B5: SHIP FROM | F5: SELLER | G5: KANMAX ENTERPRISES LTD
B6: PT NIRWANA ALABARE GARMENT | G6: 60 PAYA LEBAR ROAD
B7: JL RAYA RAANCAEKEK - MAJALAYA NO 289 | G7: #04-21 PAYA LEBAR SQUARE
B8: SOLOKAN JERUK - MAJALAYA | G8: 409051 SINGAPORE
B9: KABUPATEN BANDUNG
B10: JAWABARAT 40382 INDONESIA
B13: PURCHASER | F13: SHIP TO : | G13: ODC-0018
B14: OLD NAVY, LLC | G14: =IF(G13=Sheet1!F5,Sheet1!F6,IF(G13=Sheet1!G5,Sheet1!G6,IF(G13=Sheet1!H5,Sheet1!H6,IF(G13=Sheet1!I5,Sheet1!I6,IF(G13=Sheet1!F11,Sheet1!F12,IF(G13=Sheet1!G11,Sheet1!G12,IF(G13=Sheet1!H11,Sheet1!H12,IF(G13=Sheet1!I11,Sheet1!I12,IF(G13=Sheet1!F17,Sheet1!F18,IF(G13=Sheet1!G17,Sheet1!G18,IF(G13=Sheet1!H17,Sheet1!H18,IF(G13=Sheet1!I17,Sheet1!I18,IF(G13=Sheet1!F23,Sheet1!F24,IF(G13=Sheet1!G23,Sheet1!G24,IF(G13=Sheet1!H23,Sheet1!H24,IF(G13=Sheet1!I23,Sheet1!I24,IF(G13=Sheet1!F29,Sheet1!F30,IF(G13=Sheet1!G29,Sheet1!G30,IF(G13=Sheet1!H29,Sheet1!H30,IF(G13=Sheet1!I29,Sheet1!I30,IF(G13=Sheet1!F35,Sheet1!F36))))))))))))))))))))) -> 110 MERRITT BLVD
B15: =IF(B14=Sheet1!D5,Sheet1!D6,IF(B14=Sheet1!D11,Sheet1!D12,IF(B14=Sheet1!D17,Sheet1!D18,IF(B14=Sheet1!D23,Sheet1!D24,IF(B14=Sheet1!D29,Sheet1!D30,IF(B14=Sheet1!D35,Sheet1!D36,IF(B14=Sheet1!D41,Sheet1!D42,IF(B14=Sheet1!D47,Sheet1!D48)))))))) -> 2 FOLSOM STREET | G15: =IF(G14=Sheet1!F6,Sheet1!F7,IF(G14=Sheet1!G6,Sheet1!G7,IF(G14=Sheet1!H6,Sheet1!H7,IF(G14=Sheet1!I6,Sheet1!I7,IF(G14=Sheet1!F12,Sheet1!F13,IF(G14=Sheet1!G12,Sheet1!G13,IF(G14=Sheet1!H12,Sheet1!H13,IF(G14=Sheet1!I12,Sheet1!I13,IF(G14=Sheet1!F18,Sheet1!F19,IF(G14=Sheet1!G18,Sheet1!G19,IF(G14=Sheet1!H18,Sheet1!H19,IF(G14=Sheet1!I18,Sheet1!I19,IF(G14=Sheet1!F24,Sheet1!F25,IF(G14=Sheet1!G24,Sheet1!G25,IF(G14=Sheet1!H24,Sheet1!H25,IF(G14=Sheet1!I24,Sheet1!I25,IF(G14=Sheet1!F30,Sheet1!F31,IF(G14=Sheet1!G30,Sheet1!G31,IF(G14=Sheet1!H30,Sheet1!H31,IF(G14=Sheet1!I30,Sheet1!I31,IF(G14=Sheet1!F36,Sheet1!F37))))))))))))))))))))) -> FISHKILL, NY
B16: =IF(B15=Sheet1!D6,Sheet1!D7,IF(B15=Sheet1!D12,Sheet1!D13,IF(B15=Sheet1!D18,Sheet1!D19,IF(B15=Sheet1!D24,Sheet1!D25,IF(B15=Sheet1!D30,Sheet1!D31,IF(B15=Sheet1!D36,Sheet1!D37,IF(B15=Sheet1!D42,Sheet1!D43,IF(B15=Sheet1!D48,Sheet1!D49)))))))) -> SAN FRANCISCO, CALIFORNIA | G16: =IF(G15=Sheet1!F7,Sheet1!F8,IF(G15=Sheet1!G7,Sheet1!G8,IF(G15=Sheet1!H7,Sheet1!H8,IF(G15=Sheet1!I7,Sheet1!I8,IF(G15=Sheet1!F13,Sheet1!F14,IF(G15=Sheet1!G13,Sheet1!G14,IF(G15=Sheet1!H13,Sheet1!H14,IF(G15=Sheet1!I13,Sheet1!I14,IF(G15=Sheet1!F19,Sheet1!F20,IF(G15=Sheet1!G19,Sheet1!G20,IF(G15=Sheet1!H19,Sheet1!H20,IF(G15=Sheet1!I19,Sheet1!I20,IF(G15=Sheet1!F25,Sheet1!F26,IF(G15=Sheet1!G25,Sheet1!G26,IF(G15=Sheet1!H25,Sheet1!H26,IF(G15=Sheet1!I25,Sheet1!I26,IF(G15=Sheet1!F31,Sheet1!F32,IF(G15=Sheet1!G31,Sheet1!G32,IF(G15=Sheet1!H31,Sheet1!H32,IF(G15=Sheet1!I31,Sheet1!I32,IF(G15=Sheet1!F37,Sheet1!F38))))))))))))))))))))) -> 12524
B17: =IF(B16=Sheet1!D7,Sheet1!D8,IF(B16=Sheet1!D13,Sheet1!D14,IF(B16=Sheet1!D19,Sheet1!D20,IF(B16=Sheet1!D25,Sheet1!D26,IF(B16=Sheet1!D31,Sheet1!D32,IF(B16=Sheet1!D37,Sheet1!D38,IF(B16=Sheet1!D43,Sheet1!D44,IF(B16=Sheet1!D49,Sheet1!D50)))))))) -> 94105 | G17: =IF(G16=Sheet1!F8,Sheet1!F9,IF(G16=Sheet1!G8,Sheet1!G9,IF(G16=Sheet1!H8,Sheet1!H9,IF(G16=Sheet1!I8,Sheet1!I9,IF(G16=Sheet1!F14,Sheet1!F15,IF(G16=Sheet1!G14,Sheet1!G15,IF(G16=Sheet1!H14,Sheet1!H15,IF(G16=Sheet1!I14,Sheet1!I15,IF(G16=Sheet1!F20,Sheet1!F21,IF(G16=Sheet1!G20,Sheet1!G21,IF(G16=Sheet1!H20,Sheet1!H21,IF(G16=Sheet1!I20,Sheet1!I21,IF(G16=Sheet1!F26,Sheet1!F27,IF(G16=Sheet1!G26,Sheet1!G27,IF(G16=Sheet1!H26,Sheet1!H27,IF(G16=Sheet1!I26,Sheet1!I27,IF(G16=Sheet1!F32,Sheet1!F33,IF(G16=Sheet1!G32,Sheet1!G33,IF(G16=Sheet1!H32,Sheet1!H33,IF(G16=Sheet1!I32,Sheet1!I33,IF(G16=Sheet1!F38,Sheet1!F39))))))))))))))))))))) -> UNITED STATES
B18: =IF(B17=Sheet1!D8,Sheet1!D9,IF(B17=Sheet1!D14,Sheet1!D15,IF(B17=Sheet1!D20,Sheet1!D21,IF(B17=Sheet1!D26,Sheet1!D27,IF(B17=Sheet1!D32,Sheet1!D33,IF(B17=Sheet1!D38,Sheet1!D39,IF(B17=Sheet1!D44,Sheet1!D45,IF(B17=Sheet1!D50,Sheet1!D51)))))))) -> UNITED STATES
B20: Dest Purchase | C20: Style NO | D20: Brand | E20: Chanel Description | F20: Currency | G20: Payment Term | H20: Final Destination | I20: Country of origin
B21: =J2 -> 61613702 | C21: =VLOOKUP($K56,reff!E2:F29,2,0) -> 906033 | D21: =IF(LEFT(B14,2)="OL","OLD NAVY",IF(LEFT(B14,2)="TH","THE GAP",IF(LEFT(B14,2)="GA","GAP",IF(LEFT(B14,2)="GP","OLD NAVY")))) -> OLD NAVY | E21: =VLOOKUP($K21,reff!H2:I29,2,0) -> ONLINE | F21: USD | H21: =IF(LEFT(G17,2)="CA","CA",IF(LEFT(G17,2)="UN","US",IF(LEFT(G17,2)="PA","PA",IF(LEFT(G17,2)="JA","JP")))) -> US | I21: ID | K21: 6
B22: Ship Mode | C22: Term of Sale | D22: Transfer Point | E22: Port Of Loading | F22: Total Gross Weight(KGS) | G22: Total Net Weight(KGS) | H22: Total Net Net Weight(KGS) | I22: Total Carton
B23: OCEAN | D23: JAKARTA,ID | E23: =+D23 -> JAKARTA,ID | F23: =+O2 -> 793.975 | G23: =+N2 -> 719.575 | H23: =+M2 -> 702.287 | I23: =+L2 -> 81
B26: Product Description
B27: =+K4 -> GIRLS COTTON FIBERS, KNIT PULLOVER, WITH NO NECK CLOSURE, STITCH COUNT IS GREATER THAN 9/2CM, REACHES WAIST [100% COTTON]
B29: Invoice Summary
B31: Color Code | C31: Color Name | D31: Total Pieces (Custom Units) | F31: Quantity Invoiced (Each) | H31: Unit Cost | I31: Extended Line Total
B32: 00, 01 | C32: BLACK LEOPARD, PINK LEOPARD HEART | F32: =+K2 -> 8644 | H32: 0.84 | I32: =+H32*F32 -> 7260.96
B33: Total Dozens
B34: Sub Total | F34: =SUM(F32:G33) -> 8644 | I34: =SUM(I32:I33) -> 7260.96
B35: Hard Tag Cost
B36: Gross Invoice Sub total | I36: =+I34 -> 7260.96
B37: Discount | C37: Less early Payment discount of 5% per term and conditions of the purchase order(s)
B38: Net Invoice Total | I38: =+I36+I37 -> 7260.96
B41: Invoice Notes :
B42: (NO FS)
B44: Manufacturer Information
B46: PT NIRWANA ALABARE GARMENT | E46: JL RAYA RANCAEKEK-MAJALAYA NO 289 , SOLOKAN JERUK- MAJALAYA
E47: KABUPATEN BANDUNG 40382 JABAR , INDONESIA
B49: I hereby certify that all information provided is true and correct
B50: Prepare's Name
G52: REFF | H52: =VLOOKUP($K52,reff!B2:C29,2,0) -> 265K0059 | K52: 6
C55: Yus Yulius
...

Sheet 120
K1: Item Qty | L1: Pkg Count | M1: Net Net | N1: Net | O1: Gross | P1: Unit | Q1: Vol
B2: COMERCIAL INVOICE CMT | J2: 61969484 | K2: 549 | L2: 9 | M2: 59.18 | N2: 64.67 | O2: 72.07 | P2: KG | Q2: 0.358 | R2: CBM
B3: INVOICE NO : | C3: =+'119'!C3+1 -> 120 | G3: DATE | H3: 46215
K4: WOMENS COTTON FIBERS, KNIT PULLOVER, WITH NO NECK CLOSURE, STITCH COUNT IS GREATER THAN 9/2CM, REACHES WAIST, SLEEVELESS [96% COTTON 4% SPANDEX]
B5: SHIP FROM | F5: SELLER | G5: KANMAX ENTERPRISES LTD
B6: PT NIRWANA ALABARE GARMENT | G6: 60 PAYA LEBAR ROAD
B7: JL RAYA RAANCAEKEK - MAJALAYA NO 289 | G7: #04-21 PAYA LEBAR SQUARE
B8: SOLOKAN JERUK - MAJALAYA | G8: 409051 SINGAPORE
B9: KABUPATEN BANDUNG
B10: JAWABARAT 40382 INDONESIA
B13: PURCHASER | F13: SHIP TO : | G13: FISHKILL NY ONLINE-0007
B14: OLD NAVY, LLC | G14: =IF(G13=Sheet1!F5,Sheet1!F6,IF(G13=Sheet1!G5,Sheet1!G6,IF(G13=Sheet1!H5,Sheet1!H6,IF(G13=Sheet1!I5,Sheet1!I6,IF(G13=Sheet1!F11,Sheet1!F12,IF(G13=Sheet1!G11,Sheet1!G12,IF(G13=Sheet1!H11,Sheet1!H12,IF(G13=Sheet1!I11,Sheet1!I12,IF(G13=Sheet1!F17,Sheet1!F18,IF(G13=Sheet1!G17,Sheet1!G18,IF(G13=Sheet1!H17,Sheet1!H18,IF(G13=Sheet1!I17,Sheet1!I18,IF(G13=Sheet1!F23,Sheet1!F24,IF(G13=Sheet1!G23,Sheet1!G24,IF(G13=Sheet1!H23,Sheet1!H24,IF(G13=Sheet1!I23,Sheet1!I24,IF(G13=Sheet1!F29,Sheet1!F30,IF(G13=Sheet1!G29,Sheet1!G30,IF(G13=Sheet1!H29,Sheet1!H30,IF(G13=Sheet1!I29,Sheet1!I30,IF(G13=Sheet1!F35,Sheet1!F36))))))))))))))))))))) -> 110 MERRITT BLVD
B15: =IF(B14=Sheet1!D5,Sheet1!D6,IF(B14=Sheet1!D11,Sheet1!D12,IF(B14=Sheet1!D17,Sheet1!D18,IF(B14=Sheet1!D23,Sheet1!D24,IF(B14=Sheet1!D29,Sheet1!D30,IF(B14=Sheet1!D35,Sheet1!D36,IF(B14=Sheet1!D41,Sheet1!D42,IF(B14=Sheet1!D47,Sheet1!D48)))))))) -> 2 FOLSOM STREET | G15: =IF(G14=Sheet1!F6,Sheet1!F7,IF(G14=Sheet1!G6,Sheet1!G7,IF(G14=Sheet1!H6,Sheet1!H7,IF(G14=Sheet1!I6,Sheet1!I7,IF(G14=Sheet1!F12,Sheet1!F13,IF(G14=Sheet1!G12,Sheet1!G13,IF(G14=Sheet1!H12,Sheet1!H13,IF(G14=Sheet1!I12,Sheet1!I13,IF(G14=Sheet1!F18,Sheet1!F19,IF(G14=Sheet1!G18,Sheet1!G19,IF(G14=Sheet1!H18,Sheet1!H19,IF(G14=Sheet1!I18,Sheet1!I19,IF(G14=Sheet1!F24,Sheet1!F25,IF(G14=Sheet1!G24,Sheet1!G25,IF(G14=Sheet1!H24,Sheet1!H25,IF(G14=Sheet1!I24,Sheet1!I25,IF(G14=Sheet1!F30,Sheet1!F31,IF(G14=Sheet1!G30,Sheet1!G31,IF(G14=Sheet1!H30,Sheet1!H31,IF(G14=Sheet1!I30,Sheet1!I31,IF(G14=Sheet1!F36,Sheet1!F37))))))))))))))))))))) -> FISHKILL, NY
B16: =IF(B15=Sheet1!D6,Sheet1!D7,IF(B15=Sheet1!D12,Sheet1!D13,IF(B15=Sheet1!D18,Sheet1!D19,IF(B15=Sheet1!D24,Sheet1!D25,IF(B15=Sheet1!D30,Sheet1!D31,IF(B15=Sheet1!D36,Sheet1!D37,IF(B15=Sheet1!D42,Sheet1!D43,IF(B15=Sheet1!D48,Sheet1!D49)))))))) -> SAN FRANCISCO, CALIFORNIA | G16: =IF(G15=Sheet1!F7,Sheet1!F8,IF(G15=Sheet1!G7,Sheet1!G8,IF(G15=Sheet1!H7,Sheet1!H8,IF(G15=Sheet1!I7,Sheet1!I8,IF(G15=Sheet1!F13,Sheet1!F14,IF(G15=Sheet1!G13,Sheet1!G14,IF(G15=Sheet1!H13,Sheet1!H14,IF(G15=Sheet1!I13,Sheet1!I14,IF(G15=Sheet1!F19,Sheet1!F20,IF(G15=Sheet1!G19,Sheet1!G20,IF(G15=Sheet1!H19,Sheet1!H20,IF(G15=Sheet1!I19,Sheet1!I20,IF(G15=Sheet1!F25,Sheet1!F26,IF(G15=Sheet1!G25,Sheet1!G26,IF(G15=Sheet1!H25,Sheet1!H26,IF(G15=Sheet1!I25,Sheet1!I26,IF(G15=Sheet1!F31,Sheet1!F32,IF(G15=Sheet1!G31,Sheet1!G32,IF(G15=Sheet1!H31,Sheet1!H32,IF(G15=Sheet1!I31,Sheet1!I32,IF(G15=Sheet1!F37,Sheet1!F38))))))))))))))))))))) -> 12524
B17: =IF(B16=Sheet1!D7,Sheet1!D8,IF(B16=Sheet1!D13,Sheet1!D14,IF(B16=Sheet1!D19,Sheet1!D20,IF(B16=Sheet1!D25,Sheet1!D26,IF(B16=Sheet1!D31,Sheet1!D32,IF(B16=Sheet1!D37,Sheet1!D38,IF(B16=Sheet1!D43,Sheet1!D44,IF(B16=Sheet1!D49,Sheet1!D50)))))))) -> 94105 | G17: =IF(G16=Sheet1!F8,Sheet1!F9,IF(G16=Sheet1!G8,Sheet1!G9,IF(G16=Sheet1!H8,Sheet1!H9,IF(G16=Sheet1!I8,Sheet1!I9,IF(G16=Sheet1!F14,Sheet1!F15,IF(G16=Sheet1!G14,Sheet1!G15,IF(G16=Sheet1!H14,Sheet1!H15,IF(G16=Sheet1!I14,Sheet1!I15,IF(G16=Sheet1!F20,Sheet1!F21,IF(G16=Sheet1!G20,Sheet1!G21,IF(G16=Sheet1!H20,Sheet1!H21,IF(G16=Sheet1!I20,Sheet1!I21,IF(G16=Sheet1!F26,Sheet1!F27,IF(G16=Sheet1!G26,Sheet1!G27,IF(G16=Sheet1!H26,Sheet1!H27,IF(G16=Sheet1!I26,Sheet1!I27,IF(G16=Sheet1!F32,Sheet1!F33,IF(G16=Sheet1!G32,Sheet1!G33,IF(G16=Sheet1!H32,Sheet1!H33,IF(G16=Sheet1!I32,Sheet1!I33,IF(G16=Sheet1!F38,Sheet1!F39))))))))))))))))))))) -> UNITED STATES
B18: =IF(B17=Sheet1!D8,Sheet1!D9,IF(B17=Sheet1!D14,Sheet1!D15,IF(B17=Sheet1!D20,Sheet1!D21,IF(B17=Sheet1!D26,Sheet1!D27,IF(B17=Sheet1!D32,Sheet1!D33,IF(B17=Sheet1!D38,Sheet1!D39,IF(B17=Sheet1!D44,Sheet1!D45,IF(B17=Sheet1!D50,Sheet1!D51)))))))) -> UNITED STATES
B20: Dest Purchase | C20: Style NO | D20: Brand | E20: Chanel Description | F20: Currency | G20: Payment Term | H20: Final Destination | I20: Country of origin
B21: =J2 -> 61969484 | C21: =VLOOKUP($K55,reff!E2:F29,2,0) -> 692926 | D21: =IF(LEFT(B14,2)="OL","OLD NAVY",IF(LEFT(B14,2)="TH","THE GAP",IF(LEFT(B14,2)="GA","GAP",IF(LEFT(B14,2)="GP","OLD NAVY")))) -> OLD NAVY | E21: =VLOOKUP($K21,reff!H2:I29,2,0) -> ONLINE | F21: USD | H21: =IF(LEFT(G17,2)="CA","CA",IF(LEFT(G17,2)="UN","US",IF(LEFT(G17,2)="PA","PA",IF(LEFT(G17,2)="JA","JP")))) -> US | I21: ID | K21: 7
B22: Ship Mode | C22: Term of Sale | D22: Transfer Point | E22: Port Of Loading | F22: Total Gross Weight(KGS) | G22: Total Net Weight(KGS) | H22: Total Net Net Weight(KGS) | I22: Total Carton
B23: OCEAN | D23: JAKARTA,ID | E23: =+D23 -> JAKARTA,ID | F23: =+O2 -> 72.07 | G23: =+N2 -> 64.67 | H23: =+M2 -> 59.18 | I23: =+L2 -> 9
B26: Product Description
B27: =+K4 -> WOMENS COTTON FIBERS, KNIT PULLOVER, WITH NO NECK CLOSURE, STITCH COUNT IS GREATER THAN 9/2CM, REACHES WAIST, SLEEVELESS [96% COTTON 4% SPANDEX]
B29: Invoice Summary
B31: Color Code | C31: Color Name | D31: Total Pieces (Custom Units) | F31: Quantity Invoiced (Each) | H31: Unit Cost | I31: Extended Line Total
B32: 21 | C32: SHOOTING STAR | F32: =+K2 -> 549 | H32: 0.76 | I32: =+H32*F32 -> 417.24
B33: Total Dozens
B34: Sub Total | F34: =SUM(F32:G33) -> 549 | I34: =SUM(I32:I33) -> 417.24
B35: Hard Tag Cost
B36: Gross Invoice Sub total | I36: =+I34 -> 417.24
B37: Discount | C37: Less early Payment discount of 5% per term and conditions of the purchase order(s)
B38: Net Invoice Total | I38: =+I36+I37 -> 417.24
B41: Invoice Notes :
B42: (NO FS)
B44: Manufacturer Information
B46: PT NIRWANA ALABARE GARMENT | E46: JL RAYA RANCAEKEK-MAJALAYA NO 289 , SOLOKAN JERUK- MAJALAYA
E47: KABUPATEN BANDUNG 40382 JABAR , INDONESIA
B49: I hereby certify that all information provided is true and correct
B50: Prepare's Name
G52: REFF | H52: =VLOOKUP($K52,reff!B2:C29,2,0) -> 265K0075 | K52: 7
C55: Yus Yulius | K55: 7
...

Sheet 121
K1: Item Qty | L1: Pkg Count | M1: Net Net | N1: Net | O1: Gross | P1: Unit | Q1: Vol
B2: COMERCIAL INVOICE CMT | J2: 62023767 | K2: 1139 | L2: 23 | M2: 115.77 | N2: 155.635 | O2: 177.835 | P2: KG | Q2: 1.409 | R2: CBM
B3: INVOICE NO : | C3: =+'120'!C3+1 -> 121 | G3: DATE | H3: 46215
K4: WOMENS COTTON FIBERS, KNIT PULLOVER, WITH NO NECK CLOSURE, STITCH COUNT IS GREATER THAN 9/2CM, REACHES WAIST, SLEEVELESS [96% COTTON 4% SPANDEX]
B5: SHIP FROM | F5: SELLER | G5: KANMAX ENTERPRISES LTD
B6: PT NIRWANA ALABARE GARMENT | G6: 60 PAYA LEBAR ROAD
B7: JL RAYA RAANCAEKEK - MAJALAYA NO 289 | G7: #04-21 PAYA LEBAR SQUARE
B8: SOLOKAN JERUK - MAJALAYA | G8: 409051 SINGAPORE
B9: KABUPATEN BANDUNG
B10: JAWABARAT 40382 INDONESIA
B13: PURCHASER | F13: SHIP TO : | G13: ODC-0018
B14: OLD NAVY, LLC | G14: =IF(G13=Sheet1!F5,Sheet1!F6,IF(G13=Sheet1!G5,Sheet1!G6,IF(G13=Sheet1!H5,Sheet1!H6,IF(G13=Sheet1!I5,Sheet1!I6,IF(G13=Sheet1!F11,Sheet1!F12,IF(G13=Sheet1!G11,Sheet1!G12,IF(G13=Sheet1!H11,Sheet1!H12,IF(G13=Sheet1!I11,Sheet1!I12,IF(G13=Sheet1!F17,Sheet1!F18,IF(G13=Sheet1!G17,Sheet1!G18,IF(G13=Sheet1!H17,Sheet1!H18,IF(G13=Sheet1!I17,Sheet1!I18,IF(G13=Sheet1!F23,Sheet1!F24,IF(G13=Sheet1!G23,Sheet1!G24,IF(G13=Sheet1!H23,Sheet1!H24,IF(G13=Sheet1!I23,Sheet1!I24,IF(G13=Sheet1!F29,Sheet1!F30,IF(G13=Sheet1!G29,Sheet1!G30,IF(G13=Sheet1!H29,Sheet1!H30,IF(G13=Sheet1!I29,Sheet1!I30,IF(G13=Sheet1!F35,Sheet1!F36))))))))))))))))))))) -> 110 MERRITT BLVD
B15: =IF(B14=Sheet1!D5,Sheet1!D6,IF(B14=Sheet1!D11,Sheet1!D12,IF(B14=Sheet1!D17,Sheet1!D18,IF(B14=Sheet1!D23,Sheet1!D24,IF(B14=Sheet1!D29,Sheet1!D30,IF(B14=Sheet1!D35,Sheet1!D36,IF(B14=Sheet1!D41,Sheet1!D42,IF(B14=Sheet1!D47,Sheet1!D48)))))))) -> 2 FOLSOM STREET | G15: =IF(G14=Sheet1!F6,Sheet1!F7,IF(G14=Sheet1!G6,Sheet1!G7,IF(G14=Sheet1!H6,Sheet1!H7,IF(G14=Sheet1!I6,Sheet1!I7,IF(G14=Sheet1!F12,Sheet1!F13,IF(G14=Sheet1!G12,Sheet1!G13,IF(G14=Sheet1!H12,Sheet1!H13,IF(G14=Sheet1!I12,Sheet1!I13,IF(G14=Sheet1!F18,Sheet1!F19,IF(G14=Sheet1!G18,Sheet1!G19,IF(G14=Sheet1!H18,Sheet1!H19,IF(G14=Sheet1!I18,Sheet1!I19,IF(G14=Sheet1!F24,Sheet1!F25,IF(G14=Sheet1!G24,Sheet1!G25,IF(G14=Sheet1!H24,Sheet1!H25,IF(G14=Sheet1!I24,Sheet1!I25,IF(G14=Sheet1!F30,Sheet1!F31,IF(G14=Sheet1!G30,Sheet1!G31,IF(G14=Sheet1!H30,Sheet1!H31,IF(G14=Sheet1!I30,Sheet1!I31,IF(G14=Sheet1!F36,Sheet1!F37))))))))))))))))))))) -> FISHKILL, NY
B16: =IF(B15=Sheet1!D6,Sheet1!D7,IF(B15=Sheet1!D12,Sheet1!D13,IF(B15=Sheet1!D18,Sheet1!D19,IF(B15=Sheet1!D24,Sheet1!D25,IF(B15=Sheet1!D30,Sheet1!D31,IF(B15=Sheet1!D36,Sheet1!D37,IF(B15=Sheet1!D42,Sheet1!D43,IF(B15=Sheet1!D48,Sheet1!D49)))))))) -> SAN FRANCISCO, CALIFORNIA | G16: =IF(G15=Sheet1!F7,Sheet1!F8,IF(G15=Sheet1!G7,Sheet1!G8,IF(G15=Sheet1!H7,Sheet1!H8,IF(G15=Sheet1!I7,Sheet1!I8,IF(G15=Sheet1!F13,Sheet1!F14,IF(G15=Sheet1!G13,Sheet1!G14,IF(G15=Sheet1!H13,Sheet1!H14,IF(G15=Sheet1!I13,Sheet1!I14,IF(G15=Sheet1!F19,Sheet1!F20,IF(G15=Sheet1!G19,Sheet1!G20,IF(G15=Sheet1!H19,Sheet1!H20,IF(G15=Sheet1!I19,Sheet1!I20,IF(G15=Sheet1!F25,Sheet1!F26,IF(G15=Sheet1!G25,Sheet1!G26,IF(G15=Sheet1!H25,Sheet1!H26,IF(G15=Sheet1!I25,Sheet1!I26,IF(G15=Sheet1!F31,Sheet1!F32,IF(G15=Sheet1!G31,Sheet1!G32,IF(G15=Sheet1!H31,Sheet1!H32,IF(G15=Sheet1!I31,Sheet1!I32,IF(G15=Sheet1!F37,Sheet1!F38))))))))))))))))))))) -> 12524
B17: =IF(B16=Sheet1!D7,Sheet1!D8,IF(B16=Sheet1!D13,Sheet1!D14,IF(B16=Sheet1!D19,Sheet1!D20,IF(B16=Sheet1!D25,Sheet1!D26,IF(B16=Sheet1!D31,Sheet1!D32,IF(B16=Sheet1!D37,Sheet1!D38,IF(B16=Sheet1!D43,Sheet1!D44,IF(B16=Sheet1!D49,Sheet1!D50)))))))) -> 94105 | G17: =IF(G16=Sheet1!F8,Sheet1!F9,IF(G16=Sheet1!G8,Sheet1!G9,IF(G16=Sheet1!H8,Sheet1!H9,IF(G16=Sheet1!I8,Sheet1!I9,IF(G16=Sheet1!F14,Sheet1!F15,IF(G16=Sheet1!G14,Sheet1!G15,IF(G16=Sheet1!H14,Sheet1!H15,IF(G16=Sheet1!I14,Sheet1!I15,IF(G16=Sheet1!F20,Sheet1!F21,IF(G16=Sheet1!G20,Sheet1!G21,IF(G16=Sheet1!H20,Sheet1!H21,IF(G16=Sheet1!I20,Sheet1!I21,IF(G16=Sheet1!F26,Sheet1!F27,IF(G16=Sheet1!G26,Sheet1!G27,IF(G16=Sheet1!H26,Sheet1!H27,IF(G16=Sheet1!I26,Sheet1!I27,IF(G16=Sheet1!F32,Sheet1!F33,IF(G16=Sheet1!G32,Sheet1!G33,IF(G16=Sheet1!H32,Sheet1!H33,IF(G16=Sheet1!I32,Sheet1!I33,IF(G16=Sheet1!F38,Sheet1!F39))))))))))))))))))))) -> UNITED STATES
B18: =IF(B17=Sheet1!D8,Sheet1!D9,IF(B17=Sheet1!D14,Sheet1!D15,IF(B17=Sheet1!D20,Sheet1!D21,IF(B17=Sheet1!D26,Sheet1!D27,IF(B17=Sheet1!D32,Sheet1!D33,IF(B17=Sheet1!D38,Sheet1!D39,IF(B17=Sheet1!D44,Sheet1!D45,IF(B17=Sheet1!D50,Sheet1!D51)))))))) -> UNITED STATES
B20: Dest Purchase | C20: Style NO | D20: Brand | E20: Chanel Description | F20: Currency | G20: Payment Term | H20: Final Destination | I20: Country of origin
B21: =J2 -> 62023767 | C21: =VLOOKUP($K55,reff!E2:F29,2,0) -> 692926 | D21: =IF(LEFT(B14,2)="OL","OLD NAVY",IF(LEFT(B14,2)="TH","THE GAP",IF(LEFT(B14,2)="GA","GAP",IF(LEFT(B14,2)="GP","OLD NAVY")))) -> OLD NAVY | E21: =VLOOKUP($K21,reff!H2:I29,2,0) -> RETAIL | F21: USD | H21: =IF(LEFT(G17,2)="CA","CA",IF(LEFT(G17,2)="UN","US",IF(LEFT(G17,2)="PA","PA",IF(LEFT(G17,2)="JA","JP")))) -> US | I21: ID | K21: 8
B22: Ship Mode | C22: Term of Sale | D22: Transfer Point | E22: Port Of Loading | F22: Total Gross Weight(KGS) | G22: Total Net Weight(KGS) | H22: Total Net Net Weight(KGS) | I22: Total Carton
B23: OCEAN | D23: JAKARTA,ID | E23: =+D23 -> JAKARTA,ID | F23: =+O2 -> 177.835 | G23: =+N2 -> 155.635 | H23: =+M2 -> 115.77 | I23: =+L2 -> 23
B26: Product Description
B27: =+K4 -> WOMENS COTTON FIBERS, KNIT PULLOVER, WITH NO NECK CLOSURE, STITCH COUNT IS GREATER THAN 9/2CM, REACHES WAIST, SLEEVELESS [96% COTTON 4% SPANDEX]
B29: Invoice Summary
B31: Color Code | C31: Color Name | D31: Total Pieces (Custom Units) | F31: Quantity Invoiced (Each) | H31: Unit Cost | I31: Extended Line Total
B32: 21 | C32: SHOOTING STAR | F32: =+K2 -> 1139 | H32: 0.76 | I32: =+H32*F32 -> 865.64
B33: Total Dozens
B34: Sub Total | F34: =SUM(F32:G33) -> 1139 | I34: =SUM(I32:I33) -> 865.64
B35: Hard Tag Cost
B36: Gross Invoice Sub total | I36: =+I34 -> 865.64
B37: Discount | C37: Less early Payment discount of 5% per term and conditions of the purchase order(s)
B38: Net Invoice Total | I38: =+I36+I37 -> 865.64
B41: Invoice Notes :
B42: (NO FS)
B44: Manufacturer Information
B46: PT NIRWANA ALABARE GARMENT | E46: JL RAYA RANCAEKEK-MAJALAYA NO 289 , SOLOKAN JERUK- MAJALAYA
E47: KABUPATEN BANDUNG 40382 JABAR , INDONESIA
B49: I hereby certify that all information provided is true and correct
B50: Prepare's Name
G52: REFF | H52: =VLOOKUP($K52,reff!B2:C29,2,0) -> 265K0075 | K52: 8
C55: Yus Yulius | K55: 8
...

Sheet 122
K1: Item Qty | L1: Pkg Count | M1: Net Net | N1: Net | O1: Gross | P1: Unit | Q1: Vol
B2: COMERCIAL INVOICE CMT | J2: 62023770 | K2: 1174 | L2: 23 | M2: 120.24 | N2: 161.33 | O2: 183.93 | P2: KG | Q2: 1.476 | R2: CBM
B3: INVOICE NO : | C3: =+'121'!C3+1 -> 122 | G3: DATE | H3: 46215
K4: WOMENS COTTON FIBERS, KNIT PULLOVER, WITH NO NECK CLOSURE, STITCH COUNT IS GREATER THAN 9/2CM, REACHES WAIST, SLEEVELESS [96% COTTON 4% SPANDEX]
B5: SHIP FROM | F5: SELLER | G5: KANMAX ENTERPRISES LTD
B6: PT NIRWANA ALABARE GARMENT | G6: 60 PAYA LEBAR ROAD
B7: JL RAYA RAANCAEKEK - MAJALAYA NO 289 | G7: #04-21 PAYA LEBAR SQUARE
B8: SOLOKAN JERUK - MAJALAYA | G8: 409051 SINGAPORE
B9: KABUPATEN BANDUNG
B10: JAWABARAT 40382 INDONESIA
B13: PURCHASER | F13: SHIP TO : | G13: ODC-0018
