Workbook

Sheet INV-HQ
A1: KAM HING (VIETNAM) TEXTILE PRINTING AND DYEING COMPANY LIMITED
A2: NHON TRACH 6A SUBDIVISION, NHON TRACH 6 INDUSTRIAL PARK,PHUOC AN COMMUNE, DONG NAI PROVINCE, VIET NAM
A3: COMMERCIAL INVOICE
A4: SELLER/FOR ACCOUNT | D4: KAM HING PIECE WORKS LTD | J4: No.: | L4: KHV-MNA150726-01
A5: OF APPLICANT: | D5: UNIT A, 23/F., TML TOWER, 3 HOI SHING ROAD, | J5: Date: | L5: 15/07/2026
D6: TSUEN WAN, N.T., HONG KONG | J6: VENDOR NAME : | L6: MAXHILL MANAGEMENT SERVICES PTE LTD.
A7: CONSIGNEE/ NOTIFY PARTY: | D7: PT Nirwana Alabare Garment | J7: VENDOR P.O. NO. : | L7: 265K0104-LOT A-CHASE-DF00252
D8: Jl. Raya Rancaekek - Majalaya No.289,Desa Solokan Jeruk , | J8: STYLE NO.: | L8: S#692926 HOL26
D9: Kecamatan Solokan Jeruk,Kabupaten Bandung Jawa Barat 40382,Indonesia | J9: P.O. NO. : | L9: KZ260600036
D10: Tel: +62 285962076 ID : 74.540.692.6-444.000 | J10: CONTRACT NO. : | L10: 01KHV-KFPW/2025
A11: Means of transport: | D11: BY VESSEL | J11: Booking No. | L11: SITSGJT0709G189957
A12: Port of Loading: | D12: HO CHI MINH CITY, VIETNAM | J12: Container No.: | L12: SITU2469545
A13: Port of Discharge: | D13: JAKARTA, INDONESIA | J13: Seal No.: | L13: SITB016385
A14: Partial Shipment: | D14: Allowed | J14: ETD DATE: | L14: 46224
A15: Transhipment: | D15: Allowed | J15: ETA DATE: | L15: 46227
A16: Terms of Payment: | D16: T/T 30 days | J16: Payment information:
A17: Trade Terms: | D17: FOB, HO CHI MINH CITY PORT, VIETNAM | J17: Account name: | K17: KAM HING (VIETNAM) TEXTILE PRINTING AND DYEING COMPANY LIMITED
J18: Account number: 1106 2809 8368( USD)
J19: Bank name : | K19: Vietnam Joint Stock Commercial Bank For Industry and Trade - Branch No.6
K20: Ho Chi Minh City
J21: Bank address: | K21: 1A - 1B - 2 Floor, A part of 11 Floor, 635B Building, Nguyen Trai Street, Cho Lon Ward,
K22: Ho Chi Minh City, Vietnam | AC22: =AB24+AC24 -> 295.38462
J23: Swift code: | K23: ICBVVNVX922 | AB23: phí kéo cont +khai hàng 1 cont 40+1*20 | AC23: phí lcc 1 cont 40+20
AB24: =3000000/26000 -> 115.38462 | AC24: 180 | AD24: usd/
A25: No. | B25: Item code Customs | C25: RD No. | D25: PO No. | E25: Description of goods | F25: Color and Reference No. | G25: Rolls | H25: Quantity NW (Kg) | I25: Quantity GW (Kg) | J25: Quantity Length (Yds) | K25: Quantity Length (MTR) | L25: Quantity NW (Lbs) | M25: Quantity GW (Lbs) | N25: Unit processing Price (USD/lb) | O25: Unit processing Price (USD/KG) | P25: Amount processing (USD/KG) | Q25: Unit Price (USD/Kg) | R25: Amount (USD) | T25: inch | U25: g/m2 | V25: MTK | W25: yds | X25: m | Y25: lbs | Z25: Giá sợi USD/Kg | AA25: GIÁ MỘC usd/kg | AB25: GIÁ DỆT+NHUỘM usd/kg | AC25: GIÁ TRUCKING usd/kg | AD25: giá fob usd/kg
A26: 1 | B26: FG-40S-95C/5S-26 | C26: RD1057305 | D26: KZ260600036 | E26: 40S/1COTTON +20D SPANDEX JERSEY(95%BCI COTTON 5%SPANDEX),WIDTH: 62"/64", WEIGHT: 155 G/M2 | F26: Calla Lily | G26: 24 | H26: 544.9 | I26: 552.1 | J26: 2441.7 | K26: 2232.69 | L26: 1201.31 | M26: 1217.15 | N26: =ROUND(0.54+0.025+0.167+0.03,2) -> 0.76 | O26: =+ROUND(N26*2.2046,2) -> 1.68 | P26: =+ROUND(O26*H26,2) -> 915.43 | Q26: 5.54 | R26: =+Q26*H26 -> 3018.746 | T26: 64 | U26: 155 | V26: =+ROUND((J26*(T26*0.0254)),2) -> 3969.23 | W26: =ROUND((I26/(U26/1000))/(T26*0.0254),2)*1.09361 -> 2396.2636 | X26: =+(I26*1000)/((T26*0.0254)*U26) -> 2191.1513 | Y26: =+I26*2.20462 -> 1217.1707 | Z26: 3.45 | AA26: 0 | AB26: =+N26*2.2046 -> 1.675496 | AC26: =+$AC$22/$H$28 -> 0.27095777 | AD26: =+Z26+AA26+AB26+AC272 -> 5.125496
A27: 2 | B27: FG-40S-95C/5S-26 | C27: RD1057305 | D27: KZ260600036 | E27: 40S/1COTTON +20D SPANDEX JERSEY(95%BCI COTTON 5%SPANDEX),WIDTH: 62"/64", WEIGHT: 155 G/M2 | F27: Black Jack | G27: 20 | H27: 545.25 | I27: 551.25 | J27: 2421.85 | K27: 2214.58 | L27: 1202.09 | M27: 1215.29 | N27: =ROUND(0.92+0.025+0.167+0.03,2) -> 1.14 | O27: =+ROUND(N27*2.2046,2) -> 2.51 | P27: =+ROUND(O27*H27,2) -> 1368.58 | Q27: 6.38 | R27: =+Q27*H27 -> 3478.695 | T27: 64 | U27: 155 | V27: =+ROUND((J27*(T27*0.0254)),2) -> 3936.96 | W27: =ROUND((I27/(U27/1000))/(T27*0.0254),2)*1.09361 -> 2392.5781 | X27: =+(I27*1000)/((T27*0.0254)*U27) -> 2187.7778 | Y27: =+I27*2.20462 -> 1215.2968 | Z27: 3.45 | AA27: 0 | AB27: =+N27*2.2046 -> 2.513244 | AC27: =+$AC$22/$H$28 -> 0.27095777 | AD27: =+Z27+AA27+AB27+AC273 -> 5.963244
A28: TOTAL | G28: =SUM(G26:G27) -> 44 | H28: =SUM(H26:H27) -> 1090.15 | I28: =SUM(I26:I27) -> 1103.35 | J28: =SUM(J26:J27) -> 4863.55 | K28: =SUM(K26:K27) -> 4447.27 | L28: =SUM(L26:L27) -> 2403.4 | M28: =SUM(M26:M27) -> 2432.44 | P28: =SUM(P26:P27) -> 2284.01 | R28: =SUM(R26:R27) -> 6497.441 | T28: 64 | U28: 155 | V28: =+ROUND((J28*(T28*0.0254)),2) -> 7906.19 | W28: =ROUND((I28/(U28/1000))/(T28*0.0254),2)*1.09361 -> 4788.8416 | X28: =+(I28*1000)/((T28*0.0254)*U28) -> 4378.9291 | Y28: =+I28*2.20462 -> 2432.4675 | Z28: 0 | AA28: 0 | AB28: =+N28*2.2046 -> 0 | AC28: =+$AC$22/$H$28 -> 0.27095777 | AD28: =+Z28+AA28+AB28+AC278 -> 0
A30: TOTAL AMOUNT (CMP): | D30: =P28 -> 2284.01
A31: In words: | D31: Two thousand two hundred eighty-four and zero one cents
M33: KAM HING (VIETNAM) TEXTILE PRINTING AND DYEING COMPANY LIMITED

Sheet PKL-HQ
A1: KAM HING (VIETNAM) TEXTILE PRINTING AND DYEING COMPANY LIMITED
A2: NHON TRACH 6A SUBDIVISION, NHON TRACH 6 INDUSTRIAL PARK,PHUOC AN COMMUNE, DONG NAI PROVINCE, VIET NAM
A3: PACKING LIST
A4: BUYER/FOR ACCOUNT | D4: ='[1]INV HQ'!E4 -> KAM HING PIECE WORKS LTD | I4: No.: | K4: ='INV-HQ'!L4 -> KHV-MNA150726-01
A5: OF APPLICANT: | D5: ='[1]INV HQ'!E5 -> UNIT A, 23/F., TML TOWER, 3 HOI SHING ROAD, | I5: Date: | K5: ='INV-HQ'!L5 -> 15/07/2026
D6: ='[1]INV HQ'!E6 -> TSUEN WAN, N.T., HONG KONG | I6: VENDOR NAME : | K6: ='INV-HQ'!L6 -> MAXHILL MANAGEMENT SERVICES PTE LTD.
A7: CONSIGNEE/ NOTIFY PARTY: | D7: ='INV-HQ'!D7 -> PT Nirwana Alabare Garment | I7: VENDOR P.O. NO. : | K7: ='INV-HQ'!L7 -> 265K0104-LOT A-CHASE-DF00252
D8: ='INV-HQ'!D8 -> Jl. Raya Rancaekek - Majalaya No.289,Desa Solokan Jeruk , | I8: STYLE NO.: | K8: ='INV-HQ'!L8 -> S#692926 HOL26
D9: ='INV-HQ'!D9 -> Kecamatan Solokan Jeruk,Kabupaten Bandung Jawa Barat 40382,Indonesia | I9: P.O. NO. : | K9: ='INV-HQ'!L9 -> KZ260600036
D10: ='INV-HQ'!D10 -> Tel: +62 285962076 ID : 74.540.692.6-444.000 | I10: CONTRACT NO. : | K10: ='INV-HQ'!L10 -> 01KHV-KFPW/2025
A11: Means of transport: | D11: ='INV-HQ'!D11 -> BY VESSEL | I11: Booking No. | K11: ='INV-HQ'!L11 -> SITSGJT0709G189957
A12: Port of Loading: | D12: ='INV-HQ'!D12 -> HO CHI MINH CITY, VIETNAM | I12: Container No.: | K12: ='INV-HQ'!L12 -> SITU2469545
A13: Port of Discharge: | D13: ='INV-HQ'!D13 -> JAKARTA, INDONESIA | I13: Seal No.: | K13: ='INV-HQ'!L13 -> SITB016385
A14: Partial Shipment: | D14: ='INV-HQ'!D14 -> Allowed | I14: ETD DATE: | K14: ='INV-HQ'!L14 -> 46224
A15: Transhipment: | D15: ='INV-HQ'!D15 -> Allowed | I15: ETA DATE: | K15: ='INV-HQ'!L15 -> 46227
A16: Terms of Payment: | D16: ='INV-HQ'!D16 -> T/T 30 days | I16: Payment information:
A17: Trade Terms: | D17: ='INV-HQ'!D17 -> FOB, HO CHI MINH CITY PORT, VIETNAM | I17: Account name: | J17: ='[1]INV HQ'!K19 -> KAM HING (VIETNAM) TEXTILE PRINTING AND DYEING COMPANY LIMITED
I18: Account number: 1106 2809 8368( USD)
I19: Bank name : | J19: ='[1]INV HQ'!K21 -> Vietnam Joint Stock Commercial Bank For Industry and Trade - Branch No.6
J20: ='[1]INV HQ'!K22 -> Ho Chi Minh City
I21: Bank address: | J21: ='[1]INV HQ'!K23 -> 1A - 1B - 2 Floor, A part of 11 Floor, 635B Building, Nguyen Trai Street, Cho Lon Ward,
J22: ='[1]INV HQ'!K24 -> Ho Chi Minh City, Vietnam
I23: Swift code: | J23: ='[1]INV HQ'!K25 -> ICBVVNVX922
A24: No. | B24: RD No. | C24: PO No. | D24: Description of goods | E24: Color and Reference No. | F24: Batch No. | G24: Rolls | H24: Quantity NW (Kg) | I24: Quantity GW (Kg) | J24: Quantity Length (Yds) | K24: Quantity Length (MTR) | L24: Quantity NW (Lbs) | M24: Quantity GW (Lbs) | N24: CONT/SEAL NO
A25: 1 | B25: RD1057305 | C25: KZ260600036 | D25: 40S/1COTTON +20D SPANDEX JERSEY(95%BCI COTTON 5%SPANDEX),WIDTH: 62"/64", WEIGHT: 155 G/M2 | E25: Calla Lily | F25: V26002660 | G25: 24 | H25: 544.9 | I25: 552.1 | J25: 2441.7 | K25: 2232.69 | L25: 1201.31 | M25: 1217.15 | N25: SITU2469545/SITB016385
A26: 2 | E26: Black Jack | F26: V26002765 | G26: 20 | H26: 545.25 | I26: 551.25 | J26: 2421.85 | K26: 2214.58 | L26: 1202.09 | M26: 1215.29
A27: TOTAL | G27: =SUM(G25:G26) -> 44 | H27: =SUM(H25:H26) -> 1090.15 | I27: =SUM(I25:I26) -> 1103.35 | J27: =SUM(J25:J26) -> 4863.55 | K27: =SUM(K25:K26) -> 4447.27 | L27: =SUM(L25:L26) -> 2403.4 | M27: =SUM(M25:M26) -> 2432.44
A29: TOTAL: | C29: =G27 -> 44 | D29: ROLLS / | E29: =J27 -> 4863.55 | F29: YDS/ | G29: 3.82 | H29: CBM
A30: NW: | C30: =H27 -> 1090.15 | D30: KGS / | E30: =L27 -> 2403.4 | F30: LBS
A31: GW: | C31: =I27 -> 1103.35 | D31: KGS / | E31: =M27 -> 2432.44 | F31: LBS
C32: =K27 -> 4447.27 | D32: MTR
K33: KAM HING (VIETNAM) TEXTILE PRINTING AND DYEING COMPANY LIMITED

Sheet SUM PKL KZ260600036
A1: KAM HING (VIETNAM) TEXTILE PRINTING AND DYEING COMPANY LIMITED
A2: NHON TRACH 6A SUBDIVISION, NHON TRACH 6 INDUSTRIAL PARK,
A3: PHUOC AN COMMUNE, DONG NAI PROVINCE, VIET NAM
A4: SUMMARY PACKING LIST
A5: BUYER/FOR ACCOUNT: | E5: KAM HING PIECE WORKS LTD | W5: No.: | Z5: BG260700056
A6: OF APPLICANT: | E6: UNIT A, 23/F., TML TOWER, 3 HOI SHING ROAD,TSUEN WAN, N.T., HONG KONG | W6: DATE : | Z6: 2026-07-14
B7: Order Type. : | Q7: FastResponse Code:
B8: CONTRACT NO. : | R8: VENDOR NAME : | W8: MAXHILL MANAGEMENT SERVICES PTE LTD.
C9: P.O. NO. : | E9: KZ260600036 | G9: STYLE NO.: | K9: S#692926 HOL26
A10: CONSIGNEE/ NOTIFY PARTY: | E10: PT Nirwana Alabare Garment Jl. Raya Rancaekek - Majalaya No.289,Desa Solokan Jeruk ,Kecamatan Solokan Jeruk,Kabupaten Bandung Jawa Barat 40382,IndonesiaTel: +62 285962076 ID : 74.540.692.6-444.000
A12: No. | B12: RD No. | D12: PO No. | E12: Description of goods | I12: Color | M12: Batch No. | O12: Rolls | P12: Quantity NW (Kg) | S12: Quantity GW (Kg) | U12: Quantity Length (Yds) | X12: Quantity Length (MTR) | Z12: Quantity NW (Lbs) | AB12: Quantity GW (Lbs) | AD12: CONT/SEAL NO
A13: 1 | B13: RD1057305 | D13: KZ260600036 | E13: 40S/1COTTON +20D SPANDEX JERSEY(95%BCI COTTON 5%SPANDEX) RD1057305 | I13: Calla Lily 漂白 | M13: V26002660 | O13: 24 | P13: 544.9 | S13: 552.1 | U13: 2441.7 | X13: 2232.69 | Z13: 1201.31 | AB13: 1217.15 | AD13: SITU2469545/SITB016385 | AE13: RD1057305 | AF13: KZ260600036 | AG13: Calla Lily | AH13: V26002660 | AI13: 24 | AJ13: 544.9 | AK13: 552.1 | AL13: 2441.7 | AM13: 2232.69 | AN13: 1201.31 | AO13: 1217.15 | AP13: =0.54+0.025+0.167+0.03 -> 0.762
A14: 2 | I14: Black Jack 克色(成人) | M14: V26002765 | O14: 20 | P14: 545.25 | S14: 551.25 | U14: 2421.85 | X14: 2214.58 | Z14: 1202.09 | AB14: 1215.29 | AE14: RD1057305 | AF14: KZ260600036 | AG14: Black Jack | AH14: V26002765 | AI14: 20 | AJ14: 545.25 | AK14: 551.25 | AL14: 2421.85 | AM14: 2214.58 | AN14: 1202.09 | AO14: 1215.29 | AP14: =0.92+0.025+0.167+0.03 -> 1.142
H15: TOTAL | M15: 44 | N15: 1090.15 | P15: 1103.35 | T15: 4863.55 | V15: 4447.27 | Y15: 2403.4 | AA15: 2432.44
A16: TOTAL: | D16: 44 | E16: ROLLS | G16: 4,447.00 | K16: MTR
A17: NW | D17: 1,090.15 | E17: KGS | G17: 2,403.40 | K17: LBS
A18: GW | D18: 1,103.35 | E18: KGS | G18: 4,863.55 | K18: YDS

Sheet DETAIL PKL KZ260600036
A1: KAM HING (VIETNAM) TEXTILE PRINTING AND DYEING COMPANY LIMITED
A2: NHON TRACH 6A SUBDIVISION, NHON TRACH 6 INDUSTRIAL PARK,
A3: PHUOC AN COMMUNE, DONG NAI PROVINCE, VIET NAM
A5: DETAIL PACKING LIST
A6: BUYER/FOR ACCOUNT: | G6: KAM HING PIECE WORKS LTD | AC6: No.: | AF6: BG260700056
A7: OF APPLICANT: | G7: UNIT A, 23/F., TML TOWER, 3 HOI SHING ROAD,TSUEN WAN, N.T., HONG KONG | AF7: 2026-07-14
B10: CONTRACT NO. : | W10: VENDOR NAME : | AC10: MAXHILL MANAGEMENT SERVICES PTE LTD.
C11: P.O. NO. : | G11: KZ260600036 | J11: STYLE NO.: | N11: S#692926 HOL26 | W11: VENDOR P.O. NO. : | AC11: 265K0104-LOT A-CHASE-DF00252
A13: CONSIGNEE/ NOTIFY PARTY: | G13: PT Nirwana Alabare Garment Jl. Raya Rancaekek - Majalaya No.289,Desa Solokan Jeruk ,Kecamatan Solokan Jeruk,Kabupaten Bandung Jawa Barat 40382,IndonesiaTel: +62 285962076 ID : 74.540.692.6-444.000
A16: RD No. | C16: PO No. | F16: Description of goods | L16: Color | O16: Batch No. | S16: Rolls | U16: Quantity NW (Kg) | W16: Quantity GW (Kg) | Z16: Quantity Length (Yds) | AC16: Quantity Length (MTR) | AF16: Quantity NW (Lbs) | AG16: Quantity GW (Lbs)
B18: 40S/1COTTON +20D SPANDEX JERSEY(95%BCI COTTON 5%SPANDEX) RD1057305
B19: Edge to edge width: | G19: 64"(+1/-0) | O19: GSM Before Wash: | W19: 155g/m2(+3%/-5%)
B20: Cuttable width: | G20: 62"(+1/-0) | O20: GSM After Wash: | W20: NWg/m2(+3%/-5%)
B21: Fabric Shrinkage: | G21: W:-6%/+0%,L:-6%/+0%,N:within 5%,Slant:within 15%
A22: RD1057305 | C22: KZ260600036 | F22: 40S/1COTTON +20D SPANDEX JERSEY(95%BCI COTTON 5%SPANDEX) RD1057305 | L22: Calla Lily 漂白 | O22: V26002660 | S22: 1 | U22: 26.35 | X22: 26.65 | Z22: 118.07 | AC22: 107.96 | AF22: 58.09 | AG22: 58.75
S23: 2 | U23: 20.85 | X23: 21.15 | Z23: 93.43 | AC23: 85.43 | AF23: 45.97 | AG23: 46.63
S24: 3 | U24: 24.35 | X24: 24.65 | Z24: 109.11 | AC24: 99.77 | AF24: 53.68 | AG24: 54.34
S25: 4 | U25: 23.8 | X25: 24.1 | Z25: 106.65 | AC25: 97.52 | AF25: 52.47 | AG25: 53.13
S26: 5 | U26: 24 | X26: 24.3 | Z26: 107.54 | AC26: 98.33 | AF26: 52.91 | AG26: 53.57
S27: 6 | U27: 24.25 | X27: 24.55 | Z27: 108.66 | AC27: 99.36 | AF27: 53.46 | AG27: 54.12
S28: 7 | U28: 23.8 | X28: 24.1 | Z28: 106.65 | AC28: 97.52 | AF28: 52.47 | AG28: 53.13
S29: 8 | U29: 24.35 | X29: 24.65 | Z29: 109.11 | AC29: 99.77 | AF29: 53.68 | AG29: 54.34
S30: 9 | U30: 25.05 | X30: 25.35 | Z30: 112.26 | AC30: 102.65 | AF30: 55.23 | AG30: 55.89
S31: 10 | U31: 23.55 | X31: 23.85 | Z31: 105.53 | AC31: 96.5 | AF31: 51.92 | AG31: 52.58
S32: 11 | U32: 24.1 | X32: 24.4 | Z32: 107.99 | AC32: 98.75 | AF32: 53.13 | AG32: 53.79
S33: 12 | U33: 24.55 | X33: 24.85 | Z33: 110 | AC33: 100.58 | AF33: 54.12 | AG33: 54.78
S34: 13 | U34: 23.35 | X34: 23.65 | Z34: 104.63 | AC34: 95.67 | AF34: 51.48 | AG34: 52.14
... S45: 24 | U45: 14.95 | X45: 15.25 | Z45: 67.03 | AC45: 61.29 | AF45: 32.98 | AG45: 33.64
L46: 小計: | Q46: 24 | T46: 544.9 | V46: 552.1 | Z46: 2441.7 | AB46: 2232.69 | AE46: 1201.31 | AG46: 1217.15
A47: RD1057305 | C47: KZ260600036 | F47: 40S/1COTTON +20D SPANDEX JERSEY(95%BCI COTTON 5%SPANDEX) RD1057305 | L47: Black Jack 克色(成人) | O47: V26002765 | S47: 2 | U47: 27.2 | X47: 27.5 | Z47: 120.82 | AC47: 110.48 | AF47: 59.97 | AG47: 60.63
A48: RD No. | C48: PO No. | F48: Description of goods | L48: Color | O48: Batch No. | S48: Rolls | U48: Quantity NW (Kg) | W48: Quantity GW (Kg) | Z48: Quantity Length (Yds) | AC48: Quantity Length (MTR) | AF48: Quantity NW (Lbs) | AG48: Quantity GW (Lbs)
A49: RD1057305 | C49: KZ260600036 | F49: 40S/1COTTON +20D SPANDEX JERSEY(95%BCI COTTON 5%SPANDEX) RD1057305 | L49: Black Jack 克色(成人) | O49: V26002765 | S49: 3 | U49: 28.05 | X49: 28.35 | Z49: 124.59 | AC49: 113.93 | AF49: 61.84 | AG49: 62.5
S50: 4 | U50: 28.15 | X50: 28.45 | Z50: 125.03 | AC50: 114.33 | AF50: 62.06 | AG50: 62.72
S51: 5 | U51: 27.7 | X51: 28 | Z51: 123.04 | AC51: 112.51 | AF51: 61.07 | AG51: 61.73
S52: 6 | U52: 26.4 | X52: 26.7 | Z52: 117.25 | AC52: 107.21 | AF52: 58.2 | AG52: 58.86
S53: 8 | U53: 27.75 | X53: 28.05 | Z53: 123.26 | AC53: 112.71 | AF53: 61.18 | AG53: 61.84
S54: 9 | U54: 27.55 | X54: 27.85 | Z54: 122.37 | AC54: 111.9 | AF54: 60.74 | AG54: 61.4
S55: 10 | U55: 26.75 | X55: 27.05 | Z55: 118.81 | AC55: 108.64 | AF55: 58.97 | AG55: 59.63
S56: 11 | U56: 27.45 | X56: 27.75 | Z56: 121.93 | AC56: 111.49 | AF56: 60.52 | AG56: 61.18
S57: 12 | U57: 26.25 | X57: 26.55 | Z57: 116.59 | AC57: 106.61 | AF57: 57.87 | AG57: 58.53
...
