Workbook
Name \z: '[1]COAT&WRAP-QIOT-#3'!#REF!
Name ________________________________________________________cao1: #REF!
Name ________________________________________________________cao1: #REF!
Name ________________________________________________________cao2: #REF!
Name ________________________________________________________cao2: #REF!
Name ________________________________________________________cao3: #REF!
Name ________________________________________________________cao3: #REF!
Name ________________________________________________________cao4: #REF!
Name ________________________________________________________cao4: #REF!
Name ________________________________________________________cao5: #REF!
Name ________________________________________________________cao5: #REF!
Name ________________________________________________________cao6: #REF!
Name ________________________________________________________cao6: #REF!
Name ________________________________________________________dai1: #REF!
Name ________________________________________________________dai1: #REF!
Name ________________________________________________________dai2: #REF!
Name ________________________________________________________dai2: #REF!
Name ________________________________________________________dai3: #REF!
Name ________________________________________________________dai3: #REF!
Name ________________________________________________________dai4: #REF!
Name ________________________________________________________dai4: #REF!
Name ________________________________________________________dai5: #REF!
Name ________________________________________________________dai5: #REF!
Name ________________________________________________________dai6: #REF!
Name ________________________________________________________dai6: #REF!
Name ________________________________________________________dan1: #REF!
Name ________________________________________________________dan1: #REF!
Name ________________________________________________________dan2: #REF!
Name ________________________________________________________dan2: #REF!
Name ________________________________________________________phi10: #REF!
Name ________________________________________________________phi10: #REF!
Name ________________________________________________________phi12: #REF!
Name ________________________________________________________phi12: #REF!
Name ________________________________________________________phi14: #REF!
Name ________________________________________________________phi14: #REF!
Name ________________________________________________________phi16: #REF!
Name ________________________________________________________phi16: #REF!
Name ________________________________________________________phi18: #REF!
Name ________________________________________________________phi18: #REF!
Name ________________________________________________________phi20: #REF!
Name ________________________________________________________phi20: #REF!
Name ________________________________________________________phi22: #REF!
Name ________________________________________________________phi22: #REF!
Name ________________________________________________________phi25: #REF!
Name ________________________________________________________phi25: #REF!
Name ________________________________________________________phi28: #REF!
Name ________________________________________________________phi28: #REF!
Name ________________________________________________________phi6: #REF!
Name ________________________________________________________phi6: #REF!
Name ________________________________________________________phi8: #REF!
Name ________________________________________________________phi8: #REF!
Name ________________________________________________________slg1: #REF!
Name ________________________________________________________slg1: #REF!
Name ________________________________________________________slg2: #REF!
Name ________________________________________________________slg2: #REF!
Name ________________________________________________________slg3: #REF!
Name ________________________________________________________slg3: #REF!
Name ________________________________________________________slg4: #REF!
Name ________________________________________________________slg4: #REF!
Name ________________________________________________________slg5: #REF!

Sheet GDI-CI
B1: COMMERCIAL INVOICE
B3: 1.Shipper/Exporter | H3: 9. No & Date of Invoice
B4: GDI TEXTILE CO ., LTD | H4: GDI/SIGD-260241 | N4: Date: 2026/09/22 | O4: 45194
B5: LOT C1, C2, C3, C5, C6 C7-2 ROAD N6 TMTC INDUSTRIAL
B6: PARK, MOC BAI BORDER GATE ECONOMIC ZONE, | H6: 10. No. & Date of L/C
B7: THUAN DONG HAMLET, BEN CAU COMMUNE, TAY NINH PROVINCE, VIETNAM
B8: 2.For account & risk of Messers | H8: 11. L/C issuing bank
B9: GDI HK LIMITED
B10: (Old Company Name: SIGD LIMITED)
B11: FLAT H, 2/F MANSION INDUSTRIAL BUILDING,
B12: 8 A KUNG NGAM VILLAGE LANE, SHAU KEI WAN, HONG KONG | H12: Remarks
H13: TT PAYMENT
B14: 3.Notify Party/Ship to | H14: CIF
B15: PT Nirwana Alabare Garment | H15: SO#
B16: Jl. Raya Rancaekek - Majalaya No.289 Desa Solokan Jeruk ,Kecamatan Solokan Jeruk,
B17: Kabupaten Bandung Jawa Barat 40382,Indonesia
B18: Tel: +62 285962076
B21: 4.Consinee For Buyer:
B26: 5.Port of loading | G26: 6.Final destination | J26: No.: SC/GDI-SIGD260241
B27: Hochiminh | G27: Indonesia,Jakarta | J27: =N4 -> Date: 2026/09/22
B28: 7.Container No# | D28: 8.Vessel | G28: 9.Sailing on or about
B30: 12.Marks and number of Pkgs. | D30: 13.Useages | F30: 14.Customer PO# | G30: 15.Description of Goods. | J30: 16. Quantity | N30: 17. Unit price (USD/LBS) | O30: 18. Amount (USD)
J31: NET WEIGHT KGS | K31: YDS | L31: LBS | M31: MTS
B32: N/M
B33: ROLLS
B35: =SUM('GDI-Total'!G14:G17) -> 56 | D35: Body | E35: Roll | F35: GDI260819008 PO#KD00465 Ref#265K0127(1ST MB), S/769950 | G35: ='GDI-Total'!E14 -> 26S/1 60% BCI COTTON 40%POLYESTER JERSEY (LACOSTE EDGE) 70/72“ 160GSM | I35: ='GDI-Total'!F14 -> CALLA LILY DD 451 漂白 | J35: =SUM('GDI-Total'!H14:H17) -> 1225.6 | K35: =SUM('GDI-Total'!I14:I17) -> 4580.6 | L35: =SUM('GDI-Total'!J14:J17) -> 2701.9 | M35: =K35*0.9144 -> 4188.5006 | N35: 1.99 | O35: =ROUND(L35*N35,2) -> 5376.78
B36: =SUM('GDI-Total'!G18:G20) -> 93 | D36: Body | E36: Roll | F36: GDI260819010 PO#KD00468 Ref#265K0125-A~D(1ST MB), S/416363 | G36: ='GDI-Total'!E18 -> 60% BETTER COTTON (BCI) 40% POLYESTER CONVENTIONAL CVC 26S/1 JERSEY(LACOSTE EDGE) 70/72“ 160GSM | I36: ='GDI-Total'!F18 -> CALLA LILY DD 451 漂白 | J36: =SUM('GDI-Total'!H18:H20) -> 2053.1 | K36: =SUM('GDI-Total'!I18:I20) -> 7673.7 | L36: =SUM('GDI-Total'!J18:J20) -> 4526.14 | M36: =K36*0.9144 -> 7016.8313 | N36: 1.99 | O36: =ROUND(L36*N36,2) -> 9007.02
B37: ='GDI-Total'!G21 -> 30 | D37: Body | E37: Roll | F37: GDI260819010 PO#KD00468 Ref#265K0125-A~D(1ST MB), S/416363 | G37: ='GDI-Total'!E21 -> 60% BETTER COTTON (BCI) 40% POLYESTER CONVENTIONAL CVC 30S/1 JERSEY(LACOSTE EDGE) 69/71" 145GSM | I37: ='GDI-Total'!F21 -> BLACK JACK DD 400 黑色 | J37: ='GDI-Total'!H21 -> 670.1 | K37: ='GDI-Total'!I21 -> 2802.2 | L37: ='GDI-Total'!J21 -> 1477.22 | M37: =K37*0.9144 -> 2562.3317 | N37: 1.99 | O37: =ROUND(L37*N37,2) -> 2939.67
B38: =SUM('GDI-Total'!G22:G23) -> 56 | D38: Body | E38: Roll | F38: GDI260819010 PO#KD00468 Ref#265K0125-A~D(1ST MB), S/416363 | G38: ='GDI-Total'!E22 -> 60% BETTER COTTON (BCI) 40% POLYESTER CONVENTIONAL CVC 30S/1 JERSEY(LACOSTE EDGE) 69/71" 145GSM | I38: ='GDI-Total'!F22 -> B25 FAUX HEATHER GREY (B25 PSD) B25单染涤 | J38: =SUM('GDI-Total'!H22:H23) -> 1234.2 | K38: =SUM('GDI-Total'!I22:I23) -> 5161.8 | L38: =SUM('GDI-Total'!J22:J23) -> 2720.83 | M38: =K38*0.9144 -> 4719.9499 | N38: 1.99 | O38: =ROUND(L38*N38,2) -> 5414.45
B39: ='GDI-Total'!G24 -> 39 | D39: Body | E39: Roll | F39: GDI260819010 PO#KD00468 Ref#265K0125-A~D(1ST MB), S/416363 | G39: ='GDI-Total'!E23 -> 60% BETTER COTTON (BCI) 40% POLYESTER CONVENTIONAL CVC 30S/1 JERSEY(LACOSTE EDGE) 69/71" 145GSM | I39: ='GDI-Total'!F24 -> MONET BLUE DD 744 油画蓝 | J39: ='GDI-Total'!H24 -> 860.3 | K39: ='GDI-Total'!I24 -> 3597.8 | L39: ='GDI-Total'!J24 -> 1896.59 | M39: =K39*0.9144 -> 3289.8283 | N39: 1.99 | O39: =ROUND(L39*N39,2) -> 3774.21
B40: ='GDI-Total'!G25 -> 40 | D40: Body | E40: Roll | F40: GDI260819010 PO#KD00468 Ref#265K0125-A~D(1ST MB), S/416363 | G40: ='GDI-Total'!E24 -> 60% BETTER COTTON (BCI) 40% POLYESTER CONVENTIONAL CVC 30S/1 JERSEY(LACOSTE EDGE) 69/71" 145GSM | I40: ='GDI-Total'!F25 -> PLANT LIFE DD 978 翡翠绿 | J40: ='GDI-Total'!H25 -> 880.3 | K40: ='GDI-Total'!I25 -> 3681.8 | L40: ='GDI-Total'!J25 -> 1940.63 | M40: =K40*0.9144 -> 3366.6379 | N40: 1.99 | O40: =ROUND(L40*N40,2) -> 3861.85
B41: ='GDI-Total'!G26 -> 29 | D41: Body | E41: Roll | F41: GDI260819010 PO#KD00468 Ref#265K0125-A~D(1ST MB), S/416363 | G41: ='GDI-Total'!E25 -> 60% BETTER COTTON (BCI) 40% POLYESTER CONVENTIONAL CVC 30S/1 JERSEY(LACOSTE EDGE) 69/71" 145GSM | I41: ='GDI-Total'!F26 -> WINE STAIN DD 853 酒红 | J41: ='GDI-Total'!H26 -> 631.9 | K41: ='GDI-Total'!I26 -> 2642.9 | L41: ='GDI-Total'!J26 -> 1393.07 | M41: =K41*0.9144 -> 2416.6678 | N41: 1.99 | O41: =ROUND(L41*N41,2) -> 2772.21
B42: =SUM('GDI-Total'!G27:G29) -> 41 | D42: Body | E42: Bale | F42: GDI260810010 PO#KD00452 Ref#265K0107-b , S/905994 | G42: ='GDI-Total'!E27 -> 60% BCI COTTON 40% RECYCLED POLYESTER 32S/1 JERSEY 69/71" 125GSM | I42: ='GDI-Total'!F27 -> CLOUD COVER PSD 中灰色-单染涤 | J42: =SUM('GDI-Total'!H27:H29) -> 897.4 | K42: =SUM('GDI-Total'!I27:I29) -> 4353 | L42: =SUM('GDI-Total'!J27:J29) -> 1978.37 | M42: =K42*0.9144 -> 3980.3832 | N42: 2.12 | O42: =ROUND(L42*N42,2) -> 4194.14
B43: =SUM('GDI-Total'!G30:G31) -> 47 | D43: Body | E43: Bale | F43: GDI260904001 PO#KD00475 Ref#265K0093-Ba, S/878746 | G43: ='GDI-Total'!E30 -> 60% BCI COTTON 40% RECYCLED POLYESTER 32S/1 JERSEY 69/71“ 125GSM | I43: ='GDI-Total'!F30 -> BLACK JACK 400 黑色 | J43: =SUM('GDI-Total'!H30:H31) -> 1021.8 | K43: =SUM('GDI-Total'!I30:I31) -> 4957.1 | L43: =SUM('GDI-Total'!J30:J31) -> 2252.64 | M43: =K43*0.9144 -> 4532.7722 | N43: 2.12 | O43: =ROUND(L43*N43,2) -> 4775.6
B44: =SUM('GDI-Total'!G32:G32) -> 7 | D44: Body | E44: Bale | F44: GDI260904002 PO#KD00474 Ref#265K0092 -Ba, S/867788 | G44: ='GDI-Total'!E34 -> 60% BCI COTTON 40% RECYCLED POLYESTER 32S/1 JERSEY 69/71“ 125GSM | I44: ='GDI-Total'!F31 -> BLACK JACK 400 黑色 | J44: =SUM('GDI-Total'!H32:H32) -> 155.7 | K44: =SUM('GDI-Total'!I32:I32) -> 755.3 | L44: =SUM('GDI-Total'!J32:J32) -> 343.26 | M44: =K44*0.9144 -> 690.64632 | N44: 2.12 | O44: =ROUND(L44*N44,2) -> 727.71
B45: =SUM('GDI-Total'!G33:G35) -> 21 | D45: Body | E45: Bale | F45: GDI260904002 PO#KD00474 Ref#265K0092 -Ba, S/867788 | G45: ='GDI-Total'!E33 -> 60% BCI COTTON 40% RECYCLED POLYESTER 32S/1 JERSEY 69/71“ 125GSM | I45: ='GDI-Total'!F35 -> BLUSH HUE 257 粉红色 | J45: =SUM('GDI-Total'!H33:H35) -> 452.2 | K45: =SUM('GDI-Total'!I33:I35) -> 2193.7 | L45: =SUM('GDI-Total'!J33:J35) -> 996.92 | M45: =K45*0.9144 -> 2005.9193 | N45: 2.12 | O45: =ROUND(L45*N45,2) -> 2113.47
B46: =SUM('GDI-Total'!G36:G37) -> 26 | D46: Body | E46: Bale | F46: GDI260904002 PO#KD00474 Ref#265K0092 -Ba, S/867788 | G46: ='GDI-Total'!E37 -> 60% BCI COTTON 40% POLYESTER 32S/1 JERSEY(LACOSTE EDGE) 62/64" 145GSM | I46: ='GDI-Total'!F37 -> CALLA LILY 451 漂白 | J46: =SUM('GDI-Total'!H36:H37) -> 563.3 | K46: =SUM('GDI-Total'!I36:I37) -> 2613.3 | L46: =SUM('GDI-Total'!J36:J37) -> 1241.81 | M46: =K46*0.9144 -> 2389.6015 | N46: 2.12 | O46: =ROUND(L46*N46,2) -> 2632.64
B47: ='GDI-Total'!G38 -> 4 | D47: Body | E47: Roll | F47: SIOB260507007 PO#KD00433 Ref#265K0077-2ND MB S/767468 | G47: ='GDI-Total'!E38 -> 60% BCI COTTON 40%POLYESTER 26S/1 JERSEY (LACOSTE EDGE) 70/72" 160GSM | I47: ='GDI-Total'!F38 -> BLACK JACK 400 黑色 | J47: ='GDI-Total'!H38 -> 68.1 | K47: ='GDI-Total'!I38 -> 254.5 | L47: ='GDI-Total'!J38 -> 150.14 | M47: =K47*0.9144 -> 232.7148 | N47: 1.99 | O47: =ROUND(L47*N47,2) -> 298.78
B49: =SUM(B35:C47) -> 489 | G49: TOTAL | J49: =SUM(J35:J48) -> 10714 | K49: =SUM(K35:K48) -> 45267.7 | L49: =SUM(L35:L48) -> 23619.52 | M49: =SUM(M35:M48) -> 41392.785 | O49: =SUM(O35:O48) -> 47888.53
R52: (Roll) | S52: (N.W) | T52: (YDS) | U52: (LBS) | V52: Amount
...

Sheet GDI-PI
A1: PACKING LIST
A3: 1.Shipper/Exporter | H3: 9. No & Date of Invoice
A4: =[24]CI!B4 -> GDI TEXTILE CO ., LTD | H4: ='GDI-CI'!H4 -> GDI/SIGD-260241 | N4: ='GDI-CI'!N4 -> Date: 2026/09/22
A5: ='GDI-CI'!B5 -> LOT C1, C2, C3, C5, C6 C7-2 ROAD N6 TMTC INDUSTRIAL
A6: ='GDI-CI'!B6 -> PARK, MOC BAI BORDER GATE ECONOMIC ZONE, | H6: 10. No. & Date of L/C
A7: ='GDI-CI'!B7 -> THUAN DONG HAMLET, BEN CAU COMMUNE, TAY NINH PROVINCE, VIETNAM
A8: =+'GDI-CI'!B8 -> 2.For account & risk of Messers | H8: 11. L/C issuing bank
A9: =+'GDI-CI'!B9 -> GDI HK LIMITED
A10: =+'GDI-CI'!B10 -> (Old Company Name: SIGD LIMITED)
A11: =+'GDI-CI'!B11 -> FLAT H, 2/F MANSION INDUSTRIAL BUILDING,
A12: =+'GDI-CI'!B12 -> 8 A KUNG NGAM VILLAGE LANE, SHAU KEI WAN, HONG KONG | H12: Remarks
A13: =+'GDI-CI'!B13 -> 0 | H13: =[24]CI!E12 -> TT PAYMENT
A14: =+'GDI-CI'!B14 -> 3.Notify Party/Ship to | H14: =+'GDI-CI'!H14 -> CIF
A15: ='GDI-CI'!B15 -> PT Nirwana Alabare Garment
A16: =+'GDI-CI'!B16 -> Jl. Raya Rancaekek - Majalaya No.289 Desa Solokan Jeruk ,Kecamatan Solokan Jeruk,
A17: =+'GDI-CI'!B17 -> Kabupaten Bandung Jawa Barat 40382,Indonesia
A18: =+'GDI-CI'!B18 -> Tel: +62 285962076
A19: =+'GDI-CI'!B19 -> 0
A20: 4. For account & risk of Messers
A21: =[24]CI!B19 -> 0
A22: =[24]CI!B20 -> 0
A23: =[24]CI!B21 -> 0
A25: 5.Port of loading | G25: 6.Final destination
A26: ='GDI-CI'!B27 -> Hochiminh | G26: ='GDI-CI'!G27 -> Indonesia,Jakarta
A27: ='GDI-CI'!B28 -> 7.Container No# | D27: ='GDI-CI'!D28 -> 8.Vessel | G27: ='GDI-CI'!G28 -> 9.Sailing on or about
A28: ='GDI-CI'!B29 -> 0 | D28: ='GDI-CI'!D29 -> 0 | G28: ='GDI-CI'!G29 -> 0
A29: 12.Marks and number of Pkgs. | D29: 13.Useages | F29: 14.Customer PO# | G29: 15.Description of Goods | J29: 16. Quantity
G30: =[24]CI!D28 -> 0 | J30: NET WEIGHT KGS | K30: YDS | L30: LBS | M30: MTS | N30: GROSS WEIGHT KGS
A31: N/M | G31: =[24]CI!D29 -> 0
A32: ROLLS | G32: =[24]CI!D30 -> 0
A33: =[24]CI!B32 -> 0 | G33: =[24]CI!D32 -> 0 | J33: =[24]CI!F32 -> 0 | K33: =[24]CI!G32 -> 0 | M33: =J33 -> 0
A34: =[24]CI!B33 -> 0 | G34: =[24]CI!D33 -> 0 | J34: =[24]CI!F33 -> 0 | K34: =[24]CI!G33 -> 0 | M34: =J34 -> 0
A35: ='GDI-CI'!B35 -> 56 | D35: ='GDI-CI'!D35 -> Body | E35: ='GDI-CI'!E35 -> Roll | F35: ='GDI-CI'!F35 -> GDI260819008 PO#KD00465 Ref#265K0127(1ST MB), S/769950 | G35: ='GDI-CI'!G35 -> 26S/1 60% BCI COTTON 40%POLYESTER JERSEY (LACOSTE EDGE) 70/72“ 160GSM | I35: ='GDI-CI'!I35 -> CALLA LILY DD 451 漂白 | J35: ='GDI-CI'!J35 -> 1225.6 | K35: ='GDI-CI'!K35 -> 4580.6 | L35: ='GDI-CI'!L35 -> 2701.9 | M35: ='GDI-CI'!M35 -> 4188.5006 | N35: =SUM('GDI-Total'!K14:K17) -> 1236.8
A36: ='GDI-CI'!B36 -> 93 | D36: ='GDI-CI'!D36 -> Body | E36: ='GDI-CI'!E36 -> Roll | F36: ='GDI-CI'!F36 -> GDI260819010 PO#KD00468 Ref#265K0125-A~D(1ST MB), S/416363 | G36: ='GDI-CI'!G36 -> 60% BETTER COTTON (BCI) 40% POLYESTER CONVENTIONAL CVC 26S/1 JERSEY(LACOSTE EDGE) 70/72“ 160GSM | I36: ='GDI-CI'!I36 -> CALLA LILY DD 451 漂白 | J36: ='GDI-CI'!J36 -> 2053.1 | K36: ='GDI-CI'!K36 -> 7673.7 | L36: ='GDI-CI'!L36 -> 4526.14 | M36: ='GDI-CI'!M36 -> 7016.8313 | N36: =SUM('GDI-Total'!K18:K20) -> 2071.7
A37: ='GDI-CI'!B37 -> 30 | D37: ='GDI-CI'!D37 -> Body | E37: ='GDI-CI'!E37 -> Roll | F37: ='GDI-CI'!F37 -> GDI260819010 PO#KD00468 Ref#265K0125-A~D(1ST MB), S/416363 | G37: ='GDI-CI'!G37 -> 60% BETTER COTTON (BCI) 40% POLYESTER CONVENTIONAL CVC 30S/1 JERSEY(LACOSTE EDGE) 69/71" 145GSM | I37: ='GDI-CI'!I37 -> BLACK JACK DD 400 黑色 | J37: ='GDI-CI'!J37 -> 670.1 | K37: ='GDI-CI'!K37 -> 2802.2 | L37: ='GDI-CI'!L37 -> 1477.22 | M37: ='GDI-CI'!M37 -> 2562.3317 | N37: ='GDI-Total'!K21 -> 676.1
A38: ='GDI-CI'!B38 -> 56 | D38: ='GDI-CI'!D38 -> Body | E38: ='GDI-CI'!E38 -> Roll | F38: ='GDI-CI'!F38 -> GDI260819010 PO#KD00468 Ref#265K0125-A~D(1ST MB), S/416363 | G38: ='GDI-CI'!G38 -> 60% BETTER COTTON (BCI) 40% POLYESTER CONVENTIONAL CVC 30S/1 JERSEY(LACOSTE EDGE) 69/71" 145GSM | I38: ='GDI-CI'!I38 -> B25 FAUX HEATHER GREY (B25 PSD) B25单染涤 | J38: ='GDI-CI'!J38 -> 1234.2 | K38: ='GDI-CI'!K38 -> 5161.8 | L38: ='GDI-CI'!L38 -> 2720.83 | M38: ='GDI-CI'!M38 -> 4719.9499 | N38: =SUM('GDI-Total'!K22:K23) -> 1245.4
A39: ='GDI-CI'!B39 -> 39 | D39: ='GDI-CI'!D39 -> Body | E39: ='GDI-CI'!E39 -> Roll | F39: ='GDI-CI'!F39 -> GDI260819010 PO#KD00468 Ref#265K0125-A~D(1ST MB), S/416363 | G39: ='GDI-CI'!G39 -> 60% BETTER COTTON (BCI) 40% POLYESTER CONVENTIONAL CVC 30S/1 JERSEY(LACOSTE EDGE) 69/71" 145GSM | I39: ='GDI-CI'!I39 -> MONET BLUE DD 744 油画蓝 | J39: ='GDI-CI'!J39 -> 860.3 | K39: ='GDI-CI'!K39 -> 3597.8 | L39: ='GDI-CI'!L39 -> 1896.59 | M39: ='GDI-CI'!M39 -> 3289.8283 | N39: ='GDI-Total'!K24 -> 868.1
A40: ='GDI-CI'!B40 -> 40 | D40: ='GDI-CI'!D40 -> Body | E40: ='GDI-CI'!E40 -> Roll | F40: ='GDI-CI'!F40 -> GDI260819010 PO#KD00468 Ref#265K0125-A~D(1ST MB), S/416363 | G40: ='GDI-CI'!G40 -> 60% BETTER COTTON (BCI) 40% POLYESTER CONVENTIONAL CVC 30S/1 JERSEY(LACOSTE EDGE) 69/71" 145GSM | I40: ='GDI-CI'!I40 -> PLANT LIFE DD 978 翡翠绿 | J40: ='GDI-CI'!J40 -> 880.3 | K40: ='GDI-CI'!K40 -> 3681.8 | L40: ='GDI-CI'!L40 -> 1940.63 | M40: ='GDI-CI'!M40 -> 3366.6379 | N40: ='GDI-Total'!K25 -> 888.3
A41: ='GDI-CI'!B41 -> 29 | D41: ='GDI-CI'!D41 -> Body | E41: ='GDI-CI'!E41 -> Roll | F41: ='GDI-CI'!F41 -> GDI260819010 PO#KD00468 Ref#265K0125-A~D(1ST MB), S/416363 | G41: ='GDI-CI'!G41 -> 60% BETTER COTTON (BCI) 40% POLYESTER CONVENTIONAL CVC 30S/1 JERSEY(LACOSTE EDGE) 69/71" 145GSM | I41: ='GDI-CI'!I41 -> WINE STAIN DD 853 酒红 | J41: ='GDI-CI'!J41 -> 631.9 | K41: ='GDI-CI'!K41 -> 2642.9 | L41: ='GDI-CI'!L41 -> 1393.07 | M41: ='GDI-CI'!M41 -> 2416.6678 | N41: ='GDI-Total'!K26 -> 637.7
A42: ='GDI-CI'!B42 -> 41 | D42: ='GDI-CI'!D42 -> Body | E42: ='GDI-CI'!E42 -> Bale | F42: ='GDI-CI'!F42 -> GDI260810010 PO#KD00452 Ref#265K0107-b , S/905994 | G42: ='GDI-CI'!G42 -> 60% BCI COTTON 40% RECYCLED POLYESTER 32S/1 JERSEY 69/71" 125GSM | I42: ='GDI-CI'!I42 -> CLOUD COVER PSD 中灰色-单染涤 | J42: ='GDI-CI'!J42 -> 897.4 | K42: ='GDI-CI'!K42 -> 4353 | L42: ='GDI-CI'!L42 -> 1978.37 | M42: ='GDI-CI'!M42 -> 3980.3832 | N42: =SUM('GDI-Total'!K27:K29) -> 905.6
...

Sheet GDI-SC
A2: SALES CONTRACT
A4: 1. Seller: | G4: ='GDI-CI'!J26 -> No.: SC/GDI-SIGD260241
A5: GDI TEXTILE CO., LTD | G5: ='GDI-CI'!J27 -> Date: 2026/09/22
A6: LOT C1, C2, C3, C5, C6 ROAD N6 TMTC INDUSTRIAL PARK, MOC BAI BORDER GATE ECONOMIC ZONE
A7: THUAN DONG HAMLET, LOI THUAN COMMUNE, BEN CAU DISTRICT, TAY NINH PROVINCE, VIETNAM
A9: 2. Buyer (For account & risk of Messers):
A10: ='GDI-CI'!B9 -> GDI HK LIMITED
A11: ='GDI-CI'!B11 -> FLAT H, 2/F MANSION INDUSTRIAL BUILDING,
A12: ='GDI-CI'!B12 -> 8 A KUNG NGAM VILLAGE LANE, SHAU KEI WAN, HONG KONG
A14: 3. Notify Party/Ship to:
A15: ='GDI-CI'!B15 -> PT Nirwana Alabare Garment
A22: Payment Term: 100% TT AFTER DELIVERY | E22: Shipment date:
E23: Shipment method : BY TRUCK
E24: Partial delivery: ALLOWED
E25: Term of price: EXW
A26: CPO | B26: Quality | E26: Quantity (KGS) | F26: Quantity (YDS) | G26: Price (USD/KGS) | H26: Amount (USD)
A27: ='GDI-CI'!#REF! -> #REF! | B27: ='GDI-CI'!#REF! -> #REF! | E27: ='GDI-CI'!#REF! -> #REF! | F27: ='GDI-CI'!#REF! -> #REF! | G27: ='GDI-CI'!#REF! -> #REF! | H27: ='GDI-CI'!#REF! -> #REF!
A28: ='GDI-CI'!#REF! -> #REF! | E28: ='GDI-CI'!#REF! -> #REF! | F28: ='GDI-CI'!#REF! -> #REF! | G28: ='GDI-CI'!#REF! -> #REF! | H28: ='GDI-CI'!#REF! -> #REF!
A29: ='GDI-CI'!#REF! -> #REF! | B29: ='GDI-CI'!#REF! -> #REF! | E29: ='GDI-CI'!#REF! -> #REF! | F29: ='GDI-CI'!#REF! -> #REF! | G29: ='GDI-CI'!#REF! -> #REF! | H29: ='GDI-CI'!#REF! -> #REF!
A30: ='GDI-CI'!#REF! -> #REF! | B30: ='GDI-CI'!#REF! -> #REF! | E30: ='GDI-CI'!#REF! -> #REF! | F30: ='GDI-CI'!#REF! -> #REF! | G30: ='GDI-CI'!#REF! -> #REF! | H30: ='GDI-CI'!#REF! -> #REF!
A31: ='GDI-CI'!#REF! -> #REF! | E31: ='GDI-CI'!#REF! -> #REF! | F31: ='GDI-CI'!#REF! -> #REF! | G31: ='GDI-CI'!#REF! -> #REF! | H31: ='GDI-CI'!#REF! -> #REF!
A32: ='GDI-CI'!#REF! -> #REF! | B32: ='GDI-CI'!#REF! -> #REF! | E32: ='GDI-CI'!#REF! -> #REF! | F32: ='GDI-CI'!#REF! -> #REF! | G32: ='GDI-CI'!#REF! -> #REF! | H32: ='GDI-CI'!#REF! -> #REF!
A33: ='GDI-CI'!#REF! -> #REF! | E33: ='GDI-CI'!#REF! -> #REF! | F33: ='GDI-CI'!#REF! -> #REF! | G33: ='GDI-CI'!#REF! -> #REF! | H33: ='GDI-CI'!#REF! -> #REF!
B35: TOTAL | E35: =SUM(E27:E34) -> #REF! | F35: =SUM(F27:F34) -> #REF! | H35: ='GDI-CI'!O49 -> 47888.53
A37: * DELIVERY QUANTITY TOLERANCE : +- 3%
A38: * WIDTH / WEIGHT TOLERANCE : +/- 5 %
A40: * NOTE: GDI TEXTILE MAKES NO WARRANTY, NOR SHOULD ANY BE IMPLIED, FOR THE FITNESS OR MERCHANTABILITY OF THESE
A41: FABRICS FOR GARMENT DYE OR GARMENT WASH PROCESS. ALL CLAIMS MUST BE MADE WITHIN THIRTY DAYS FROM RECEIPT OF
A42: MERCHANDISE. NO CLAIM(S) OR ALLOWANCES CAN BE MADE AFTER THE GOODS ARE CUT OR OTHERWISE PROCESSED. NO MERCHANDISE
A43: ACCEPTED FOR RETURN WITHOUT AUTHORIZATION.
A46: BANK INFORMATION
A47: ACCOUNT NAME: | B47: GDI TEXTILE CO.,LTD.
B48: LOT C1, C2, C3, C5, C6 ROAD N6 TMTC INDUSTRIAL PARK, MOC BAI BORDER GATE ECONOMIC ZONE
B49: THUAN DONG HAMLET, LOI THUAN COMMUNE, BEN CAU DISTRICT, TAY NINH PROVINCE, VIETNAM
A50: ACCOUNT NO: | B50: 112002866447 USD
A51: BANK NAME: | B51: VietNam Joint Stock Commercial Bank for Industry and Trade Ho Chi Minh City Branch.
A52: BANK ADDRESS: | B52: 79A Ham Nghi Street, Nguyen Thai Binh Ward, District 1, Ho Chi Minh City Viet Nam.
A53: SWIFT CODE: | B53: ICBVVNVX900
B55: GDI TEXTILE CO ., LTD | G55: LUENTECH TEXTILE SOLUTIONS CO., LTD.
D64: =+#REF! -> #REF!

Sheet SC
A2: SALES CONTRACT
A4: 1. Seller: | G4: ='GDI-CI'!J26 -> No.: SC/GDI-SIGD260241
A5: GDI TEXTILE CO., LTD | G5: ='GDI-CI'!J27 -> Date: 2026/09/22
A6: ='GDI-CI'!B5 -> LOT C1, C2, C3, C5, C6 C7-2 ROAD N6 TMTC INDUSTRIAL
A7: ='GDI-CI'!B6 -> PARK, MOC BAI BORDER GATE ECONOMIC ZONE,
A8: ='GDI-CI'!B7 -> THUAN DONG HAMLET, BEN CAU COMMUNE, TAY NINH PROVINCE, VIETNAM
A9: 2. Buyer (For account & risk of Messers):
A10: ='GDI-CI'!B9 -> GDI HK LIMITED
A11: ='GDI-CI'!B10 -> (Old Company Name: SIGD LIMITED)
A12: ='GDI-CI'!B11 -> FLAT H, 2/F MANSION INDUSTRIAL BUILDING,
A13: ='GDI-CI'!B12 -> 8 A KUNG NGAM VILLAGE LANE, SHAU KEI WAN, HONG KONG
A15: 3. Notify Party/Ship to:
A16: ='GDI-CI'!B15 -> PT Nirwana Alabare Garment
A17: ='GDI-CI'!B16 -> Jl. Raya Rancaekek - Majalaya No.289 Desa Solokan Jeruk ,Kecamatan Solokan Jeruk,
A18: ='GDI-CI'!B17 -> Kabupaten Bandung Jawa Barat 40382,Indonesia
A19: ='GDI-CI'!B18 -> Tel: +62 285962076
A23: Payment Term: 100% TT AFTER DELIVERY | C23: Shipment date:
C24: Shipment method : BY VESSEL
C25: Partial delivery: ALLOWED
C26: Term of price: EXW | D26: CIF
A27: CPO | B27: Quality | C27: Quantity (KGS) | D27: Quantity (YDS) | E27: Quantity (LBS) | F27: Quantity (MTS) | G27: Price (USD/LBS) | H27: Amount (USD)
A28: ='GDI-CI'!F35 -> GDI260819008 PO#KD00465 Ref#265K0127(1ST MB), S/769950 | B28: ='GDI-CI'!G35 -> 26S/1 60% BCI COTTON 40%POLYESTER JERSEY (LACOSTE EDGE) 70/72“ 160GSM | C28: ='GDI-CI'!J35 -> 1225.6 | D28: ='GDI-CI'!K35 -> 4580.6 | E28: ='GDI-CI'!L35 -> 2701.9 | F28: ='GDI-CI'!M35 -> 4188.5006 | G28: ='GDI-CI'!N35 -> 1.99 | H28: ='GDI-CI'!O35 -> 5376.78
A29: ='GDI-CI'!F36 -> GDI260819010 PO#KD00468 Ref#265K0125-A~D(1ST MB), S/416363 | B29: ='GDI-CI'!G36 -> 60% BETTER COTTON (BCI) 40% POLYESTER CONVENTIONAL CVC 26S/1 JERSEY(LACOSTE EDGE) 70/72“ 160GSM | C29: ='GDI-CI'!J36 -> 2053.1 | D29: ='GDI-CI'!K36 -> 7673.7 | E29: ='GDI-CI'!L36 -> 4526.14 | F29: ='GDI-CI'!M36 -> 7016.8313 | G29: ='GDI-CI'!N36 -> 1.99 | H29: ='GDI-CI'!O36 -> 9007.02
A30: ='GDI-CI'!F37 -> GDI260819010 PO#KD00468 Ref#265K0125-A~D(1ST MB), S/416363 | B30: ='GDI-CI'!G37 -> 60% BETTER COTTON (BCI) 40% POLYESTER CONVENTIONAL CVC 30S/1 JERSEY(LACOSTE EDGE) 69/71" 145GSM | C30: ='GDI-CI'!J37 -> 670.1 | D30: ='GDI-CI'!K37 -> 2802.2 | E30: ='GDI-CI'!L37 -> 1477.22 | F30: ='GDI-CI'!M37 -> 2562.3317 | G30: ='GDI-CI'!N37 -> 1.99 | H30: ='GDI-CI'!O37 -> 2939.67
A31: ='GDI-CI'!F38 -> GDI260819010 PO#KD00468 Ref#265K0125-A~D(1ST MB), S/416363 | B31: ='GDI-CI'!G38 -> 60% BETTER COTTON (BCI) 40% POLYESTER CONVENTIONAL CVC 30S/1 JERSEY(LACOSTE EDGE) 69/71" 145GSM | C31: ='GDI-CI'!J38 -> 1234.2 | D31: ='GDI-CI'!K38 -> 5161.8 | E31: ='GDI-CI'!L38 -> 2720.83 | F31: ='GDI-CI'!M38 -> 4719.9499 | G31: ='GDI-CI'!N38 -> 1.99 | H31: ='GDI-CI'!O38 -> 5414.45
A32: ='GDI-CI'!F39 -> GDI260819010 PO#KD00468 Ref#265K0125-A~D(1ST MB), S/416363 | B32: ='GDI-CI'!G39 -> 60% BETTER COTTON (BCI) 40% POLYESTER CONVENTIONAL CVC 30S/1 JERSEY(LACOSTE EDGE) 69/71" 145GSM | C32: ='GDI-CI'!J39 -> 860.3 | D32: ='GDI-CI'!K39 -> 3597.8 | E32: ='GDI-CI'!L39 -> 1896.59 | F32: ='GDI-CI'!M39 -> 3289.8283 | G32: ='GDI-CI'!N39 -> 1.99 | H32: ='GDI-CI'!O39 -> 3774.21
A33: ='GDI-CI'!F40 -> GDI260819010 PO#KD00468 Ref#265K0125-A~D(1ST MB), S/416363 | B33: ='GDI-CI'!G40 -> 60% BETTER COTTON (BCI) 40% POLYESTER CONVENTIONAL CVC 30S/1 JERSEY(LACOSTE EDGE) 69/71" 145GSM | C33: ='GDI-CI'!J40 -> 880.3 | D33: ='GDI-CI'!K40 -> 3681.8 | E33: ='GDI-CI'!L40 -> 1940.63 | F33: ='GDI-CI'!M40 -> 3366.6379 | G33: ='GDI-CI'!N40 -> 1.99 | H33: ='GDI-CI'!O40 -> 3861.85
A34: ='GDI-CI'!F41 -> GDI260819010 PO#KD00468 Ref#265K0125-A~D(1ST MB), S/416363 | B34: ='GDI-CI'!G41 -> 60% BETTER COTTON (BCI) 40% POLYESTER CONVENTIONAL CVC 30S/1 JERSEY(LACOSTE EDGE) 69/71" 145GSM | C34: ='GDI-CI'!J41 -> 631.9 | D34: ='GDI-CI'!K41 -> 2642.9 | E34: ='GDI-CI'!L41 -> 1393.07 | F34: ='GDI-CI'!M41 -> 2416.6678 | G34: ='GDI-CI'!N41 -> 1.99 | H34: ='GDI-CI'!O41 -> 2772.21
A35: ='GDI-CI'!F42 -> GDI260810010 PO#KD00452 Ref#265K0107-b , S/905994 | B35: ='GDI-CI'!G42 -> 60% BCI COTTON 40% RECYCLED POLYESTER 32S/1 JERSEY 69/71" 125GSM | C35: ='GDI-CI'!J42 -> 897.4 | D35: ='GDI-CI'!K42 -> 4353 | E35: ='GDI-CI'!L42 -> 1978.37 | F35: ='GDI-CI'!M42 -> 3980.3832 | G35: ='GDI-CI'!N42 -> 2.12 | H35: ='GDI-CI'!O42 -> 4194.14
A36: ='GDI-CI'!F43 -> GDI260904001 PO#KD00475 Ref#265K0093-Ba, S/878746 | B36: ='GDI-CI'!G43 -> 60% BCI COTTON 40% RECYCLED POLYESTER 32S/1 JERSEY 69/71“ 125GSM | C36: ='GDI-CI'!J43 -> 1021.8 | D36: ='GDI-CI'!K43 -> 4957.1 | E36: ='GDI-CI'!L43 -> 2252.64 | F36: ='GDI-CI'!M43 -> 4532.7722 | G36: ='GDI-CI'!N43 -> 2.12 | H36: ='GDI-CI'!O43 -> 4775.6
A37: ='GDI-CI'!F44 -> GDI260904002 PO#KD00474 Ref#265K0092 -Ba, S/867788 | B37: ='GDI-CI'!G44 -> 60% BCI COTTON 40% RECYCLED POLYESTER 32S/1 JERSEY 69/71“ 125GSM | C37: ='GDI-CI'!J44 -> 155.7 | D37: ='GDI-CI'!K44 -> 755.3 | E37: ='GDI-CI'!L44 -> 343.26 | F37: ='GDI-CI'!M44 -> 690.64632 | G37: ='GDI-CI'!N44 -> 2.12 | H37: ='GDI-CI'!O44 -> 727.71
A38: ='GDI-CI'!F45 -> GDI260904002 PO#KD00474 Ref#265K0092 -Ba, S/867788 | B38: ='GDI-CI'!G45 -> 60% BCI COTTON 40% RECYCLED POLYESTER 32S/1 JERSEY 69/71“ 125GSM | C38: ='GDI-CI'!J45 -> 452.2 | D38: ='GDI-CI'!K45 -> 2193.7 | E38: ='GDI-CI'!L45 -> 996.92 | F38: ='GDI-CI'!M45 -> 2005.9193 | G38: ='GDI-CI'!N45 -> 2.12 | H38: ='GDI-CI'!O45 -> 2113.47
A39: ='GDI-CI'!F46 -> GDI260904002 PO#KD00474 Ref#265K0092 -Ba, S/867788 | B39: ='GDI-CI'!G46 -> 60% BCI COTTON 40% POLYESTER 32S/1 JERSEY(LACOSTE EDGE) 62/64" 145GSM | C39: ='GDI-CI'!J46 -> 563.3 | D39: ='GDI-CI'!K46 -> 2613.3 | E39: ='GDI-CI'!L46 -> 1241.81 | F39: ='GDI-CI'!M46 -> 2389.6015 | G39: ='GDI-CI'!N46 -> 2.12 | H39: ='GDI-CI'!O46 -> 2632.64
A40: ='GDI-CI'!F47 -> SIOB260507007 PO#KD00433 Ref#265K0077-2ND MB S/767468 | B40: ='GDI-CI'!G47 -> 60% BCI COTTON 40%POLYESTER 26S/1 JERSEY (LACOSTE EDGE) 70/72" 160GSM | C40: ='GDI-CI'!J47 -> 68.1 | D40: ='GDI-CI'!K47 -> 254.5 | E40: ='GDI-CI'!L47 -> 150.14 | F40: ='GDI-CI'!M47 -> 232.7148 | G40: ='GDI-CI'!N47 -> 1.99 | H40: ='GDI-CI'!O47 -> 298.78
B42: TOTAL | C42: =SUM(C28:C41) -> 10714 | D42: =SUM(D28:D41) -> 45267.7 | E42: =SUM(E28:E41) -> 23619.52 | F42: =SUM(F28:F41) -> 41392.785 | H42: ='GDI-CI'!O49 -> 47888.53
A44: * DELIVERY QUANTITY TOLERANCE : 0~+ 2% | K44: (N.W) | L44: (YDS) | M44: (LBS) | N44: Amount
A45: * WIDTH / WEIGHT TOLERANCE : +/- 5 % | K45: =C42='GDI-Total'!H39 -> TRUE | L45: =D42='GDI-Total'!I39 -> TRUE | M45: =E42='GDI-Total'!J39 -> TRUE | N45: =H42='GDI-CI'!O49 -> TRUE
A47: * NOTE: GDI TEXTILE MAKES NO WARRANTY, NOR SHOULD ANY BE IMPLIED, FOR THE FITNESS OR MERCHANTABILITY OF THESE
A48: FABRICS FOR GARMENT DYE OR GARMENT WASH PROCESS. ALL CLAIMS MUST BE MADE WITHIN THIRTY DAYS FROM RECEIPT OF
A49: MERCHANDISE. NO CLAIM(S) OR ALLOWANCES CAN BE MADE AFTER THE GOODS ARE CUT OR OTHERWISE PROCESSED. NO MERCHANDISE
...

Sheet GDI-DPL
C1: GDI TEXTILE CO., LTD
C2: LOT C1, C2, C3, C5, C6, ROAD N6, TMTC INDUSTRIAL PARK,MOC BAI BORDER GATE ECONOMIC ZONE
C3: THUAN DONG HAMLET, BEN CAU DIST., TAY NINH PROV., VIET NAM
B4: DETAILED PACKING LIST
B5: SHIP TO: | C5: PT Nirwana Alabare Garment Jl. Raya Rancaekek - Majalaya No.289 Desa Solokan Jeruk ,Kecamatan Solokan Jeruk, Kabupaten Bandung Jawa Barat 40382,Indonesia Tel: +62 285962076
B8: CPO/STYLE#
B9: PO#
B10: DATE:
B11: ITEM:
B12: COLOR:
A13: Useages | B13: 单号 | C13: 缸号# | D13: REF# | E13: ITEM | F13: 颜色名 | G13: 卷号# | H13: 净重KG | I13: 码数YD | J13: 磅数LBS | K13: 毛重KG
A14: BODY | B14: GDI260819008 | C14: 260601-036-lot4 | D14: KD00465/265K0127(1ST MB), S/769950 | E14: 26S/1 60% BCI COTTON 40%POLYESTER JERSEY (LACOSTE EDGE) 70/72“ 160GSM | F14: CALLA LILY DD 451 漂白 | G14: 1 | H14: 19.3 | I14: 72.1 | J14: =ROUND(H14*2.2046,2) -> 42.55 | K14: =H14+0.2 -> 19.5
A15: BODY | B15: GDI260819008 | C15: 260601-036-lot4 | D15: KD00465/265K0127(1ST MB), S/769950 | E15: 26S/1 60% BCI COTTON 40%POLYESTER JERSEY (LACOSTE EDGE) 70/72“ 160GSM | F15: CALLA LILY DD 451 漂白 | G15: 2 | H15: 21.4 | I15: 80 | J15: =ROUND(H15*2.2046,2) -> 47.18 | K15: =H15+0.2 -> 21.6
A16: BODY | B16: GDI260819008 | C16: 260601-036-lot4 | D16: KD00465/265K0127(1ST MB), S/769950 | E16: 26S/1 60% BCI COTTON 40%POLYESTER JERSEY (LACOSTE EDGE) 70/72“ 160GSM | F16: CALLA LILY DD 451 漂白 | G16: 3 | H16: 21.9 | I16: 81.9 | J16: =ROUND(H16*2.2046,2) -> 48.28 | K16: =H16+0.2 -> 22.1
C17: TOTAL: | G17: =COUNT(G14:G16) -> 3 | H17: =SUM(H14:H16) -> 62.6 | I17: =SUM(I14:I16) -> 234 | J17: =SUM(J14:J16) -> 138.01 | K17: =SUM(K14:K16) -> 63.2
A18: BODY | B18: GDI260819008 | C18: 260709-002-lot3 | D18: KD00465/265K0127(1ST MB), S/769950 | E18: 26S/1 60% BCI COTTON 40%POLYESTER JERSEY (LACOSTE EDGE) 70/72“ 160GSM | F18: CALLA LILY DD 451 漂白 | G18: 12 | H18: 22.1 | I18: 82.6 | J18: =ROUND(H18*2.2046,2) -> 48.72 | K18: =H18+0.2 -> 22.3
A19: BODY | B19: GDI260819008 | C19: 260709-002-lot3 | D19: KD00465/265K0127(1ST MB), S/769950 | E19: 26S/1 60% BCI COTTON 40%POLYESTER JERSEY (LACOSTE EDGE) 70/72“ 160GSM | F19: CALLA LILY DD 451 漂白 | G19: 13 | H19: 22 | I19: 82.2 | J19: =ROUND(H19*2.2046,2) -> 48.5 | K19: =H19+0.2 -> 22.2
C20: TOTAL: | G20: =COUNT(G18:G19) -> 2 | H20: =SUM(H18:H19) -> 44.1 | I20: =SUM(I18:I19) -> 164.8 | J20: =SUM(J18:J19) -> 97.22 | K20: =SUM(K18:K19) -> 44.5
A21: BODY | B21: GDI260819008 | C21: 260824-069-lot2 | D21: KD00465/265K0127(1ST MB), S/769950 | E21: 26S/1 60% BCI COTTON 40%POLYESTER JERSEY (LACOSTE EDGE) 70/72“ 160GSM | F21: CALLA LILY DD 451 漂白 | G21: 1 | H21: 19.5 | I21: 72.9 | J21: =ROUND(H21*2.2046,2) -> 42.99 | K21: =H21+0.2 -> 19.7
A22: BODY | B22: GDI260819008 | C22: 260824-069-lot2 | D22: KD00465/265K0127(1ST MB), S/769950 | E22: 26S/1 60% BCI COTTON 40%POLYESTER JERSEY (LACOSTE EDGE) 70/72“ 160GSM | F22: CALLA LILY DD 451 漂白 | G22: 2 | H22: 22.5 | I22: 84.1 | J22: =ROUND(H22*2.2046,2) -> 49.6 | K22: =H22+0.2 -> 22.7
A23: BODY | B23: GDI260819008 | C23: 260824-069-lot2 | D23: KD00465/265K0127(1ST MB), S/769950 | E23: 26S/1 60% BCI COTTON 40%POLYESTER JERSEY (LACOSTE EDGE) 70/72“ 160GSM | F23: CALLA LILY DD 451 漂白 | G23: 3 | H23: 21.6 | I23: 80.7 | J23: =ROUND(H23*2.2046,2) -> 47.62 | K23: =H23+0.2 -> 21.8
A24: BODY | B24: GDI260819008 | C24: 260824-069-lot2 | D24: KD00465/265K0127(1ST MB), S/769950 | E24: 26S/1 60% BCI COTTON 40%POLYESTER JERSEY (LACOSTE EDGE) 70/72“ 160GSM | F24: CALLA LILY DD 451 漂白 | G24: 4 | H24: 22.2 | I24: 83 | J24: =ROUND(H24*2.2046,2) -> 48.94 | K24: =H24+0.2 -> 22.4
A25: BODY | B25: GDI260819008 | C25: 260824-069-lot2 | D25: KD00465/265K0127(1ST MB), S/769950 | E25: 26S/1 60% BCI COTTON 40%POLYESTER JERSEY (LACOSTE EDGE) 70/72“ 160GSM | F25: CALLA LILY DD 451 漂白 | G25: 5 | H25: 22.3 | I25: 83.3 | J25: =ROUND(H25*2.2046,2) -> 49.16 | K25: =H25+0.2 -> 22.5
A26: BODY | B26: GDI260819008 | C26: 260824-069-lot2 | D26: KD00465/265K0127(1ST MB), S/769950 | E26: 26S/1 60% BCI COTTON 40%POLYESTER JERSEY (LACOSTE EDGE) 70/72“ 160GSM | F26: CALLA LILY DD 451 漂白 | G26: 6 | H26: 22.4 | I26: 83.7 | J26: =ROUND(H26*2.2046,2) -> 49.38 | K26: =H26+0.2 -> 22.6
A27: BODY | B27: GDI260819008 | C27: 260824-069-lot2 | D27: KD00465/265K0127(1ST MB), S/769950 | E27: 26S/1 60% BCI COTTON 40%POLYESTER JERSEY (LACOSTE EDGE) 70/72“ 160GSM | F27: CALLA LILY DD 451 漂白 | G27: 7 | H27: 22 | I27: 82.2 | J27: =ROUND(H27*2.2046,2) -> 48.5 | K27: =H27+0.2 -> 22.2
A28: BODY | B28: GDI260819008 | C28: 260824-069-lot2 | D28: KD00465/265K0127(1ST MB), S/769950 | E28: 26S/1 60% BCI COTTON 40%POLYESTER JERSEY (LACOSTE EDGE) 70/72“ 160GSM | F28: CALLA LILY DD 451 漂白 | G28: 8 | H28: 24.8 | I28: 92.7 | J28: =ROUND(H28*2.2046,2) -> 54.67 | K28: =H28+0.2 -> 25
A29: BODY | B29: GDI260819008 | C29: 260824-069-lot2 | D29: KD00465/265K0127(1ST MB), S/769950 | E29: 26S/1 60% BCI COTTON 40%POLYESTER JERSEY (LACOSTE EDGE) 70/72“ 160GSM | F29: CALLA LILY DD 451 漂白 | G29: 9 | H29: 22.1 | I29: 82.6 | J29: =ROUND(H29*2.2046,2) -> 48.72 | K29: =H29+0.2 -> 22.3
A30: BODY | B30: GDI260819008 | C30: 260824-069-lot2 | D30: KD00465/265K0127(1ST MB), S/769950 | E30: 26S/1 60% BCI COTTON 40%POLYESTER JERSEY (LACOSTE EDGE) 70/72“ 160GSM | F30: CALLA LILY DD 451 漂白 | G30: 10 | H30: 21.9 | I30: 81.9 | J30: =ROUND(H30*2.2046,2) -> 48.28 | K30: =H30+0.2 -> 22.1
A31: BODY | B31: GDI260819008 | C31: 260824-069-lot2 | D31: KD00465/265K0127(1ST MB), S/769950 | E31: 26S/1 60% BCI COTTON 40%POLYESTER JERSEY (LACOSTE EDGE) 70/72“ 160GSM | F31: CALLA LILY DD 451 漂白 | G31: 11 | H31: 22.6 | I31: 84.5 | J31: =ROUND(H31*2.2046,2) -> 49.82 | K31: =H31+0.2 -> 22.8
A32: BODY | B32: GDI260819008 | C32: 260824-069-lot2 | D32: KD00465/265K0127(1ST MB), S/769950 | E32: 26S/1 60% BCI COTTON 40%POLYESTER JERSEY (LACOSTE EDGE) 70/72“ 160GSM | F32: CALLA LILY DD 451 漂白 | G32: 12 | H32: 21.6 | I32: 80.7 | J32: =ROUND(H32*2.2046,2) -> 47.62 | K32: =H32+0.2 -> 21.8
... A44: BODY | B44: GDI260819008 | C44: 260824-069-lot2 | D44: KD00465/265K0127(1ST MB), S/769950 | E44: 26S/1 60% BCI COTTON 40%POLYESTER JERSEY (LACOSTE EDGE) 70/72“ 160GSM | F44: CALLA LILY DD 451 漂白 | G44: 24 | H44: 20.4 | I44: 76.2 | J44: =ROUND(H44*2.2046,2) -> 44.97 | K44: =H44+0.2 -> 20.6
C45: TOTAL: | G45: =COUNT(G21:G44) -> 24 | H45: =SUM(H21:H44) -> 532.9 | I45: =SUM(I21:I44) -> 1991.7 | J45: =SUM(J21:J44) -> 1174.79 | K45: =SUM(K21:K44) -> 537.7
A46: BODY | B46: GDI260819008 | C46: 260824-068-lot1 | D46: KD00465/265K0127(1ST MB), S/769950 | E46: 26S/1 60% BCI COTTON 40%POLYESTER JERSEY (LACOSTE EDGE) 70/72“ 160GSM | F46: CALLA LILY DD 451 漂白 | G46: 1 | H46: 21.6 | I46: 80.7 | J46: =ROUND(H46*2.2046,2) -> 47.62 | K46: =H46+0.2 -> 21.8
A47: BODY | B47: GDI260819008 | C47: 260824-068-lot1 | D47: KD00465/265K0127(1ST MB), S/769950 | E47: 26S/1 60% BCI COTTON 40%POLYESTER JERSEY (LACOSTE EDGE) 70/72“ 160GSM | F47: CALLA LILY DD 451 漂白 | G47: 2 | H47: 22.4 | I47: 83.7 | J47: =ROUND(H47*2.2046,2) -> 49.38 | K47: =H47+0.2 -> 22.6
A48: BODY | B48: GDI260819008 | C48: 260824-068-lot1 | D48: KD00465/265K0127(1ST MB), S/769950 | E48: 26S/1 60% BCI COTTON 40%POLYESTER JERSEY (LACOSTE EDGE) 70/72“ 160GSM | F48: CALLA LILY DD 451 漂白 | G48: 3 | H48: 22 | I48: 82.2 | J48: =ROUND(H48*2.2046,2) -> 48.5 | K48: =H48+0.2 -> 22.2
A49: BODY | B49: GDI260819008 | C49: 260824-068-lot1 | D49: KD00465/265K0127(1ST MB), S/769950 | E49: 26S/1 60% BCI COTTON 40%POLYESTER JERSEY (LACOSTE EDGE) 70/72“ 160GSM | F49: CALLA LILY DD 451 漂白 | G49: 4 | H49: 22.3 | I49: 83.3 | J49: =ROUND(H49*2.2046,2) -> 49.16 | K49: =H49+0.2 -> 22.5
A50: BODY | B50: GDI260819008 | C50: 260824-068-lot1 | D50: KD00465/265K0127(1ST MB), S/769950 | E50: 26S/1 60% BCI COTTON 40%POLYESTER JERSEY (LACOSTE EDGE) 70/72“ 160GSM | F50: CALLA LILY DD 451 漂白 | G50: 5 | H50: 20.9 | I50: 78.1 | J50: =ROUND(H50*2.2046,2) -> 46.08 | K50: =H50+0.2 -> 21.1
A51: BODY | B51: GDI260819008 | C51: 260824-068-lot1 | D51: KD00465/265K0127(1ST MB), S/769950 | E51: 26S/1 60% BCI COTTON 40%POLYESTER JERSEY (LACOSTE EDGE) 70/72“ 160GSM | F51: CALLA LILY DD 451 漂白 | G51: 6 | H51: 23.1 | I51: 86.3 | J51: =ROUND(H51*2.2046,2) -> 50.93 | K51: =H51+0.2 -> 23.3
A52: BODY | B52: GDI260819008 | C52: 260824-068-lot1 | D52: KD00465/265K0127(1ST MB), S/769950 | E52: 26S/1 60% BCI COTTON 40%POLYESTER JERSEY (LACOSTE EDGE) 70/72“ 160GSM | F52: CALLA LILY DD 451 漂白 | G52: 7 | H52: 22.2 | I52: 83 | J52: =ROUND(H52*2.2046,2) -> 48.94 | K52: =H52+0.2 -> 22.4
A53: BODY | B53: GDI260819008 | C53: 260824-068-lot1 | D53: KD00465/265K0127(1ST MB), S/769950 | E53: 26S/1 60% BCI COTTON 40%POLYESTER JERSEY (LACOSTE EDGE) 70/72“ 160GSM | F53: CALLA LILY DD 451 漂白 | G53: 8 | H53: 21.6 | I53: 80.7 | J53: =ROUND(H53*2.2046,2) -> 47.62 | K53: =H53+0.2 -> 21.8
...

Sheet GDI-Total
C1: GDI TEXTILE CO., LTD
C2: LOT C1, C2, C3, C5, C6, ROAD N6, TMTC INDUSTRIAL PARK,MOC BAI BORDER GATE ECONOMIC ZONE
C3: THUAN DONG HAMLET, BEN CAU DIST., TAY NINH PROV., VIET NAM
B4: DETAILED PACKING LIST
B5: SHIP TO: | C5: ='GDI-DPL'!C5 -> PT Nirwana Alabare Garment Jl. Raya Rancaekek - Majalaya No.289 Desa Solokan Jeruk ,Kecamatan Solokan Jeruk, Kabupaten Bandung Jawa Barat 40382,Indonesia Tel: +62 285962076
B8: CPO/STYLE#
B9: PO#
B10: DATE:
B11: ITEM:
B12: COLOR:
A13: Useages | B13: PO# | C13: 缸号# | D13: REF# | E13: ITEM | F13: 颜色名 | G13: 卷号# | H13: 净重KG | I13: 码数YD | J13: 磅数LBS | K13: 毛重KG | M13: PO | N13: TOLERANCE | R13: 已出
A14: BODY | B14: GDI260819008 | C14: 260601-036-lot4 | D14: KD00465/265K0127(1ST MB), S/769950 | E14: 26S/1 60% BCI COTTON 40%POLYESTER JERSEY (LACOSTE EDGE) 70/72“ 160GSM | F14: CALLA LILY DD 451 漂白 | G14: ='GDI-DPL'!G17 -> 3 | H14: ='GDI-DPL'!H17 -> 62.6 | I14: ='GDI-DPL'!I17 -> 234 | J14: ='GDI-DPL'!J17 -> 138.01 | K14: ='GDI-DPL'!K17 -> 63.2 | L14: C1-C3
A15: BODY | B15: GDI260819008 | C15: 260709-002-lot3 | D15: KD00465/265K0127(1ST MB), S/769950 | E15: 26S/1 60% BCI COTTON 40%POLYESTER JERSEY (LACOSTE EDGE) 70/72“ 160GSM | F15: CALLA LILY DD 451 漂白 | G15: ='GDI-DPL'!G20 -> 2 | H15: ='GDI-DPL'!H20 -> 44.1 | I15: ='GDI-DPL'!I20 -> 164.8 | J15: ='GDI-DPL'!J20 -> 97.22 | K15: ='GDI-DPL'!K20 -> 44.5 | L15: C12-C13
A16: BODY | B16: GDI260819008 | C16: 260824-069-lot2 | D16: KD00465/265K0127(1ST MB), S/769950 | E16: 26S/1 60% BCI COTTON 40%POLYESTER JERSEY (LACOSTE EDGE) 70/72“ 160GSM | F16: CALLA LILY DD 451 漂白 | G16: ='GDI-DPL'!G45 -> 24 | H16: ='GDI-DPL'!H45 -> 532.9 | I16: ='GDI-DPL'!I45 -> 1991.7 | J16: ='GDI-DPL'!J45 -> 1174.79 | K16: ='GDI-DPL'!K45 -> 537.7
A17: BODY | B17: GDI260819008 | C17: 260824-068-lot1 | D17: KD00465/265K0127(1ST MB), S/769950 | E17: 26S/1 60% BCI COTTON 40%POLYESTER JERSEY (LACOSTE EDGE) 70/72“ 160GSM | F17: CALLA LILY DD 451 漂白 | G17: ='GDI-DPL'!G73 -> 27 | H17: ='GDI-DPL'!H73 -> 586 | I17: ='GDI-DPL'!I73 -> 2190.1 | J17: ='GDI-DPL'!J73 -> 1291.88 | K17: ='GDI-DPL'!K73 -> 591.4
A18: BODY | B18: GDI260819010 | C18: 260824-072-lot3 | D18: KD00468/265K0125-A~D(1ST MB), S/416363 | E18: 60% BETTER COTTON (BCI) 40% POLYESTER CONVENTIONAL CVC 26S/1 JERSEY(LACOSTE EDGE) 70/72“ 160GSM | F18: CALLA LILY DD 451 漂白 | G18: ='GDI-DPL'!G105 -> 31 | H18: ='GDI-DPL'!H105 -> 694.9 | I18: ='GDI-DPL'!I105 -> 2597.3 | J18: ='GDI-DPL'!J105 -> 1531.97 | K18: ='GDI-DPL'!K105 -> 701.1
A19: BODY | B19: GDI260819010 | C19: 260824-071-lot2 | D19: KD00468/265K0125-A~D(1ST MB), S/416363 | E19: 60% BETTER COTTON (BCI) 40% POLYESTER CONVENTIONAL CVC 26S/1 JERSEY(LACOSTE EDGE) 70/72“ 160GSM | F19: CALLA LILY DD 451 漂白 | G19: ='GDI-DPL'!G138 -> 32 | H19: ='GDI-DPL'!H138 -> 709.7 | I19: ='GDI-DPL'!I138 -> 2652.7 | J19: ='GDI-DPL'!J138 -> 1564.54 | K19: ='GDI-DPL'!K138 -> 716.1
A20: BODY | B20: GDI260819010 | C20: 260824-070-lot1 | D20: KD00468/265K0125-A~D(1ST MB), S/416363 | E20: 60% BETTER COTTON (BCI) 40% POLYESTER CONVENTIONAL CVC 26S/1 JERSEY(LACOSTE EDGE) 70/72“ 160GSM | F20: CALLA LILY DD 451 漂白 | G20: ='GDI-DPL'!G169 -> 30 | H20: ='GDI-DPL'!H169 -> 648.5 | I20: ='GDI-DPL'!I169 -> 2423.7 | J20: ='GDI-DPL'!J169 -> 1429.63 | K20: ='GDI-DPL'!K169 -> 654.5 | L20: C1-C30
A21: BODY | B21: GDI260819010 | C21: 260824-064-lot1 | D21: KD00468/265K0125-A~D(1ST MB), S/416363 | E21: 60% BETTER COTTON (BCI) 40% POLYESTER CONVENTIONAL CVC 30S/1 JERSEY(LACOSTE EDGE) 69/71" 145GSM | F21: BLACK JACK DD 400 黑色 | G21: ='GDI-DPL'!G331 -> 30 | H21: ='GDI-DPL'!H331 -> 670.1 | I21: ='GDI-DPL'!I331 -> 2802.2 | J21: ='GDI-DPL'!J331 -> 1477.22 | K21: ='GDI-DPL'!K331 -> 676.1
A22: BODY | B22: GDI260819010 | C22: 260910-010-lot4 | D22: KD00468/265K0125-A~D(1ST MB), S/416363 | E22: 60% BETTER COTTON (BCI) 40% POLYESTER CONVENTIONAL CVC 30S/1 JERSEY(LACOSTE EDGE) 69/71" 145GSM | F22: B25 FAUX HEATHER GREY (B25 PSD) B25单染涤 | G22: ='GDI-DPL'!G369 -> 37 | H22: ='GDI-DPL'!H369 -> 819.7 | I22: ='GDI-DPL'!I369 -> 3428.5 | J22: ='GDI-DPL'!J369 -> 1807.04 | K22: ='GDI-DPL'!K369 -> 827.1
A23: BODY | B23: GDI260819010 | C23: 260910-009-lot3 | D23: KD00468/265K0125-A~D(1ST MB), S/416363 | E23: 60% BETTER COTTON (BCI) 40% POLYESTER CONVENTIONAL CVC 30S/1 JERSEY(LACOSTE EDGE) 69/71" 145GSM | F23: B25 FAUX HEATHER GREY (B25 PSD) B25单染涤 | G23: ='GDI-DPL'!G389 -> 19 | H23: ='GDI-DPL'!H389 -> 414.5 | I23: ='GDI-DPL'!I389 -> 1733.3 | J23: ='GDI-DPL'!J389 -> 913.79 | K23: ='GDI-DPL'!K389 -> 418.3 | L23: C1-C19
A24: BODY | B24: GDI260819010 | C24: 260824-065-lot1 | D24: KD00468/265K0125-A~D(1ST MB), S/416363 | E24: 60% BETTER COTTON (BCI) 40% POLYESTER CONVENTIONAL CVC 30S/1 JERSEY(LACOSTE EDGE) 69/71" 145GSM | F24: MONET BLUE DD 744 油画蓝 | G24: ='GDI-DPL'!G429 -> 39 | H24: ='GDI-DPL'!H429 -> 860.3 | I24: ='GDI-DPL'!I429 -> 3597.8 | J24: ='GDI-DPL'!J429 -> 1896.59 | K24: ='GDI-DPL'!K429 -> 868.1
A25: BODY | B25: GDI260819010 | C25: 260824-066-lot1 | D25: KD00468/265K0125-A~D(1ST MB), S/416363 | E25: 60% BETTER COTTON (BCI) 40% POLYESTER CONVENTIONAL CVC 30S/1 JERSEY(LACOSTE EDGE) 69/71" 145GSM | F25: PLANT LIFE DD 978 翡翠绿 | G25: ='GDI-DPL'!G470 -> 40 | H25: ='GDI-DPL'!H470 -> 880.3 | I25: ='GDI-DPL'!I470 -> 3681.8 | J25: ='GDI-DPL'!J470 -> 1940.63 | K25: ='GDI-DPL'!K470 -> 888.3 | L25: C1-C40
A26: BODY | B26: GDI260819010 | C26: 260824-067-lot1 | D26: KD00468/265K0125-A~D(1ST MB), S/416363 | E26: 60% BETTER COTTON (BCI) 40% POLYESTER CONVENTIONAL CVC 30S/1 JERSEY(LACOSTE EDGE) 69/71" 145GSM | F26: WINE STAIN DD 853 酒红 | G26: ='GDI-DPL'!G505 -> 29 | H26: ='GDI-DPL'!H505 -> 631.9 | I26: ='GDI-DPL'!I505 -> 2642.9 | J26: ='GDI-DPL'!J505 -> 1393.07 | K26: ='GDI-DPL'!K505 -> 637.7 | L26: C1-C7.C9-C30
A27: BODY | B27: GDI260810010 | C27: 260905-009-lot1 | D27: KD00452/265K0107-b , S/905994 | E27: 60% BCI COTTON 40% RECYCLED POLYESTER 32S/1 JERSEY 69/71" 125GSM | F27: CLOUD COVER PSD 中灰色-单染涤 | G27: ='GDI-DPL'!G177 -> 7 | H27: ='GDI-DPL'!H177 -> 154.1 | I27: ='GDI-DPL'!I177 -> 747.5 | J27: ='GDI-DPL'!J177 -> 339.72 | K27: ='GDI-DPL'!K177 -> 155.5
A28: BODY | B28: GDI260810010 | C28: 260824-073-lot1 | D28: KD00452/265K0107-b , S/905994 | E28: 60% BCI COTTON 40% RECYCLED POLYESTER 32S/1 JERSEY 69/71" 125GSM | F28: CLOUD COVER PSD 中灰色-单染涤 | G28: ='GDI-DPL'!G187 -> 9 | H28: ='GDI-DPL'!H187 -> 196.1 | I28: ='GDI-DPL'!I187 -> 951.2 | J28: ='GDI-DPL'!J187 -> 432.32 | K28: ='GDI-DPL'!K187 -> 197.9 | L28: C8-C16
A29: BODY | B29: GDI260810010 | C29: 260905-008-lot1 | D29: KD00452/265K0107-b , S/905994 | E29: 60% BCI COTTON 40% RECYCLED POLYESTER 32S/1 JERSEY 69/71" 125GSM | F29: CLOUD COVER PSD 中灰色-单染涤 | G29: ='GDI-DPL'!G213 -> 25 | H29: ='GDI-DPL'!H213 -> 547.2 | I29: ='GDI-DPL'!I213 -> 2654.3 | J29: ='GDI-DPL'!J213 -> 1206.33 | K29: ='GDI-DPL'!K213 -> 552.2 | L29: C1-C25
A30: BODY | B30: GDI260904001 | C30: 260907-001-lot1 | D30: KD00475/265K0093-Ba, S/878746 | E30: 60% BCI COTTON 40% RECYCLED POLYESTER 32S/1 JERSEY 69/71“ 125GSM | F30: BLACK JACK 400 黑色 | G30: ='GDI-DPL'!G527 -> 21 | H30: ='GDI-DPL'!H527 -> 459.6 | I30: ='GDI-DPL'!I527 -> 2229.7 | J30: ='GDI-DPL'!J527 -> 1013.21 | K30: ='GDI-DPL'!K527 -> 463.8 | L30: C1-C21
A31: BODY | B31: GDI260904001 | C31: 260905-016-lot1 | D31: KD00475/265K0093-Ba, S/878746 | E31: 60% BCI COTTON 40% RECYCLED POLYESTER 32S/1 JERSEY 69/71“ 125GSM | F31: BLACK JACK 400 黑色 | G31: ='GDI-DPL'!G240 -> 26 | H31: ='GDI-DPL'!H240 -> 562.2 | I31: ='GDI-DPL'!I240 -> 2727.4 | J31: ='GDI-DPL'!J240 -> 1239.43 | K31: ='GDI-DPL'!K240 -> 567.4
A32: BODY | B32: GDI260904002 | C32: 260905-015-lot1 | D32: KD00474/265K0092 -Ba, S/867788 | E32: 60% BCI COTTON 40% RECYCLED POLYESTER 32S/1 JERSEY 69/71“ 125GSM | F32: BLACK JACK 400 黑色 | G32: ='GDI-DPL'!G248 -> 7 | H32: ='GDI-DPL'!H248 -> 155.7 | I32: ='GDI-DPL'!I248 -> 755.3 | J32: ='GDI-DPL'!J248 -> 343.26 | K32: ='GDI-DPL'!K248 -> 157.1
A33: BODY | B33: GDI260904002 | C33: 260731-015-lot1 | D33: KD00474/265K0092 -Ba, S/867788 | E33: 60% BCI COTTON 40% RECYCLED POLYESTER 32S/1 JERSEY 69/71“ 125GSM | F33: BLUSH HUE 257 粉红色 | G33: ='GDI-DPL'!G250 -> 1 | H33: ='GDI-DPL'!H250 -> 19.5 | I33: ='GDI-DPL'!I250 -> 94.6 | J33: ='GDI-DPL'!J250 -> 42.99 | K33: ='GDI-DPL'!K250 -> 19.7 | L33: C23
A34: BODY | B34: GDI260904002 | C34: 260521-010-lot1 | D34: KD00474/265K0092 -Ba, S/867788 | E34: 60% BCI COTTON 40% RECYCLED POLYESTER 32S/1 JERSEY 69/71“ 125GSM | F34: BLUSH HUE 257 粉红色 | G34: ='GDI-DPL'!G252 -> 1 | H34: ='GDI-DPL'!H252 -> 21.3 | I34: ='GDI-DPL'!I252 -> 103.3 | J34: ='GDI-DPL'!J252 -> 46.96 | K34: ='GDI-DPL'!K252 -> 21.5 | L34: C46
A35: BODY | B35: GDI260904002 | C35: 260905-014-lot1 | D35: KD00474/265K0092 -Ba, S/867788 | E35: 60% BCI COTTON 40% RECYCLED POLYESTER 32S/1 JERSEY 69/71“ 125GSM | F35: BLUSH HUE 257 粉红色 | G35: ='GDI-DPL'!G272 -> 19 | H35: ='GDI-DPL'!H272 -> 411.4 | I35: ='GDI-DPL'!I272 -> 1995.8 | J35: ='GDI-DPL'!J272 -> 906.97 | K35: ='GDI-DPL'!K272 -> 415.2
A36: BODY | B36: GDI260904002 | C36: 260905-013-lot1 | D36: KD00474/265K0092 -Ba, S/867788 | E36: 60% BCI COTTON 40% POLYESTER 32S/1 JERSEY(LACOSTE EDGE) 62/64" 145GSM | F36: CALLA LILY 451 漂白 | G36: ='GDI-DPL'!G294 -> 21 | H36: ='GDI-DPL'!H294 -> 466 | I36: ='GDI-DPL'!I294 -> 2162 | J36: ='GDI-DPL'!J294 -> 1027.3 | K36: ='GDI-DPL'!K294 -> 470.2
A37: BODY | B37: GDI260904002 | C37: 260911-012-lot1 | D37: KD00474/265K0092 -Ba, S/867788 | E37: 60% BCI COTTON 40% POLYESTER 32S/1 JERSEY(LACOSTE EDGE) 62/64" 145GSM | F37: CALLA LILY 451 漂白 | G37: ='GDI-DPL'!G300 -> 5 | H37: ='GDI-DPL'!H300 -> 97.3 | I37: ='GDI-DPL'!I300 -> 451.3 | J37: ='GDI-DPL'!J300 -> 214.51 | K37: ='GDI-DPL'!K300 -> 98.3 | L37: C1-C5
A38: BODY | B38: SIOB260507007 | C38: 260707-008-lot1 | D38: KD00433/265K0077-2ND MB S/767468 | E38: 60% BCI COTTON 40%POLYESTER 26S/1 JERSEY (LACOSTE EDGE) 70/72" 160GSM | F38: BLACK JACK 400 黑色 | G38: ='GDI-DPL'!G475 -> 4 | H38: ='GDI-DPL'!H475 -> 68.1 | I38: ='GDI-DPL'!I475 -> 254.5 | J38: ='GDI-DPL'!J475 -> 150.14 | K38: ='GDI-DPL'!K475 -> 68.9 | L38: C1-C40
F39: TOTAL | G39: =SUM(G14:G38) -> 489 | H39: =SUM(H14:H38) -> 10714 | I39: =SUM(I14:I38) -> 45267.7 | J39: =SUM(J14:J38) -> 23619.52 | K39: =SUM(K14:K38) -> 10811.8
